Workbook

Sheet Mercado 2025 y 2026
A1: Ficohsa
A4: ESTADO DE RESULTADOS | B4: 45658 | C4: 45689 | D4: 45717 | E4: 45748 | F4: 45778 | G4: ENERO A MAYO | H4: 45809 | I4: 45839 | J4: 45870 | K4: 45901 | L4: 45931 | M4: 45962 | N4: 45992 | O4: ACUMULADO | Q4: 46023 | R4: 46054 | S4: 46082 | T4: 46113 | U4: 46143 | V4: 46174 | W4: 46204 | X4: 46235 | Y4: ACUMULADO
A5: Primas | B5: =IF(OR(SUM($Q5:$U5)=0,COUNTIF($Q5:$U5,"<0")*COUNTIF($Q5:$U5,">0")>0),$G5/5,$G5*Q5/SUM($Q5:$U5)) -> 0 | C5: =IF(OR(SUM($Q5:$U5)=0,COUNTIF($Q5:$U5,"<0")*COUNTIF($Q5:$U5,">0")>0),$G5/5,$G5*R5/SUM($Q5:$U5)) -> 0 | D5: =IF(OR(SUM($Q5:$U5)=0,COUNTIF($Q5:$U5,"<0")*COUNTIF($Q5:$U5,">0")>0),$G5/5,$G5*S5/SUM($Q5:$U5)) -> 0 | E5: =IF(OR(SUM($Q5:$U5)=0,COUNTIF($Q5:$U5,"<0")*COUNTIF($Q5:$U5,">0")>0),$G5/5,$G5*T5/SUM($Q5:$U5)) -> 0 | F5: =IF(OR(SUM($Q5:$U5)=0,COUNTIF($Q5:$U5,"<0")*COUNTIF($Q5:$U5,">0")>0),$G5/5,$G5*U5/SUM($Q5:$U5)) -> 0 | G5: 0 | H5: 0 | I5: 0 | J5: 0 | K5: 0 | L5: 0 | M5: 0 | N5: 0 | O5: =SUM(B5:F5,H5:N5) -> 0 | Q5: 0 | R5: 0 | S5: 0 | T5: 0 | U5: 0 | V5: 0 | W5: 0 | X5: 0 | Y5: =SUM(Q5:X5) -> 0
A6: Seguro Directo | B6: =IF(OR(SUM($Q6:$U6)=0,COUNTIF($Q6:$U6,"<0")*COUNTIF($Q6:$U6,">0")>0),$G6/5,$G6*Q6/SUM($Q6:$U6)) -> 18327417 | C6: =IF(OR(SUM($Q6:$U6)=0,COUNTIF($Q6:$U6,"<0")*COUNTIF($Q6:$U6,">0")>0),$G6/5,$G6*R6/SUM($Q6:$U6)) -> 17092855 | D6: =IF(OR(SUM($Q6:$U6)=0,COUNTIF($Q6:$U6,"<0")*COUNTIF($Q6:$U6,">0")>0),$G6/5,$G6*S6/SUM($Q6:$U6)) -> 15638711 | E6: =IF(OR(SUM($Q6:$U6)=0,COUNTIF($Q6:$U6,"<0")*COUNTIF($Q6:$U6,">0")>0),$G6/5,$G6*T6/SUM($Q6:$U6)) -> 32848248 | F6: =IF(OR(SUM($Q6:$U6)=0,COUNTIF($Q6:$U6,"<0")*COUNTIF($Q6:$U6,">0")>0),$G6/5,$G6*U6/SUM($Q6:$U6)) -> 14593229 | G6: 98500460 | H6: 12856807 | I6: 15869023 | J6: 14136893 | K6: 14833950 | L6: 14088628 | M6: 12282663 | N6: 27000392 | O6: =SUM(B6:F6,H6:N6) -> 2.0956882e+08 | Q6: 16586977 | R6: 15469654 | S6: 14153601 | T6: 29728856 | U6: 13207402 | V6: 41818714 | W6: 16816091 | X6: 16983764 | Y6: =SUM(Q6:X6) -> 1.6476506e+08
A7: (-) Devoluciones y Cancelaciones de Primas | B7: =IF(OR(SUM($Q7:$U7)=0,COUNTIF($Q7:$U7,"<0")*COUNTIF($Q7:$U7,">0")>0),$G7/5,$G7*Q7/SUM($Q7:$U7)) -> 7489396.8 | C7: =IF(OR(SUM($Q7:$U7)=0,COUNTIF($Q7:$U7,"<0")*COUNTIF($Q7:$U7,">0")>0),$G7/5,$G7*R7/SUM($Q7:$U7)) -> 5267864.7 | D7: =IF(OR(SUM($Q7:$U7)=0,COUNTIF($Q7:$U7,"<0")*COUNTIF($Q7:$U7,">0")>0),$G7/5,$G7*S7/SUM($Q7:$U7)) -> 6354688.1 | E7: =IF(OR(SUM($Q7:$U7)=0,COUNTIF($Q7:$U7,"<0")*COUNTIF($Q7:$U7,">0")>0),$G7/5,$G7*T7/SUM($Q7:$U7)) -> 3223066.5 | F7: =IF(OR(SUM($Q7:$U7)=0,COUNTIF($Q7:$U7,"<0")*COUNTIF($Q7:$U7,">0")>0),$G7/5,$G7*U7/SUM($Q7:$U7)) -> 3618639.4 | G7: 25953656 | H7: 2222667.7 | I7: 1492341.1 | J7: 3514623.4 | K7: 4296275.6 | L7: 3601388.3 | M7: 1065162.8 | N7: 590413.92 | O7: =SUM(B7:F7,H7:N7) -> 42736528 | Q7: 3749384.4 | R7: 2637228.3 | S7: 3181320 | T7: 1613549.9 | U7: 1811583.8 | V7: 7920108.8 | W7: 4660953.7 | X7: 2813076.5 | Y7: =SUM(Q7:X7) -> 28387205
A8: PRIMAS DIRECTAS NETAS | B8: =IF(OR(SUM($Q8:$U8)=0,COUNTIF($Q8:$U8,"<0")*COUNTIF($Q8:$U8,">0")>0),$G8/5,$G8*Q8/SUM($Q8:$U8)) -> 12229606 | C8: =IF(OR(SUM($Q8:$U8)=0,COUNTIF($Q8:$U8,"<0")*COUNTIF($Q8:$U8,">0")>0),$G8/5,$G8*R8/SUM($Q8:$U8)) -> 12224683 | D8: =IF(OR(SUM($Q8:$U8)=0,COUNTIF($Q8:$U8,"<0")*COUNTIF($Q8:$U8,">0")>0),$G8/5,$G8*S8/SUM($Q8:$U8)) -> 10452635 | E8: =IF(OR(SUM($Q8:$U8)=0,COUNTIF($Q8:$U8,"<0")*COUNTIF($Q8:$U8,">0")>0),$G8/5,$G8*T8/SUM($Q8:$U8)) -> 26783768 | F8: =IF(OR(SUM($Q8:$U8)=0,COUNTIF($Q8:$U8,"<0")*COUNTIF($Q8:$U8,">0")>0),$G8/5,$G8*U8/SUM($Q8:$U8)) -> 10856113 | G8: 72546804 | H8: 10634139 | I8: 14376682 | J8: 10622269 | K8: 10537675 | L8: 10487240 | M8: 11217500 | N8: 26409978 | O8: =SUM(B8:F8,H8:N8) -> 1.6683229e+08 | Q8: 12837593 | R8: 12832425 | S8: 10972281 | T8: 28115306 | U8: 11395818 | V8: 33898605 | W8: 12155137 | X8: 14170688 | Y8: =SUM(Q8:X8) -> 1.3637785e+08
B9: =IF(OR(SUM($Q9:$U9)=0,COUNTIF($Q9:$U9,"<0")*COUNTIF($Q9:$U9,">0")>0),$G9/5,$G9*Q9/SUM($Q9:$U9)) -> 0 | C9: =IF(OR(SUM($Q9:$U9)=0,COUNTIF($Q9:$U9,"<0")*COUNTIF($Q9:$U9,">0")>0),$G9/5,$G9*R9/SUM($Q9:$U9)) -> 0 | D9: =IF(OR(SUM($Q9:$U9)=0,COUNTIF($Q9:$U9,"<0")*COUNTIF($Q9:$U9,">0")>0),$G9/5,$G9*S9/SUM($Q9:$U9)) -> 0 | E9: =IF(OR(SUM($Q9:$U9)=0,COUNTIF($Q9:$U9,"<0")*COUNTIF($Q9:$U9,">0")>0),$G9/5,$G9*T9/SUM($Q9:$U9)) -> 0 | F9: =IF(OR(SUM($Q9:$U9)=0,COUNTIF($Q9:$U9,"<0")*COUNTIF($Q9:$U9,">0")>0),$G9/5,$G9*U9/SUM($Q9:$U9)) -> 0 | G9: 0 | H9: 0 | I9: 0 | J9: 0 | K9: 0 | L9: 0 | M9: 0 | N9: 0 | O9: =SUM(B9:F9,H9:N9) -> 0 | Q9: 0 | R9: 0 | S9: 0 | T9: 0 | U9: 0 | V9: 0 | W9: 0 | X9: 0 | Y9: =SUM(Q9:X9) -> 0
A10: Primas | B10: =IF(OR(SUM($Q10:$U10)=0,COUNTIF($Q10:$U10,"<0")*COUNTIF($Q10:$U10,">0")>0),$G10/5,$G10*Q10/SUM($Q10:$U10)) -> 0 | C10: =IF(OR(SUM($Q10:$U10)=0,COUNTIF($Q10:$U10,"<0")*COUNTIF($Q10:$U10,">0")>0),$G10/5,$G10*R10/SUM($Q10:$U10)) -> 0 | D10: =IF(OR(SUM($Q10:$U10)=0,COUNTIF($Q10:$U10,"<0")*COUNTIF($Q10:$U10,">0")>0),$G10/5,$G10*S10/SUM($Q10:$U10)) -> 0 | E10: =IF(OR(SUM($Q10:$U10)=0,COUNTIF($Q10:$U10,"<0")*COUNTIF($Q10:$U10,">0")>0),$G10/5,$G10*T10/SUM($Q10:$U10)) -> 0 | F10: =IF(OR(SUM($Q10:$U10)=0,COUNTIF($Q10:$U10,"<0")*COUNTIF($Q10:$U10,">0")>0),$G10/5,$G10*U10/SUM($Q10:$U10)) -> 0 | G10: 0 | H10: 0 | I10: 0 | J10: 0 | K10: 0 | L10: 0 | M10: 0 | N10: 0 | O10: =SUM(B10:F10,H10:N10) -> 0 | Q10: 0 | R10: 0 | S10: 0 | T10: 0 | U10: 0 | V10: 0 | W10: 0 | X10: 0 | Y10: =SUM(Q10:X10) -> 0
A11: (+) Por Reaseguro Tomado Local | B11: =IF(OR(SUM($Q11:$U11)=0,COUNTIF($Q11:$U11,"<0")*COUNTIF($Q11:$U11,">0")>0),$G11/5,$G11*Q11/SUM($Q11:$U11)) -> 0 | C11: =IF(OR(SUM($Q11:$U11)=0,COUNTIF($Q11:$U11,"<0")*COUNTIF($Q11:$U11,">0")>0),$G11/5,$G11*R11/SUM($Q11:$U11)) -> 0 | D11: =IF(OR(SUM($Q11:$U11)=0,COUNTIF($Q11:$U11,"<0")*COUNTIF($Q11:$U11,">0")>0),$G11/5,$G11*S11/SUM($Q11:$U11)) -> 0 | E11: =IF(OR(SUM($Q11:$U11)=0,COUNTIF($Q11:$U11,"<0")*COUNTIF($Q11:$U11,">0")>0),$G11/5,$G11*T11/SUM($Q11:$U11)) -> 0 | F11: =IF(OR(SUM($Q11:$U11)=0,COUNTIF($Q11:$U11,"<0")*COUNTIF($Q11:$U11,">0")>0),$G11/5,$G11*U11/SUM($Q11:$U11)) -> 0 | G11: 0 | H11: 0 | I11: 0 | J11: 0 | K11: 0 | L11: 0 | M11: 0 | N11: 0 | O11: =SUM(B11:F11,H11:N11) -> 0 | Q11: 0 | R11: 0 | S11: 0 | T11: 0 | U11: 0 | V11: 0 | W11: 0 | X11: 0 | Y11: =SUM(Q11:X11) -> 0
A12: (+) Por Reaseguro Tomado del Exterior | B12: =IF(OR(SUM($Q12:$U12)=0,COUNTIF($Q12:$U12,"<0")*COUNTIF($Q12:$U12,">0")>0),$G12/5,$G12*Q12/SUM($Q12:$U12)) -> 0 | C12: =IF(OR(SUM($Q12:$U12)=0,COUNTIF($Q12:$U12,"<0")*COUNTIF($Q12:$U12,">0")>0),$G12/5,$G12*R12/SUM($Q12:$U12)) -> 0 | D12: =IF(OR(SUM($Q12:$U12)=0,COUNTIF($Q12:$U12,"<0")*COUNTIF($Q12:$U12,">0")>0),$G12/5,$G12*S12/SUM($Q12:$U12)) -> 0 | E12: =IF(OR(SUM($Q12:$U12)=0,COUNTIF($Q12:$U12,"<0")*COUNTIF($Q12:$U12,">0")>0),$G12/5,$G12*T12/SUM($Q12:$U12)) -> 0 | F12: =IF(OR(SUM($Q12:$U12)=0,COUNTIF($Q12:$U12,"<0")*COUNTIF($Q12:$U12,">0")>0),$G12/5,$G12*U12/SUM($Q12:$U12)) -> 0 | G12: 0 | H12: 0 | I12: 0 | J12: 0 | K12: 0 | L12: 0 | M12: 0 | N12: 0 | O12: =SUM(B12:F12,H12:N12) -> 0 | Q12: 0 | R12: 0 | S12: 0 | T12: 0 | U12: 0 | V12: 0 | W12: 0 | X12: 0 | Y12: =SUM(Q12:X12) -> 0
A13: (-) Devoluciones y Cancelaciones de Primas | B13: =IF(OR(SUM($Q13:$U13)=0,COUNTIF($Q13:$U13,"<0")*COUNTIF($Q13:$U13,">0")>0),$G13/5,$G13*Q13/SUM($Q13:$U13)) -> 0 | C13: =IF(OR(SUM($Q13:$U13)=0,COUNTIF($Q13:$U13,"<0")*COUNTIF($Q13:$U13,">0")>0),$G13/5,$G13*R13/SUM($Q13:$U13)) -> 0 | D13: =IF(OR(SUM($Q13:$U13)=0,COUNTIF($Q13:$U13,"<0")*COUNTIF($Q13:$U13,">0")>0),$G13/5,$G13*S13/SUM($Q13:$U13)) -> 0 | E13: =IF(OR(SUM($Q13:$U13)=0,COUNTIF($Q13:$U13,"<0")*COUNTIF($Q13:$U13,">0")>0),$G13/5,$G13*T13/SUM($Q13:$U13)) -> 0 | F13: =IF(OR(SUM($Q13:$U13)=0,COUNTIF($Q13:$U13,"<0")*COUNTIF($Q13:$U13,">0")>0),$G13/5,$G13*U13/SUM($Q13:$U13)) -> 0 | G13: 0 | H13: 0 | I13: 0 | J13: 0 | K13: 0 | L13: 0 | M13: 0 | N13: 0 | O13: =SUM(B13:F13,H13:N13) -> 0 | Q13: 0 | R13: 0 | S13: 0 | T13: 0 | U13: 0 | V13: 0 | W13: 0 | X13: 0 | Y13: =SUM(Q13:X13) -> 0
A14: TOTAL DE PRIMAS NETAS | B14: =IF(OR(SUM($Q14:$U14)=0,COUNTIF($Q14:$U14,"<0")*COUNTIF($Q14:$U14,">0")>0),$G14/5,$G14*Q14/SUM($Q14:$U14)) -> 12229606 | C14: =IF(OR(SUM($Q14:$U14)=0,COUNTIF($Q14:$U14,"<0")*COUNTIF($Q14:$U14,">0")>0),$G14/5,$G14*R14/SUM($Q14:$U14)) -> 12224683 | D14: =IF(OR(SUM($Q14:$U14)=0,COUNTIF($Q14:$U14,"<0")*COUNTIF($Q14:$U14,">0")>0),$G14/5,$G14*S14/SUM($Q14:$U14)) -> 10452635 | E14: =IF(OR(SUM($Q14:$U14)=0,COUNTIF($Q14:$U14,"<0")*COUNTIF($Q14:$U14,">0")>0),$G14/5,$G14*T14/SUM($Q14:$U14)) -> 26783768 | F14: =IF(OR(SUM($Q14:$U14)=0,COUNTIF($Q14:$U14,"<0")*COUNTIF($Q14:$U14,">0")>0),$G14/5,$G14*U14/SUM($Q14:$U14)) -> 10856113 | G14: 72546804 | H14: 10634139 | I14: 14376682 | J14: 10622269 | K14: 10537675 | L14: 10487240 | M14: 11217500 | N14: 26409978 | O14: =SUM(B14:F14,H14:N14) -> 1.6683229e+08 | Q14: 12837593 | R14: 12832425 | S14: 10972281 | T14: 28115306 | U14: 11395818 | V14: 33898605 | W14: 12155137 | X14: 14170688 | Y14: =SUM(Q14:X14) -> 1.3637785e+08
B15: =IF(OR(SUM($Q15:$U15)=0,COUNTIF($Q15:$U15,"<0")*COUNTIF($Q15:$U15,">0")>0),$G15/5,$G15*Q15/SUM($Q15:$U15)) -> 0 | C15: =IF(OR(SUM($Q15:$U15)=0,COUNTIF($Q15:$U15,"<0")*COUNTIF($Q15:$U15,">0")>0),$G15/5,$G15*R15/SUM($Q15:$U15)) -> 0 | D15: =IF(OR(SUM($Q15:$U15)=0,COUNTIF($Q15:$U15,"<0")*COUNTIF($Q15:$U15,">0")>0),$G15/5,$G15*S15/SUM($Q15:$U15)) -> 0 | E15: =IF(OR(SUM($Q15:$U15)=0,COUNTIF($Q15:$U15,"<0")*COUNTIF($Q15:$U15,">0")>0),$G15/5,$G15*T15/SUM($Q15:$U15)) -> 0 | F15: =IF(OR(SUM($Q15:$U15)=0,COUNTIF($Q15:$U15,"<0")*COUNTIF($Q15:$U15,">0")>0),$G15/5,$G15*U15/SUM($Q15:$U15)) -> 0 | G15: 0 | H15: 0 | I15: 0 | J15: 0 | K15: 0 | L15: 0 | M15: 0 | N15: 0 | O15: =SUM(B15:F15,H15:N15) -> 0 | Q15: 0 | R15: 0 | S15: 0 | T15: 0 | U15: 0 | V15: 0 | W15: 0 | X15: 0 | Y15: =SUM(Q15:X15) -> 0
A16: (-) Primas por Reaseguro Cedido | B16: =IF(OR(SUM($Q16:$U16)=0,COUNTIF($Q16:$U16,"<0")*COUNTIF($Q16:$U16,">0")>0),$G16/5,$G16*Q16/SUM($Q16:$U16)) -> 6840185.9 | C16: =IF(OR(SUM($Q16:$U16)=0,COUNTIF($Q16:$U16,"<0")*COUNTIF($Q16:$U16,">0")>0),$G16/5,$G16*R16/SUM($Q16:$U16)) -> 6714668.7 | D16: =IF(OR(SUM($Q16:$U16)=0,COUNTIF($Q16:$U16,"<0")*COUNTIF($Q16:$U16,">0")>0),$G16/5,$G16*S16/SUM($Q16:$U16)) -> 4738678.1 | E16: =IF(OR(SUM($Q16:$U16)=0,COUNTIF($Q16:$U16,"<0")*COUNTIF($Q16:$U16,">0")>0),$G16/5,$G16*T16/SUM($Q16:$U16)) -> 21802814 | F16: =IF(OR(SUM($Q16:$U16)=0,COUNTIF($Q16:$U16,"<0")*COUNTIF($Q16:$U16,">0")>0),$G16/5,$G16*U16/SUM($Q16:$U16)) -> 5821907 | G16: 45918254 | H16: 5332461.2 | I16: 9240190.6 | J16: 6278339.1 | K16: 5681899.8 | L16: 5321109.8 | M16: 6384620.3 | N16: 23436890 | O16: =SUM(B16:F16,H16:N16) -> 1.0759376e+08 | Q16: 7416574.9 | R16: 7280480.9 | S16: 5137983.3 | T16: 23640031 | U16: 6312490.6 | V16: 29202471 | W16: 7521151.5 | X16: 9345196.1 | Y16: =SUM(Q16:X16) -> 95856379
B17: =IF(OR(SUM($Q17:$U17)=0,COUNTIF($Q17:$U17,"<0")*COUNTIF($Q17:$U17,">0")>0),$G17/5,$G17*Q17/SUM($Q17:$U17)) -> 0 | C17: =IF(OR(SUM($Q17:$U17)=0,COUNTIF($Q17:$U17,"<0")*COUNTIF($Q17:$U17,">0")>0),$G17/5,$G17*R17/SUM($Q17:$U17)) -> 0 | D17: =IF(OR(SUM($Q17:$U17)=0,COUNTIF($Q17:$U17,"<0")*COUNTIF($Q17:$U17,">0")>0),$G17/5,$G17*S17/SUM($Q17:$U17)) -> 0 | E17: =IF(OR(SUM($Q17:$U17)=0,COUNTIF($Q17:$U17,"<0")*COUNTIF($Q17:$U17,">0")>0),$G17/5,$G17*T17/SUM($Q17:$U17)) -> 0 | F17: =IF(OR(SUM($Q17:$U17)=0,COUNTIF($Q17:$U17,"<0")*COUNTIF($Q17:$U17,">0")>0),$G17/5,$G17*U17/SUM($Q17:$U17)) -> 0 | G17: 0 | H17: 0 | I17: 0 | J17: 0 | K17: 0 | L17: 0 | M17: 0 | N17: 0 | O17: =SUM(B17:F17,H17:N17) -> 0 | Q17: 0 | R17: 0 | S17: 0 | T17: 0 | U17: 0 | V17: 0 | W17: 0 | X17: 0 | Y17: =SUM(Q17:X17) -> 0
A18: PRIMAS NETAS DE RETENCIÓN | B18: =IF(OR(SUM($Q18:$U18)=0,COUNTIF($Q18:$U18,"<0")*COUNTIF($Q18:$U18,">0")>0),$G18/5,$G18*Q18/SUM($Q18:$U18)) -> 5475028.5 | C18: =IF(OR(SUM($Q18:$U18)=0,COUNTIF($Q18:$U18,"<0")*COUNTIF($Q18:$U18,">0")>0),$G18/5,$G18*R18/SUM($Q18:$U18)) -> 5607259.3 | D18: =IF(OR(SUM($Q18:$U18)=0,COUNTIF($Q18:$U18,"<0")*COUNTIF($Q18:$U18,">0")>0),$G18/5,$G18*S18/SUM($Q18:$U18)) -> 5892425.7 | E18: =IF(OR(SUM($Q18:$U18)=0,COUNTIF($Q18:$U18,"<0")*COUNTIF($Q18:$U18,">0")>0),$G18/5,$G18*T18/SUM($Q18:$U18)) -> 4519863.4 | F18: =IF(OR(SUM($Q18:$U18)=0,COUNTIF($Q18:$U18,"<0")*COUNTIF($Q18:$U18,">0")>0),$G18/5,$G18*U18/SUM($Q18:$U18)) -> 5133973.3 | G18: 26628550 | H18: 5301678.3 | I18: 5136490.9 | J18: 4343930.1 | K18: 4855774.8 | L18: 5166130.2 | M18: 4832879.6 | N18: 2973088 | O18: =SUM(B18:F18,H18:N18) -> 59238522 | Q18: 5421018.1 | R18: 5551944.4 | S18: 5834297.7 | T18: 4475275.6 | U18: 5083327.4 | V18: 4696133.8 | W18: 4633985.6 | X18: 4825491.6 | Y18: =SUM(Q18:X18) -> 40521474
B19: =IF(OR(SUM($Q19:$U19)=0,COUNTIF($Q19:$U19,"<0")*COUNTIF($Q19:$U19,">0")>0),$G19/5,$G19*Q19/SUM($Q19:$U19)) -> 0 | C19: =IF(OR(SUM($Q19:$U19)=0,COUNTIF($Q19:$U19,"<0")*COUNTIF($Q19:$U19,">0")>0),$G19/5,$G19*R19/SUM($Q19:$U19)) -> 0 | D19: =IF(OR(SUM($Q19:$U19)=0,COUNTIF($Q19:$U19,"<0")*COUNTIF($Q19:$U19,">0")>0),$G19/5,$G19*S19/SUM($Q19:$U19)) -> 0 | E19: =IF(OR(SUM($Q19:$U19)=0,COUNTIF($Q19:$U19,"<0")*COUNTIF($Q19:$U19,">0")>0),$G19/5,$G19*T19/SUM($Q19:$U19)) -> 0 | F19: =IF(OR(SUM($Q19:$U19)=0,COUNTIF($Q19:$U19,"<0")*COUNTIF($Q19:$U19,">0")>0),$G19/5,$G19*U19/SUM($Q19:$U19)) -> 0 | G19: 0 | H19: 0 | I19: 0 | J19: 0 | K19: 0 | L19: 0 | M19: 0 | N19: 0 | O19: =SUM(B19:F19,H19:N19) -> 0 | Q19: 0 | R19: 0 | S19: 0 | T19: 0 | U19: 0 | V19: 0 | W19: 0 | X19: 0 | Y19: =SUM(Q19:X19) -> 0
A20: VARIACIONES EN RESERVAS TÉCNICAS Y MATEMÁTICAS | B20: =IF(OR(SUM($Q20:$U20)=0,COUNTIF($Q20:$U20,"<0")*COUNTIF($Q20:$U20,">0")>0),$G20/5,$G20*Q20/SUM($Q20:$U20)) -> 314296.11 | C20: =IF(OR(SUM($Q20:$U20)=0,COUNTIF($Q20:$U20,"<0")*COUNTIF($Q20:$U20,">0")>0),$G20/5,$G20*R20/SUM($Q20:$U20)) -> 314296.11 | D20: =IF(OR(SUM($Q20:$U20)=0,COUNTIF($Q20:$U20,"<0")*COUNTIF($Q20:$U20,">0")>0),$G20/5,$G20*S20/SUM($Q20:$U20)) -> 314296.11 | E20: =IF(OR(SUM($Q20:$U20)=0,COUNTIF($Q20:$U20,"<0")*COUNTIF($Q20:$U20,">0")>0),$G20/5,$G20*T20/SUM($Q20:$U20)) -> 314296.11 | F20: =IF(OR(SUM($Q20:$U20)=0,COUNTIF($Q20:$U20,"<0")*COUNTIF($Q20:$U20,">0")>0),$G20/5,$G20*U20/SUM($Q20:$U20)) -> 314296.11 | G20: 1571480.6 | H20: -135634.59 | I20: -153831.09 | J20: -34982.13 | K20: -464571.7 | L20: 909082.78 | M20: -116891.9 | N20: 297725.71 | O20: =SUM(B20:F20,H20:N20) -> 1872377.6 | Q20: 838498.55 | R20: 814014.5 | S20: 480171.88 | T20: 183420.76 | U20: -26680.33 | V20: -195192.12 | W20: -78094.74 | X20: -396325.71 | Y20: =SUM(Q20:X20) -> 1619812.8
A21: (-) Variaciones Gastos | B21: =IF(OR(SUM($Q21:$U21)=0,COUNTIF($Q21:$U21,"<0")*COUNTIF($Q21:$U21,">0")>0),$G21/5,$G21*Q21/SUM($Q21:$U21)) -> 3425537.8 | C21: =IF(OR(SUM($Q21:$U21)=0,COUNTIF($Q21:$U21,"<0")*COUNTIF($Q21:$U21,">0")>0),$G21/5,$G21*R21/SUM($Q21:$U21)) -> 1506283 | D21: =IF(OR(SUM($Q21:$U21)=0,COUNTIF($Q21:$U21,"<0")*COUNTIF($Q21:$U21,">0")>0),$G21/5,$G21*S21/SUM($Q21:$U21)) -> 1539845.3 | E21: =IF(OR(SUM($Q21:$U21)=0,COUNTIF($Q21:$U21,"<0")*COUNTIF($Q21:$U21,">0")>0),$G21/5,$G21*T21/SUM($Q21:$U21)) -> 1129320.7 | F21: =IF(OR(SUM($Q21:$U21)=0,COUNTIF($Q21:$U21,"<0")*COUNTIF($Q21:$U21,">0")>0),$G21/5,$G21*U21/SUM($Q21:$U21)) -> 1260433.6 | G21: 8861420.5 | H21: 1172943.4 | I21: 1463092.4 | J21: 2114371.8 | K21: 1835581.7 | L21: 2053124.8 | M21: 1360517.2 | N21: 1600675 | O21: =SUM(B21:F21,H21:N21) -> 20461727 | Q21: 4648560.5 | R21: 2044072.5 | S21: 2089617.6 | T21: 1532523.1 | U21: 1710447.3 | V21: 1420618.8 | W21: 1519815.4 | X21: 1199790.8 | Y21: =SUM(Q21:X21) -> 16165446
A22: (+) Variaciones Productos | B22: =IF(OR(SUM($Q22:$U22)=0,COUNTIF($Q22:$U22,"<0")*COUNTIF($Q22:$U22,">0")>0),$G22/5,$G22*Q22/SUM($Q22:$U22)) -> 2852886.8 | C22: =IF(OR(SUM($Q22:$U22)=0,COUNTIF($Q22:$U22,"<0")*COUNTIF($Q22:$U22,">0")>0),$G22/5,$G22*R22/SUM($Q22:$U22)) -> 921039.16 | D22: =IF(OR(SUM($Q22:$U22)=0,COUNTIF($Q22:$U22,"<0")*COUNTIF($Q22:$U22,">0")>0),$G22/5,$G22*S22/SUM($Q22:$U22)) -> 1205116 | E22: =IF(OR(SUM($Q22:$U22)=0,COUNTIF($Q22:$U22,"<0")*COUNTIF($Q22:$U22,">0")>0),$G22/5,$G22*T22/SUM($Q22:$U22)) -> 1010176.8 | F22: =IF(OR(SUM($Q22:$U22)=0,COUNTIF($Q22:$U22,"<0")*COUNTIF($Q22:$U22,">0")>0),$G22/5,$G22*U22/SUM($Q22:$U22)) -> 1300721.2 | G22: 7289939.9 | H22: 1308578 | I22: 1616923.5 | J22: 2149353.9 | K22: 2300153.4 | L22: 1144042 | M22: 1477409.1 | N22: 1302949.3 | O22: =SUM(B22:F22,H22:N22) -> 18589349 | Q22: 3810061.9 | R22: 1230058 | S22: 1609445.8 | T22: 1349102.3 | U22: 1737127.6 | V22: 1615811 | W22: 1597910.1 | X22: 1596116.5 | Y22: =SUM(Q22:X22) -> 14545633
A23: PRIMAS NETAS DE RETENCIÓN DEVENGADAS | B23: =IF(OR(SUM($Q23:$U23)=0,COUNTIF($Q23:$U23,"<0")*COUNTIF($Q23:$U23,">0")>0),$G23/5,$G23*Q23/SUM($Q23:$U23)) -> 4769165.2 | C23: =IF(OR(SUM($Q23:$U23)=0,COUNTIF($Q23:$U23,"<0")*COUNTIF($Q23:$U23,">0")>0),$G23/5,$G23*R23/SUM($Q23:$U23)) -> 4930905.5 | D23: =IF(OR(SUM($Q23:$U23)=0,COUNTIF($Q23:$U23,"<0")*COUNTIF($Q23:$U23,">0")>0),$G23/5,$G23*S23/SUM($Q23:$U23)) -> 5572199.1 | E23: =IF(OR(SUM($Q23:$U23)=0,COUNTIF($Q23:$U23,"<0")*COUNTIF($Q23:$U23,">0")>0),$G23/5,$G23*T23/SUM($Q23:$U23)) -> 4466661.8 | F23: =IF(OR(SUM($Q23:$U23)=0,COUNTIF($Q23:$U23,"<0")*COUNTIF($Q23:$U23,">0")>0),$G23/5,$G23*U23/SUM($Q23:$U23)) -> 5318138 | G23: 25057070 | H23: 5437312.9 | I23: 5290322 | J23: 4378912.2 | K23: 5320346.5 | L23: 4257047.4 | M23: 4949771.5 | N23: 2675362.3 | O23: =SUM(B23:F23,H23:N23) -> 57366144 | Q23: 4582519.5 | R23: 4737929.9 | S23: 5354125.9 | T23: 4291854.9 | U23: 5110007.7 | V23: 4891325.9 | W23: 4712080.3 | X23: 5221817.3 | Y23: =SUM(Q23:X23) -> 38901661
B24: =IF(OR(SUM($Q24:$U24)=0,COUNTIF($Q24:$U24,"<0")*COUNTIF($Q24:$U24,">0")>0),$G24/5,$G24*Q24/SUM($Q24:$U24)) -> 0 | C24: =IF(OR(SUM($Q24:$U24)=0,COUNTIF($Q24:$U24,"<0")*COUNTIF($Q24:$U24,">0")>0),$G24/5,$G24*R24/SUM($Q24:$U24)) -> 0 | D24: =IF(OR(SUM($Q24:$U24)=0,COUNTIF($Q24:$U24,"<0")*COUNTIF($Q24:$U24,">0")>0),$G24/5,$G24*S24/SUM($Q24:$U24)) -> 0 | E24: =IF(OR(SUM($Q24:$U24)=0,COUNTIF($Q24:$U24,"<0")*COUNTIF($Q24:$U24,">0")>0),$G24/5,$G24*T24/SUM($Q24:$U24)) -> 0 | F24: =IF(OR(SUM($Q24:$U24)=0,COUNTIF($Q24:$U24,"<0")*COUNTIF($Q24:$U24,">0")>0),$G24/5,$G24*U24/SUM($Q24:$U24)) -> 0 | G24: 0 | H24: 0 | I24: 0 | J24: 0 | K24: 0 | L24: 0 | M24: 0 | N24: 0 | O24: =SUM(B24:F24,H24:N24) -> 0 | Q24: 0 | R24: 0 | S24: 0 | T24: 0 | U24: 0 | V24: 0 | W24: 0 | X24: 0 | Y24: =SUM(Q24:X24) -> 0
A25: (-) COSTO DE ADQUISICIÓN Y SINIESTRALIDAD | B25: =IF(OR(SUM($Q25:$U25)=0,COUNTIF($Q25:$U25,"<0")*COUNTIF($Q25:$U25,">0")>0),$G25/5,$G25*Q25/SUM($Q25:$U25)) -> 164303.92 | C25: =IF(OR(SUM($Q25:$U25)=0,COUNTIF($Q25:$U25,"<0")*COUNTIF($Q25:$U25,">0")>0),$G25/5,$G25*R25/SUM($Q25:$U25)) -> 240830.1 | D25: =IF(OR(SUM($Q25:$U25)=0,COUNTIF($Q25:$U25,"<0")*COUNTIF($Q25:$U25,">0")>0),$G25/5,$G25*S25/SUM($Q25:$U25)) -> 270670.48 | E25: =IF(OR(SUM($Q25:$U25)=0,COUNTIF($Q25:$U25,"<0")*COUNTIF($Q25:$U25,">0")>0),$G25/5,$G25*T25/SUM($Q25:$U25)) -> 318819.31 | F25: =IF(OR(SUM($Q25:$U25)=0,COUNTIF($Q25:$U25,"<0")*COUNTIF($Q25:$U25,">0")>0),$G25/5,$G25*U25/SUM($Q25:$U25)) -> 214291.62 | G25: 1208915.4 | H25: 1063644.8 | I25: 435519.9 | J25: 1327989.1 | K25: 1183296.7 | L25: 1032883.2 | M25: 383966.96 | N25: 924714.52 | O25: =SUM(B25:F25,H25:N25) -> 7560930.6 | Q25: 676646.22 | R25: 991800.92 | S25: 1114691.4 | T25: 1312980.8 | U25: 882508.56 | V25: 874443.27 | W25: -225298.98 | X25: 2357603.1 | Y25: =SUM(Q25:X25) -> 7985375.2
A26: ADQUISICIÓN | B26: =IF(OR(SUM($Q26:$U26)=0,COUNTIF($Q26:$U26,"<0")*COUNTIF($Q26:$U26,">0")>0),$G26/5,$G26*Q26/SUM($Q26:$U26)) -> -129036.28 | C26: =IF(OR(SUM($Q26:$U26)=0,COUNTIF($Q26:$U26,"<0")*COUNTIF($Q26:$U26,">0")>0),$G26/5,$G26*R26/SUM($Q26:$U26)) -> -129036.28 | D26: =IF(OR(SUM($Q26:$U26)=0,COUNTIF($Q26:$U26,"<0")*COUNTIF($Q26:$U26,">0")>0),$G26/5,$G26*S26/SUM($Q26:$U26)) -> -129036.28 | E26: =IF(OR(SUM($Q26:$U26)=0,COUNTIF($Q26:$U26,"<0")*COUNTIF($Q26:$U26,">0")>0),$G26/5,$G26*T26/SUM($Q26:$U26)) -> -129036.28 | F26: =IF(OR(SUM($Q26:$U26)=0,COUNTIF($Q26:$U26,"<0")*COUNTIF($Q26:$U26,">0")>0),$G26/5,$G26*U26/SUM($Q26:$U26)) -> -129036.28 | G26: -645181.38 | H26: 398917.38 | I26: 52411.17 | J26: 125744.51 | K26: 536292.23 | L26: 609577.07 | M26: -728140.02 | N26: -301098.24 | O26: =SUM(B26:F26,H26:N26) -> 48522.72 | Q26: 64843.15 | R26: 67707.22 | S26: 15677.6 | T26: 316734.26 | U26: -261306.68 | V26: -167891.65 | W26: 365577.8 | X26: 549618.85 | Y26: =SUM(Q26:X26) -> 950960.55
A27: (+) Gastos de Adquisición y Renovación | B27: =IF(OR(SUM($Q27:$U27)=0,COUNTIF($Q27:$U27,"<0")*COUNTIF($Q27:$U27,">0")>0),$G27/5,$G27*Q27/SUM($Q27:$U27)) -> 1683128.8 | C27: =IF(OR(SUM($Q27:$U27)=0,COUNTIF($Q27:$U27,"<0")*COUNTIF($Q27:$U27,">0")>0),$G27/5,$G27*R27/SUM($Q27:$U27)) -> 1614278.2 | D27: =IF(OR(SUM($Q27:$U27)=0,COUNTIF($Q27:$U27,"<0")*COUNTIF($Q27:$U27,">0")>0),$G27/5,$G27*S27/SUM($Q27:$U27)) -> 1377431.5 | E27: =IF(OR(SUM($Q27:$U27)=0,COUNTIF($Q27:$U27,"<0")*COUNTIF($Q27:$U27,">0")>0),$G27/5,$G27*T27/SUM($Q27:$U27)) -> 2138947.6 | F27: =IF(OR(SUM($Q27:$U27)=0,COUNTIF($Q27:$U27,"<0")*COUNTIF($Q27:$U27,">0")>0),$G27/5,$G27*U27/SUM($Q27:$U27)) -> 1695349.3 | G27: 8509135.4 | H27: 1430908.3 | I27: 1675048.1 | J27: 1717279.3 | K27: 1783506.2 | L27: 1350012 | M27: 688668.2 | N27: 3648254 | O27: =SUM(B27:F27,H27:N27) -> 20802812 | Q27: 2019888.8 | R27: 1937262.6 | S27: 1653027.8 | T27: 2566907.8 | U27: 2034554.4 | V27: 1494772 | W27: 2015394.9 | X27: 2268495.5 | Y27: =SUM(Q27:X27) -> 15990304
A28: (-) Comisiones y Participaciones por Reaseguro Cedido | B28: =IF(OR(SUM($Q28:$U28)=0,COUNTIF($Q28:$U28,"<0")*COUNTIF($Q28:$U28,">0")>0),$G28/5,$G28*Q28/SUM($Q28:$U28)) -> 1788282.6 | C28: =IF(OR(SUM($Q28:$U28)=0,COUNTIF($Q28:$U28,"<0")*COUNTIF($Q28:$U28,">0")>0),$G28/5,$G28*R28/SUM($Q28:$U28)) -> 1710084.6 | D28: =IF(OR(SUM($Q28:$U28)=0,COUNTIF($Q28:$U28,"<0")*COUNTIF($Q28:$U28,">0")>0),$G28/5,$G28*S28/SUM($Q28:$U28)) -> 1497686.2 | E28: =IF(OR(SUM($Q28:$U28)=0,COUNTIF($Q28:$U28,"<0")*COUNTIF($Q28:$U28,">0")>0),$G28/5,$G28*T28/SUM($Q28:$U28)) -> 2058236.5 | F28: =IF(OR(SUM($Q28:$U28)=0,COUNTIF($Q28:$U28,"<0")*COUNTIF($Q28:$U28,">0")>0),$G28/5,$G28*U28/SUM($Q28:$U28)) -> 2100026.9 | G28: 9154316.8 | H28: 1031991 | I28: 1622636.9 | J28: 1591534.8 | K28: 1247214 | L28: 740434.9 | M28: 1416808.2 | N28: 3949352.2 | O28: =SUM(B28:F28,H28:N28) -> 20754289 | Q28: 1955045.7 | R28: 1869555.4 | S28: 1637350.2 | T28: 2250173.5 | U28: 2295861.1 | V28: 1662663.7 | W28: 1649817.1 | X28: 1718876.7 | Y28: =SUM(Q28:X28) -> 15039343
A29: SINIESTRALIDAD | B29: =IF(OR(SUM($Q29:$U29)=0,COUNTIF($Q29:$U29,"<0")*COUNTIF($Q29:$U29,">0")>0),$G29/5,$G29*Q29/SUM($Q29:$U29)) -> 237559.94 | C29: =IF(OR(SUM($Q29:$U29)=0,COUNTIF($Q29:$U29,"<0")*COUNTIF($Q29:$U29,">0")>0),$G29/5,$G29*R29/SUM($Q29:$U29)) -> 358820.76 | D29: =IF(OR(SUM($Q29:$U29)=0,COUNTIF($Q29:$U29,"<0")*COUNTIF($Q29:$U29,">0")>0),$G29/5,$G29*S29/SUM($Q29:$U29)) -> 426741.3 | E29: =IF(OR(SUM($Q29:$U29)=0,COUNTIF($Q29:$U29,"<0")*COUNTIF($Q29:$U29,">0")>0),$G29/5,$G29*T29/SUM($Q29:$U29)) -> 386837.32 | F29: =IF(OR(SUM($Q29:$U29)=0,COUNTIF($Q29:$U29,"<0")*COUNTIF($Q29:$U29,">0")>0),$G29/5,$G29*U29/SUM($Q29:$U29)) -> 444137.49 | G29: 1854096.8 | H29: 664727.42 | I29: 383108.73 | J29: 1202244.6 | K29: 647004.48 | L29: 423306.16 | M29: 1112107 | N29: 1225812.8 | O29: =SUM(B29:F29,H29:N29) -> 7512407.9 | Q29: 611803.07 | R29: 924093.7 | S29: 1099013.8 | T29: 996246.5 | U29: 1143815.2 | V29: 1042334.9 | W29: -590876.78 | X29: 1807984.2 | Y29: =SUM(Q29:X29) -> 7034414.6
A30: (+) Gastos Por Obligaciones Contractuales | B30: =IF(OR(SUM($Q30:$U30)=0,COUNTIF($Q30:$U30,"<0")*COUNTIF($Q30:$U30,">0")>0),$G30/5,$G30*Q30/SUM($Q30:$U30)) -> 1066032.4 | C30: =IF(OR(SUM($Q30:$U30)=0,COUNTIF($Q30:$U30,"<0")*COUNTIF($Q30:$U30,">0")>0),$G30/5,$G30*R30/SUM($Q30:$U30)) -> 1341878.6 | D30: =IF(OR(SUM($Q30:$U30)=0,COUNTIF($Q30:$U30,"<0")*COUNTIF($Q30:$U30,">0")>0),$G30/5,$G30*S30/SUM($Q30:$U30)) -> 1631248.4 | E30: =IF(OR(SUM($Q30:$U30)=0,COUNTIF($Q30:$U30,"<0")*COUNTIF($Q30:$U30,">0")>0),$G30/5,$G30*T30/SUM($Q30:$U30)) -> 1255471.9 | F30: =IF(OR(SUM($Q30:$U30)=0,COUNTIF($Q30:$U30,"<0")*COUNTIF($Q30:$U30,">0")>0),$G30/5,$G30*U30/SUM($Q30:$U30)) -> 1074098.1 | G30: 6368729.4 | H30: 3706019.3 | I30: 16095670 | J30: 36824121 | K30: 13977736 | L30: 4427131.3 | M30: 5855169.9 | N30: -21565323 | O30: =SUM(B30:F30,H30:N30) -> 65689254 | Q30: 3814554.2 | R30: 4801607.3 | S30: 5837051.3 | T30: 4492420.5 | U30: 3843415.6 | V30: 4994499 | W30: 4938376.9 | X30: 7820157 | Y30: =SUM(Q30:X30) -> 40542082
A31: (+) Participa. Reaseguradoras en Salvamentos y Recup. | B31: =IF(OR(SUM($Q31:$U31)=0,COUNTIF($Q31:$U31,"<0")*COUNTIF($Q31:$U31,">0")>0),$G31/5,$G31*Q31/SUM($Q31:$U31)) -> 284220.11 | C31: =IF(OR(SUM($Q31:$U31)=0,COUNTIF($Q31:$U31,"<0")*COUNTIF($Q31:$U31,">0")>0),$G31/5,$G31*R31/SUM($Q31:$U31)) -> 234585.09 | D31: =IF(OR(SUM($Q31:$U31)=0,COUNTIF($Q31:$U31,"<0")*COUNTIF($Q31:$U31,">0")>0),$G31/5,$G31*S31/SUM($Q31:$U31)) -> 664227.48 | E31: =IF(OR(SUM($Q31:$U31)=0,COUNTIF($Q31:$U31,"<0")*COUNTIF($Q31:$U31,">0")>0),$G31/5,$G31*T31/SUM($Q31:$U31)) -> 937074.42 | F31: =IF(OR(SUM($Q31:$U31)=0,COUNTIF($Q31:$U31,"<0")*COUNTIF($Q31:$U31,">0")>0),$G31/5,$G31*U31/SUM($Q31:$U31)) -> 633385.24 | G31: 2753492.3 | H31: 501809.54 | I31: 304547.35 | J31: 257490.34 | K31: 1428087.7 | L31: 319384.54 | M31: 551962.07 | N31: 439507.8 | O31: =SUM(B31:F31,H31:N31) -> 6556281.6 | Q31: 163569.15 | R31: 135004.11 | S31: 382264.03 | T31: 539287.9 | U31: 364514.27 | V31: 298496.35 | W31: 680146.03 | X31: 428071.1 | Y31: =SUM(Q31:X31) -> 2991352.9
A32: (+) Variación en Reservas de Reclamaciones de Seguro de Caución (Neto) | B32: =IF(OR(SUM($Q32:$U32)=0,COUNTIF($Q32:$U32,"<0")*COUNTIF($Q32:$U32,">0")>0),$G32/5,$G32*Q32/SUM($Q32:$U32)) -> 0 | C32: =IF(OR(SUM($Q32:$U32)=0,COUNTIF($Q32:$U32,"<0")*COUNTIF($Q32:$U32,">0")>0),$G32/5,$G32*R32/SUM($Q32:$U32)) -> 0 | D32: =IF(OR(SUM($Q32:$U32)=0,COUNTIF($Q32:$U32,"<0")*COUNTIF($Q32:$U32,">0")>0),$G32/5,$G32*S32/SUM($Q32:$U32)) -> 0 | E32: =IF(OR(SUM($Q32:$U32)=0,COUNTIF($Q32:$U32,"<0")*COUNTIF($Q32:$U32,">0")>0),$G32/5,$G32*T32/SUM($Q32:$U32)) -> 0 | F32: =IF(OR(SUM($Q32:$U32)=0,COUNTIF($Q32:$U32,"<0")*COUNTIF($Q32:$U32,">0")>0),$G32/5,$G32*U32/SUM($Q32:$U32)) -> 0 | G32: 0 | H32: 0 | I32: 0 | J32: 0 | K32: 0 | L32: 0 | M32: 0 | N32: 0 | O32: =SUM(B32:F32,H32:N32) -> 0 | Q32: 0 | R32: 0 | S32: 0 | T32: 0 | U32: 0 | V32: 0 | W32: 0 | X32: 0 | Y32: =SUM(Q32:X32) -> 0
A33: (-) Recuperaciones por Reaseguro Cedido | B33: =IF(OR(SUM($Q33:$U33)=0,COUNTIF($Q33:$U33,"<0")*COUNTIF($Q33:$U33,">0")>0),$G33/5,$G33*Q33/SUM($Q33:$U33)) -> 481634.12 | C33: =IF(OR(SUM($Q33:$U33)=0,COUNTIF($Q33:$U33,"<0")*COUNTIF($Q33:$U33,">0")>0),$G33/5,$G33*R33/SUM($Q33:$U33)) -> 600963.13 | D33: =IF(OR(SUM($Q33:$U33)=0,COUNTIF($Q33:$U33,"<0")*COUNTIF($Q33:$U33,">0")>0),$G33/5,$G33*S33/SUM($Q33:$U33)) -> 730003.68 | E33: =IF(OR(SUM($Q33:$U33)=0,COUNTIF($Q33:$U33,"<0")*COUNTIF($Q33:$U33,">0")>0),$G33/5,$G33*T33/SUM($Q33:$U33)) -> 538949.36 | F33: =IF(OR(SUM($Q33:$U33)=0,COUNTIF($Q33:$U33,"<0")*COUNTIF($Q33:$U33,">0")>0),$G33/5,$G33*U33/SUM($Q33:$U33)) -> 390170.25 | G33: 2741720.5 | H33: 2748141.3 | I33: 15438857 | J33: 35397355 | K33: 13119396 | L33: 3706290.5 | M33: 4585760.6 | N33: -24056629 | O33: =SUM(B33:F33,H33:N33) -> 53680893 | Q33: 2947903 | R33: 3678271.5 | S33: 4468080.6 | T33: 3298708.3 | U33: 2388086.8 | V33: 3321704.3 | W33: 3439087.6 | X33: 5752786.2 | Y33: =SUM(Q33:X33) -> 29294628
A34: (-) Salvamentos y Recuperaciones | B34: =IF(OR(SUM($Q34:$U34)=0,COUNTIF($Q34:$U34,"<0")*COUNTIF($Q34:$U34,">0")>0),$G34/5,$G34*Q34/SUM($Q34:$U34)) -> 672161.17 | C34: =IF(OR(SUM($Q34:$U34)=0,COUNTIF($Q34:$U34,"<0")*COUNTIF($Q34:$U34,">0")>0),$G34/5,$G34*R34/SUM($Q34:$U34)) -> 536945.75 | D34: =IF(OR(SUM($Q34:$U34)=0,COUNTIF($Q34:$U34,"<0")*COUNTIF($Q34:$U34,">0")>0),$G34/5,$G34*S34/SUM($Q34:$U34)) -> 1047752.2 | E34: =IF(OR(SUM($Q34:$U34)=0,COUNTIF($Q34:$U34,"<0")*COUNTIF($Q34:$U34,">0")>0),$G34/5,$G34*T34/SUM($Q34:$U34)) -> 1183548.7 | F34: =IF(OR(SUM($Q34:$U34)=0,COUNTIF($Q34:$U34,"<0")*COUNTIF($Q34:$U34,">0")>0),$G34/5,$G34*U34/SUM($Q34:$U34)) -> 1085996.5 | G34: 4526404.3 | H34: 794960.15 | I34: 578251.57 | J34: 482011.86 | K34: 1639423.2 | L34: 616919.22 | M34: 709264.37 | N34: 1705000.4 | O34: =SUM(B34:F34,H34:N34) -> 11052235 | Q34: 418417.23 | R34: 334246.25 | S34: 652220.91 | T34: 736753.59 | U34: 676027.84 | V34: 928956.04 | W34: 2770312.2 | X34: 687457.72 | Y34: =SUM(Q34:X34) -> 7204391.7
B35: =IF(OR(SUM($Q35:$U35)=0,COUNTIF($Q35:$U35,"<0")*COUNTIF($Q35:$U35,">0")>0),$G35/5,$G35*Q35/SUM($Q35:$U35)) -> 0 | C35: =IF(OR(SUM($Q35:$U35)=0,COUNTIF($Q35:$U35,"<0")*COUNTIF($Q35:$U35,">0")>0),$G35/5,$G35*R35/SUM($Q35:$U35)) -> 0 | D35: =IF(OR(SUM($Q35:$U35)=0,COUNTIF($Q35:$U35,"<0")*COUNTIF($Q35:$U35,">0")>0),$G35/5,$G35*S35/SUM($Q35:$U35)) -> 0 | E35: =IF(OR(SUM($Q35:$U35)=0,COUNTIF($Q35:$U35,"<0")*COUNTIF($Q35:$U35,">0")>0),$G35/5,$G35*T35/SUM($Q35:$U35)) -> 0 | F35: =IF(OR(SUM($Q35:$U35)=0,COUNTIF($Q35:$U35,"<0")*COUNTIF($Q35:$U35,">0")>0),$G35/5,$G35*U35/SUM($Q35:$U35)) -> 0 | G35: 0 | H35: 0 | I35: 0 | J35: 0 | K35: 0 | L35: 0 | M35: 0 | N35: 0 | O35: =SUM(B35:F35,H35:N35) -> 0 | Q35: 0 | R35: 0 | S35: 0 | T35: 0 | U35: 0 | V35: 0 | W35: 0 | X35: 0 | Y35: =SUM(Q35:X35) -> 0
A36: UTILIDAD BRUTA EN OPERACIONES DE SEGUROS | B36: =IF(OR(SUM($Q36:$U36)=0,COUNTIF($Q36:$U36,"<0")*COUNTIF($Q36:$U36,">0")>0),$G36/5,$G36*Q36/SUM($Q36:$U36)) -> 4877411 | C36: =IF(OR(SUM($Q36:$U36)=0,COUNTIF($Q36:$U36,"<0")*COUNTIF($Q36:$U36,">0")>0),$G36/5,$G36*R36/SUM($Q36:$U36)) -> 4677932.3 | D36: =IF(OR(SUM($Q36:$U36)=0,COUNTIF($Q36:$U36,"<0")*COUNTIF($Q36:$U36,">0")>0),$G36/5,$G36*S36/SUM($Q36:$U36)) -> 5293941.4 | E36: =IF(OR(SUM($Q36:$U36)=0,COUNTIF($Q36:$U36,"<0")*COUNTIF($Q36:$U36,">0")>0),$G36/5,$G36*T36/SUM($Q36:$U36)) -> 3719832.2 | F36: =IF(OR(SUM($Q36:$U36)=0,COUNTIF($Q36:$U36,"<0")*COUNTIF($Q36:$U36,">0")>0),$G36/5,$G36*U36/SUM($Q36:$U36)) -> 5279037.3 | G36: 23848154 | H36: 4373668.1 | I36: 4854802.1 | J36: 3050923.1 | K36: 4137049.8 | L36: 3224164.2 | M36: 4565804.5 | N36: 1750647.8 | O36: =SUM(B36:F36,H36:N36) -> 49805214 | Q36: 3905873.3 | R36: 3746129 | S36: 4239434.5 | T36: 2978874.1 | U36: 4227499.2 | V36: 4016882.6 | W36: 4937379.3 | X36: 2864214.2 | Y36: =SUM(Q36:X36) -> 30916286
A37: (-) GASTOS Y PRODUCTOS DE OPERACIONES | B37: =IF(OR(SUM($Q37:$U37)=0,COUNTIF($Q37:$U37,"<0")*COUNTIF($Q37:$U37,">0")>0),$G37/5,$G37*Q37/SUM($Q37:$U37)) -> 3928629.6 | C37: =IF(OR(SUM($Q37:$U37)=0,COUNTIF($Q37:$U37,"<0")*COUNTIF($Q37:$U37,">0")>0),$G37/5,$G37*R37/SUM($Q37:$U37)) -> 3596784.5 | D37: =IF(OR(SUM($Q37:$U37)=0,COUNTIF($Q37:$U37,"<0")*COUNTIF($Q37:$U37,">0")>0),$G37/5,$G37*S37/SUM($Q37:$U37)) -> 3680797.8 | E37: =IF(OR(SUM($Q37:$U37)=0,COUNTIF($Q37:$U37,"<0")*COUNTIF($Q37:$U37,">0")>0),$G37/5,$G37*T37/SUM($Q37:$U37)) -> 3374405.1 | F37: =IF(OR(SUM($Q37:$U37)=0,COUNTIF($Q37:$U37,"<0")*COUNTIF($Q37:$U37,">0")>0),$G37/5,$G37*U37/SUM($Q37:$U37)) -> 3523494.2 | G37: 18104111 | H37: 3557207.5 | I37: 3369378 | J37: 3384760 | K37: 3461068.7 | L37: 2952864 | M37: 3748911.7 | N37: 3173549.2 | O37: =SUM(B37:F37,H37:N37) -> 41751850 | Q37: 3900040.5 | R37: 3570610.3 | S37: 3654012.2 | T37: 3349849.2 | U37: 3497853.4 | V37: 3175304.6 | W37: 4098391.4 | X37: 2954141.6 | Y37: =SUM(Q37:X37) -> 28200203
A38: (+) Egresos por Inversiones | B38: =IF(OR(SUM($Q38:$U38)=0,COUNTIF($Q38:$U38,"<0")*COUNTIF($Q38:$U38,">0")>0),$G38/5,$G38*Q38/SUM($Q38:$U38)) -> 51698.082 | C38: =IF(OR(SUM($Q38:$U38)=0,COUNTIF($Q38:$U38,"<0")*COUNTIF($Q38:$U38,">0")>0),$G38/5,$G38*R38/SUM($Q38:$U38)) -> 40744.473 | D38: =IF(OR(SUM($Q38:$U38)=0,COUNTIF($Q38:$U38,"<0")*COUNTIF($Q38:$U38,">0")>0),$G38/5,$G38*S38/SUM($Q38:$U38)) -> 42112.21 | E38: =IF(OR(SUM($Q38:$U38)=0,COUNTIF($Q38:$U38,"<0")*COUNTIF($Q38:$U38,">0")>0),$G38/5,$G38*T38/SUM($Q38:$U38)) -> 53801.378 | F38: =IF(OR(SUM($Q38:$U38)=0,COUNTIF($Q38:$U38,"<0")*COUNTIF($Q38:$U38,">0")>0),$G38/5,$G38*U38/SUM($Q38:$U38)) -> 52219.107 | G38: 240575.25 | H38: 47738.92 | I38: 63134.34 | J38: 59731.42 | K38: 58352.1 | L38: 32724.25 | M38: 73098.65 | N38: 87990.76 | O38: =SUM(B38:F38,H38:N38) -> 663345.69 | Q38: 67895.87 | R38: 53510.33 | S38: 55306.6 | T38: 70658.16 | U38: 68580.14 | V38: 58791.34 | W38: 83318.89 | X38: 52339.96 | Y38: =SUM(Q38:X38) -> 510401.29
A39: (+) Gastos de Administración | B39: =IF(OR(SUM($Q39:$U39)=0,COUNTIF($Q39:$U39,"<0")*COUNTIF($Q39:$U39,">0")>0),$G39/5,$G39*Q39/SUM($Q39:$U39)) -> 4806922.2 | C39: =IF(OR(SUM($Q39:$U39)=0,COUNTIF($Q39:$U39,"<0")*COUNTIF($Q39:$U39,">0")>0),$G39/5,$G39*R39/SUM($Q39:$U39)) -> 4474658.4 | D39: =IF(OR(SUM($Q39:$U39)=0,COUNTIF($Q39:$U39,"<0")*COUNTIF($Q39:$U39,">0")>0),$G39/5,$G39*S39/SUM($Q39:$U39)) -> 4435703.8 | E39: =IF(OR(SUM($Q39:$U39)=0,COUNTIF($Q39:$U39,"<0")*COUNTIF($Q39:$U39,">0")>0),$G39/5,$G39*T39/SUM($Q39:$U39)) -> 4487152 | F39: =IF(OR(SUM($Q39:$U39)=0,COUNTIF($Q39:$U39,"<0")*COUNTIF($Q39:$U39,">0")>0),$G39/5,$G39*U39/SUM($Q39:$U39)) -> 4361363.3 | G39: 22565800 | H39: 4312301.6 | I39: 4263284.6 | J39: 4117224.5 | K39: 4219699 | L39: 3810952.2 | M39: 4393202.7 | N39: 4390513.8 | O39: =SUM(B39:F39,H39:N39) -> 52072978 | Q39: 4657304.4 | R39: 4335382.5 | S39: 4297640.3 | T39: 4347487.2 | U39: 4225613.7 | V39: 4526186.6 | W39: 4832549.6 | X39: 3811321.8 | Y39: =SUM(Q39:X39) -> 35033486
A40: (-) Derechos de Emisión de Pólizas (Neto) | B40: =IF(OR(SUM($Q40:$U40)=0,COUNTIF($Q40:$U40,"<0")*COUNTIF($Q40:$U40,">0")>0),$G40/5,$G40*Q40/SUM($Q40:$U40)) -> 624215.54 | C40: =IF(OR(SUM($Q40:$U40)=0,COUNTIF($Q40:$U40,"<0")*COUNTIF($Q40:$U40,">0")>0),$G40/5,$G40*R40/SUM($Q40:$U40)) -> 619505.69 | D40: =IF(OR(SUM($Q40:$U40)=0,COUNTIF($Q40:$U40,"<0")*COUNTIF($Q40:$U40,">0")>0),$G40/5,$G40*S40/SUM($Q40:$U40)) -> 466579.41 | E40: =IF(OR(SUM($Q40:$U40)=0,COUNTIF($Q40:$U40,"<0")*COUNTIF($Q40:$U40,">0")>0),$G40/5,$G40*T40/SUM($Q40:$U40)) -> 860803.24 | F40: =IF(OR(SUM($Q40:$U40)=0,COUNTIF($Q40:$U40,"<0")*COUNTIF($Q40:$U40,">0")>0),$G40/5,$G40*U40/SUM($Q40:$U40)) -> 536532.25 | G40: 3107636.1 | H40: 466988.51 | I40: 637926.41 | J40: 451743.83 | K40: 478928.95 | L40: 433152.9 | M40: 453384.19 | N40: 1206676.3 | O40: =SUM(B40:F40,H40:N40) -> 7236437.2 | Q40: 585552.35 | R40: 581134.22 | S40: 437680.02 | T40: 807486.08 | U40: 503300.06 | V40: 1121084.8 | W40: 521909.75 | X40: 609779.2 | Y40: =SUM(Q40:X40) -> 5167926.4
A41: (-) Productos de Inversiones | B41: =IF(OR(SUM($Q41:$U41)=0,COUNTIF($Q41:$U41,"<0")*COUNTIF($Q41:$U41,">0")>0),$G41/5,$G41*Q41/SUM($Q41:$U41)) -> 295762.85 | C41: =IF(OR(SUM($Q41:$U41)=0,COUNTIF($Q41:$U41,"<0")*COUNTIF($Q41:$U41,">0")>0),$G41/5,$G41*R41/SUM($Q41:$U41)) -> 292727.45 | D41: =IF(OR(SUM($Q41:$U41)=0,COUNTIF($Q41:$U41,"<0")*COUNTIF($Q41:$U41,">0")>0),$G41/5,$G41*S41/SUM($Q41:$U41)) -> 322483.6 | E41: =IF(OR(SUM($Q41:$U41)=0,COUNTIF($Q41:$U41,"<0")*COUNTIF($Q41:$U41,">0")>0),$G41/5,$G41*T41/SUM($Q41:$U41)) -> 321934.83 | F41: =IF(OR(SUM($Q41:$U41)=0,COUNTIF($Q41:$U41,"<0")*COUNTIF($Q41:$U41,">0")>0),$G41/5,$G41*U41/SUM($Q41:$U41)) -> 361718.8 | G41: 1594627.5 | H41: 335844.6 | I41: 319114.56 | J41: 340452.07 | K41: 338053.42 | L41: 457659.57 | M41: 264005.44 | N41: 98279.12 | O41: =SUM(B41:F41,H41:N41) -> 3748036.3 | Q41: 239607.33 | R41: 237148.25 | S41: 261254.7 | T41: 260810.12 | U41: 293040.44 | V41: 288588.62 | W41: 295567.28 | X41: 299741 | Y41: =SUM(Q41:X41) -> 2175757.7
B42: =IF(OR(SUM($Q42:$U42)=0,COUNTIF($Q42:$U42,"<0")*COUNTIF($Q42:$U42,">0")>0),$G42/5,$G42*Q42/SUM($Q42:$U42)) -> 0 | C42: =IF(OR(SUM($Q42:$U42)=0,COUNTIF($Q42:$U42,"<0")*COUNTIF($Q42:$U42,">0")>0),$G42/5,$G42*R42/SUM($Q42:$U42)) -> 0 | D42: =IF(OR(SUM($Q42:$U42)=0,COUNTIF($Q42:$U42,"<0")*COUNTIF($Q42:$U42,">0")>0),$G42/5,$G42*S42/SUM($Q42:$U42)) -> 0 | E42: =IF(OR(SUM($Q42:$U42)=0,COUNTIF($Q42:$U42,"<0")*COUNTIF($Q42:$U42,">0")>0),$G42/5,$G42*T42/SUM($Q42:$U42)) -> 0 | F42: =IF(OR(SUM($Q42:$U42)=0,COUNTIF($Q42:$U42,"<0")*COUNTIF($Q42:$U42,">0")>0),$G42/5,$G42*U42/SUM($Q42:$U42)) -> 0 | G42: 0 | H42: 0 | I42: 0 | J42: 0 | K42: 0 | L42: 0 | M42: 0 | N42: 0 | O42: =SUM(B42:F42,H42:N42) -> 0 | Q42: 0 | R42: 0 | S42: 0 | T42: 0 | U42: 0 | V42: 0 | W42: 0 | X42: 0 | Y42: =SUM(Q42:X42) -> 0
...

Sheet Informacion de Sam
A1: Concepto | B1: 43831 | C1: 43862 | D1: 43891 | E1: 43922 | F1: 43952 | G1: 43983 | H1: 44013 | I1: 44044 | J1: 44075 | K1: 44105 | L1: 44136 | M1: 44166 | N1: 44197 | O1: 44228 | P1: 44256 | Q1: 44287 | R1: 44317 | S1: 44348 | T1: 44378 | U1: 44409 | V1: 44440 | W1: 44470 | X1: 44501 | Y1: 44531 | Z1: 44562 | AA1: 44593 | AB1: 44621 | AC1: 44652 | AD1: 44682 | AE1: 44713 | AF1: 44743 | AG1: 44774 | AH1: 44805 | AI1: 44835 | AJ1: 44866 | AK1: 44896 | AL1: 44927 | AM1: 44958 | AN1: 44986 | AO1: 45017 | AP1: 45047 | AQ1: 45078 | AR1: 45108 | AS1: 45139 | AT1: 45170 | AU1: 45200 | AV1: 45231 | AW1: 45261 | AX1: 45292 | AY1: 45323 | AZ1: 45352 | BA1: 45383 | BB1: 45413 | BC1: 45444 | BD1: 45474 | BE1: 45505 | BF1: 45536 | BG1: 45566 | BH1: 45597 | BI1: 45627 | BJ1: 45658 | BK1: 45689 | BL1: 45717 | BM1: 45748 | BN1: 45778 | BO1: 45809 | BP1: 45839 | BQ1: 45870 | BR1: 45901 | BS1: 45931 | BT1: 45962 | BU1: 45992 | BV1: 46023 | BW1: 46054 | BX1: 46082 | BY1: 46113 | BZ1: 46143 | CA1: 46174 | CB1: 46204 | CC1: 46235
A2: Primas Brutas | F2: 31102521 | G2: 35112660 | H2: 31479548 | I2: 66674857 | J2: 34490069 | K2: 33559997 | L2: 34613138 | M2: 39773343 | N2: 33573625 | O2: 38470535 | P2: 48669164 | Q2: 32979431 | R2: 30459725 | S2: 39378124 | T2: 32040782 | U2: 70471823 | V2: 35548483 | W2: 34734938 | X2: 35070487 | Y2: 35257319 | Z2: 38869210 | AA2: 66747425 | AB2: 43201477 | AC2: 44933269 | AD2: 50850685 | AE2: 60657568 | AF2: 84933444 | AG2: 51764632 | AH2: 55571672 | AI2: 50856757 | AJ2: 44718445 | AK2: 40379470 | AL2: 52439627 | AM2: 69263142 | AN2: 51811531 | AO2: 62661126 | AP2: 50407674 | AQ2: 49407530 | AR2: 45400084 | AS2: 91397458 | AT2: 47241820 | AU2: 46387362 | AV2: 59746928 | AW2: 50707767 | AX2: 56235002 | AY2: 80447760 | AZ2: 52367160 | BA2: 66079228 | BB2: 59278999 | BC2: 56553219 | BD2: 58223920 | BE2: 1.1064099e+08 | BF2: 55409769 | BG2: 66117728 | BH2: 64628560 | BI2: 48945421 | BJ2: 76596366 | BK2: 85461451 | BL2: 71128531 | BM2: 69878133 | BN2: 55430646 | BO2: 58031052 | BP2: 65154984 | BQ2: 63173458 | BR2: 62428610 | BS2: 56527550 | BT2: 52458789 | BU2: 44957199 | BV2: 55492142 | BW2: 79909300 | BX2: 68348604 | BY2: 59814608 | BZ2: 55508522 | CA2: 48704702 | CB2: 50585028 | CC2: 51181162
A3: (-) Devoluciones y Cancelaciones | F3: 4659794.7 | G3: 5419389.9 | H3: 2648916.9 | I3: 4234333.7 | J3: 4317614.6 | K3: 3761815.5 | L3: 5524123.7 | M3: 3038103.4 | N3: 9599889.3 | O3: 1533431.1 | P3: 9082355 | Q3: 1325005.7 | R3: 3474913.1 | S3: 4784771 | T3: 1934480.6 | U3: 4062122.1 | V3: 3703477.3 | W3: 4707037.1 | X3: 3367874 | Y3: 1732603.8 | Z3: 3979552.8 | AA3: 4167832.6 | AB3: 4223660.7 | AC3: 4713693.4 | AD3: 10753126 | AE3: 12703756 | AF3: 4489698.6 | AG3: 4106829.5 | AH3: 3335831.5 | AI3: 5524300.5 | AJ3: 2687448.7 | AK3: 3188867.5 | AL3: 3521007.7 | AM3: 3738419.8 | AN3: 5926629.8 | AO3: 4526167 | AP3: 6231474 | AQ3: 3210753.5 | AR3: 4498219.3 | AS3: 8734528.6 | AT3: 4148949 | AU3: 4428107.2 | AV3: 7104043.5 | AW3: 1606880.8 | AX3: 4862255.1 | AY3: 3860281.5 | AZ3: 6032483.7 | BA3: 6856463.4 | BB3: 13910858 | BC3: 4182202.1 | BD3: 7075816.3 | BE3: 5588606.9 | BF3: 6656176.5 | BG3: 5820628.2 | BH3: 2532174.5 | BI3: 8667983.1 | BJ3: 5104873.8 | BK3: 8253616.2 | BL3: 15211032 | BM3: 16855330 | BN3: 6041157.9 | BO3: 2776640.2 | BP3: 7434936.9 | BQ3: 5885393.3 | BR3: 4937725.4 | BS3: 8068454.7 | BT3: 5595818.5 | BU3: 6450448.6 | BV3: 4299628.6 | BW3: 5793714.4 | BX3: 5852794 | BY3: 18388453 | BZ3: 15132048 | CA3: 5995997.3 | CB3: 4451830 | CC3: 5089122.2
A5: Primas Netas | B5: 29627738 | C5: 44729547 | D5: 29073920 | E5: 26448703 | F5: 27557156 | G5: 29693270 | H5: 28830631 | I5: 62440523 | J5: 30172454 | K5: 29798182 | L5: 29089015 | M5: 36735239 | N5: 23973736 | O5: 36937104 | P5: 39586809 | Q5: 31654425 | R5: 26984812 | S5: 34593353 | T5: 30106302 | U5: 66409701 | V5: 31845005 | W5: 30027901 | X5: 31702613 | Y5: 33524715 | Z5: 34889657 | AA5: 62579592 | AB5: 38977816 | AC5: 40219576 | AD5: 40097559 | AE5: 47953812 | AF5: 80443745 | AG5: 47657803 | AH5: 52235840 | AI5: 45332456 | AJ5: 42030997 | AK5: 37190603 | AL5: 48918619 | AM5: 65524723 | AN5: 45884901 | AO5: 58134959 | AP5: 44176200 | AQ5: 46196777 | AR5: 40901864 | AS5: 82662929 | AT5: 43092871 | AU5: 41959254 | AV5: 52642884 | AW5: 49100886 | AX5: 51372747 | AY5: 76587478 | AZ5: 46334676 | BA5: 59222765 | BB5: 45368141 | BC5: 52371017 | BD5: 51148104 | BE5: 1.0505238e+08 | BF5: 48753592 | BG5: 60297100 | BH5: 62096386 | BI5: 40277438 | BJ5: 71491492 | BK5: 77207835 | BL5: 55917499 | BM5: 53022803 | BN5: 49389488 | BO5: 55254412 | BP5: 57720047 | BQ5: 57288065 | BR5: 57490885 | BS5: 48459095 | BT5: 46862971 | BU5: 38506750 | BV5: 51192513 | BW5: 74115586 | BX5: 62495810 | BY5: 41426155 | BZ5: 40376474 | CA5: 42708705 | CB5: 46133198 | CC5: 46092040
A7: Primas por Reaseguro Cedido | B7: 14280524 | C7: 20373376 | D7: 10166879 | E7: 13703221 | F7: 11344553 | G7: 15047318 | H7: 12554282 | I7: 40743734 | J7: 14983191 | K7: 13668092 | L7: 15383656 | M7: 22289748 | N7: 9378417.9 | O7: 16670613 | P7: 12486903 | Q7: 16295074 | R7: 13304568 | S7: 19038865 | T7: 12751977 | U7: 44566200 | V7: 15772985 | W7: 13891808 | X7: 16310863 | Y7: 22118731 | Z7: 16161408 | AA7: 21265640 | AB7: 16196181 | AC7: 20673260 | AD7: 20973793 | AE7: 27064111 | AF7: 50344784 | AG7: 21490423 | AH7: 23590907 | AI7: 20203933 | AJ7: 17762188 | AK7: 20607699 | AL7: 20973062 | AM7: 20894148 | AN7: 21309639 | AO7: 27340889 | AP7: 21760373 | AQ7: 22836101 | AR7: 18103322 | AS7: 52523853 | AT7: 18250226 | AU7: 18027089 | AV7: 31768978 | AW7: 21573703 | AX7: 21351896 | AY7: 22787927 | AZ7: 22759221 | BA7: 27280443 | BB7: 21019483 | BC7: 26164305 | BD7: 18476477 | BE7: 67036234 | BF7: 19109453 | BG7: 28140488 | BH7: 33307340 | BI7: 20682510 | BJ7: 33364683 | BK7: 28047520 | BL7: 26293104 | BM7: 19630589 | BN7: 20732604 | BO7: 24480040 | BP7: 27234464 | BQ7: 20124405 | BR7: 21237599 | BS7: 23685552 | BT7: 23183097 | BU7: 23708610 | BV7: 18254565 | BW7: 26621037 | BX7: 33028070 | BY7: 15146108 | BZ7: 15850704 | CA7: 21920937 | CB7: 23762795 | CC7: 19178662
A9: PRIMAS NETAS DE RETENCION | B9: 15347214 | C9: 24356172 | D9: 18907041 | E9: 12745482 | F9: 16212603 | G9: 14645953 | H9: 16276349 | I9: 21696789 | J9: 15189263 | K9: 16130090 | L9: 13705358 | M9: 14445491 | N9: 14595318 | O9: 20266491 | P9: 27099906 | Q9: 15359352 | R9: 13680244 | S9: 15554489 | T9: 17354325 | U9: 21843501 | V9: 16072021 | W9: 16136093 | X9: 15391750 | Y9: 11405984 | Z9: 18728249 | AA9: 41313952 | AB9: 22781635 | AC9: 19546315 | AD9: 19123766 | AE9: 20889701 | AF9: 30098961 | AG9: 26167380 | AH9: 28644933 | AI9: 25128523 | AJ9: 24268808 | AK9: 16582904 | AL9: 27945557 | AM9: 44630574 | AN9: 24575261 | AO9: 30794070 | AP9: 22415827 | AQ9: 23360675 | AR9: 22798542 | AS9: 30139077 | AT9: 24842645 | AU9: 23932166 | AV9: 20873907 | AW9: 27527182 | AX9: 30020851 | AY9: 53799551 | AZ9: 23575456 | BA9: 31942321 | BB9: 24348658 | BC9: 26206712 | BD9: 32671627 | BE9: 38016144 | BF9: 29644140 | BG9: 32156611 | BH9: 28789045 | BI9: 19594928 | BJ9: 38126810 | BK9: 49160315 | BL9: 29624395 | BM9: 33392214 | BN9: 28656884 | BO9: 30774372 | BP9: 30485583 | BQ9: 37163660 | BR9: 36253286 | BS9: 24773543 | BT9: 23679874 | BU9: 14798141 | BV9: 32937948 | BW9: 47494549 | BX9: 29467739 | BY9: 26280047 | BZ9: 24525770 | CA9: 20787768 | CB9: 22370403 | CC9: 26913378
A11: VARIACIONES EN RESERVAS TECNICAS Y MATEMÁTICAS
A12: Menos:
A13: Variaciones Gastos | B13: -412861.05 | C13: 7122851.1 | D13: 2169790.6 | E13: -1076894.7 | F13: 97680.49 | G13: -1038554.5 | H13: -502418.95 | I13: 1418651 | J13: -3130.25 | K13: 1324282.8 | L13: -3818277.4 | M13: -748399.27 | N13: -994677.32 | O13: 1567826 | P13: 12919415 | Q13: -172532.49 | R13: -3228718.7 | S13: -822329.72 | T13: -311327.01 | U13: -1169971.9 | V13: -263423.92 | W13: -450442.25 | X13: -1754874.1 | Y13: -3129441.2 | Z13: 3561213.3 | AA13: 22231159 | AB13: 1259462.8 | AC13: -3749.55 | AD13: -1249167.4 | AE13: -2881266.1 | AF13: 3497611.2 | AG13: 2295923 | AH13: 6262139.3 | AI13: 4947017.9 | AJ13: 312162.42 | AK13: -3606698.1 | AL13: 7965130.9 | AM13: 18470604 | AN13: 2519877.5 | AO13: 5823588.9 | AP13: -2147734.7 | AQ13: -3142430 | AR13: 1102759.8 | AS13: -230429.83 | AT13: 87775.81 | AU13: -2038780 | AV13: -3084811.6 | AW13: -4593961.6 | AX13: 6142339 | AY13: 25304716 | AZ13: -1859668.2 | BA13: 4973325.6 | BB13: -4622358.7 | BC13: -1191281 | BD13: 2119109.6 | BE13: 1128183.6 | BF13: 515791.02 | BG13: -2032376.7 | BH13: -3940349.8 | BI13: -6007286.4 | BJ13: 5905450.1 | BK13: 21969661 | BL13: -885553.12 | BM13: 3592943.5 | BN13: -3584336.1 | BO13: -3202225.6 | BP13: 2216721.2 | BQ13: 7638925.7 | BR13: 4443104.1 | BS13: -3199160.5 | BT13: -7245626.1 | BU13: -10796070 | BV13: 1184257.6 | BW13: 16481580 | BX13: -1458432.3 | BY13: -2173653.3 | BZ13: -4869557.7 | CA13: -8047144.3 | CB13: -2151335.5 | CC13: 234537.22
A14: PRIMAS NETAS DE RETENCION DEVENGADAS | B14: 15760075 | C14: 17233321 | D14: 16737250 | E14: 13822377 | F14: 16114922 | G14: 15684507 | H14: 16778768 | I14: 20278138 | J14: 15192393 | K14: 14805807 | L14: 17523636 | M14: 15193890 | N14: 15589995 | O14: 18698665 | P14: 14180492 | Q14: 15531884 | R14: 16908963 | S14: 16376818 | T14: 17665652 | U14: 23013472 | V14: 16335445 | W14: 16586536 | X14: 17146624 | Y14: 14535425 | Z14: 15167036 | AA14: 19082793 | AB14: 21522172 | AC14: 19550065 | AD14: 20372934 | AE14: 23770967 | AF14: 26601350 | AG14: 23871457 | AH14: 22382794 | AI14: 20181505 | AJ14: 23956646 | AK14: 20189602 | AL14: 19980426 | AM14: 26159971 | AN14: 22055384 | AO14: 24970481 | AP14: 24563562 | AQ14: 26503105 | AR14: 21695783 | AS14: 30369506 | AT14: 24754870 | AU14: 25970946 | AV14: 23958718 | AW14: 32121144 | AX14: 23878512 | AY14: 28494834 | AZ14: 25435124 | BA14: 26968996 | BB14: 28971017 | BC14: 27397993 | BD14: 30552517 | BE14: 36887961 | BF14: 29128349 | BG14: 34188988 | BH14: 32729395 | BI14: 25602214 | BJ14: 32221359 | BK14: 27190655 | BL14: 30509949 | BM14: 29799271 | BN14: 32241220 | BO14: 33976598 | BP14: 28268862 | BQ14: 29524734 | BR14: 31810182 | BS14: 27972704 | BT14: 30925500 | BU14: 25594211 | BV14: 31753690 | BW14: 31012970 | BX14: 30926172 | BY14: 28453700 | BZ14: 29395327 | CA14: 28834912 | CB14: 24521739 | CC14: 26678841
A16: Menos:
A17: COSTO DE ADQUISICION Y SINIESTRALIDAD | B17: 7113966.5 | C17: 9884371 | D17: 8697480.3 | E17: 3809018.8 | F17: 7727115.8 | G17: 4590399.4 | H17: 6983276.7 | I17: 10972814 | J17: 11352547 | K17: 7555087.7 | L17: 10053199 | M17: 6308006.8 | N17: 6824439 | O17: 8900427.4 | P17: 9951874.3 | Q17: 7841328.9 | R17: 10143574 | S17: 9170230.4 | T17: 9322903.1 | U17: 12742738 | V17: 10344680 | W17: 9185294.1 | X17: 9735815.1 | Y17: 6996590 | Z17: 7710739.8 | AA17: 8832035.4 | AB17: 9281109.9 | AC17: 9373805.4 | AD17: 11637366 | AE17: 9384408.7 | AF17: 13723422 | AG17: 11123792 | AH17: 9254343.4 | AI17: 6756314 | AJ17: 14090958 | AK17: 2297884.5 | AL17: 6765513.8 | AM17: 11321924 | AN17: 10321990 | AO17: 8254533.2 | AP17: 10854006 | AQ17: 12829760 | AR17: 11820769 | AS17: 18611648 | AT17: 12555130 | AU17: 15253616 | AV17: 14732272 | AW17: 9039569.9 | AX17: 13932467 | AY17: 16630569 | AZ17: 14694317 | BA17: 10081775 | BB17: 17196724 | BC17: 12580388 | BD17: 16360572 | BE17: 18734342 | BF17: 17676142 | BG17: 13516191 | BH17: 25291571 | BI17: -301999.37 | BJ17: 18337740 | BK17: 13878685 | BL17: 18932473 | BM17: 16094575 | BN17: 16440400 | BO17: 17529443 | BP17: 19621431 | BQ17: 15231023 | BR17: =BR18+BR23 -> 14789919 | BS17: =BS18+BS23 -> 15192433 | BT17: 13634829 | BU17: 11775673 | BV17: 15752668 | BW17: 14115381 | BX17: 12785419 | BY17: 15516205 | BZ17: 13686701 | CA17: 13813410 | CB17: 9587218.3 | CC17: 15275230
A18: ADQUISICION | B18: 120313.72 | C18: 835532.52 | D18: 791832.42 | E18: 355082.02 | F18: 573945.24 | G18: -1061358.5 | H18: -169681.64 | I18: 3570095.9 | J18: 313364.39 | K18: 343585 | L18: -321694.77 | M18: -2663435.8 | N18: 53832.16 | O18: 3772.66 | P18: 502572.29 | Q18: 523176.09 | R18: 230908.08 | S18: -284830.73 | T18: 492714.78 | U18: 4159186.3 | V18: -1974352.4 | W18: -58498.9 | X18: -468636.27 | Y18: -3595350.2 | Z18: -8793.31 | AA18: -118575.89 | AB18: -92167.78 | AC18: -322021.82 | AD18: 563112.17 | AE18: -215711.47 | AF18: 4283849.5 | AG18: -321241.16 | AH18: -2727989 | AI18: -1446275.1 | AJ18: 284526.18 | AK18: -10221039 | AL18: -1008272.7 | AM18: -24332.86 | AN18: -690419.26 | AO18: -1568306.4 | AP18: -470607.8 | AQ18: -436152.55 | AR18: 2808892.8 | AS18: 6237026.9 | AT18: 1210060.1 | AU18: 1824871.6 | AV18: 2075392.7 | AW18: -7634489 | AX18: 2721926.1 | AY18: 1085733.4 | AZ18: 555719.43 | BA18: 398073.61 | BB18: 1431667.4 | BC18: -1328774.4 | BD18: -27025.95 | BE18: 5727733.1 | BF18: 577340.1 | BG18: 104109.89 | BH18: 1493657.7 | BI18: -3315632.3 | BJ18: 1094836.9 | BK18: 1315905.4 | BL18: 2202353.5 | BM18: -1569898.1 | BN18: -696884.21 | BO18: 111189.22 | BP18: 620885.78 | BQ18: 232381.13 | BR18: 810350.9 | BS18: -439432.14 | BT18: -266080.74 | BU18: -3163330.3 | BV18: 707888.92 | BW18: 1088468.7 | BX18: 93216.23 | BY18: 1006077 | BZ18: 679772.01 | CA18: -973590.81 | CB18: -1793446.5 | CC18: -589713.58
A19: Gastos de Adquisicion y Renovacion | B19: 3024484.5 | C19: 3498757.3 | D19: 3751273.4 | E19: 3425475.1 | F19: 3044231.7 | G19: 2587761.3 | H19: 3276083.6 | I19: 6923983.3 | J19: 3564924.1 | K19: 3698943.1 | L19: 3926752.3 | M19: 3300743.5 | N19: 3277858 | O19: 3554252.5 | P19: 4027396.4 | Q19: 3316764.4 | R19: 3364876.7 | S19: 3613173.4 | T19: 3858499.8 | U19: 7592182.8 | V19: 2019611.9 | W19: 3785578.7 | X19: 3905050.6 | Y19: 2221386.5 | Z19: 3830851.8 | AA19: 4798084.5 | AB19: 4301116.8 | AC19: 3992240.3 | AD19: 4204417 | AE19: 4483427.5 | AF19: 9109704.1 | AG19: 5942813.4 | AH19: 3999655.8 | AI19: 4138935.9 | AJ19: 5269448.3 | AK19: 793401.27 | AL19: 4240265.3 | AM19: 4963076.2 | AN19: 4741762.4 | AO19: 3228950 | AP19: 4863788.5 | AQ19: 5259635.1 | AR19: 7478272.7 | AS19: 11192491 | AT19: 6454812.9 | AU19: 6090431.6 | AV19: 6737528.9 | AW19: 5083506 | AX19: 7924344 | AY19: 6512949.7 | AZ19: 5290897.4 | BA19: 5516307.4 | BB19: 6240834.7 | BC19: 4524763.3 | BD19: 4608769.3 | BE19: 12529887 | BF19: 5625694.6 | BG19: 5829959 | BH19: 7402726.2 | BI19: 4799851.9 | BJ19: 6580103.1 | BK19: 6094848.7 | BL19: 7072791.6 | BM19: 2982831.3 | BN19: 4745092 | BO19: 5170294.2 | BP19: 5789330.3 | BQ19: 5605692.4 | BR19: 5699791.1 | BS19: 4546605.9 | BT19: 4531253.9 | BU19: 2897551.3 | BV19: 4980433 | BW19: 5846745 | BX19: 5075350.1 | BY19: 4581437.4 | BZ19: 4315722.9 | CA19: 4104502 | CB19: 2903721.5 | CC19: 4370450.3
A20: Menos:
A21: Comisiones y Participaciones por Reaseguro Cedido | B21: 2904170.7 | C21: 2663224.8 | D21: 2959441 | E21: 3070393.1 | F21: 2470286.4 | G21: 3649119.8 | H21: 3445765.2 | I21: 3353887.4 | J21: 3251559.7 | K21: 3355358.1 | L21: 4248447.1 | M21: 5964179.3 | N21: 3224025.9 | O21: 3550479.9 | P21: 3524824.1 | Q21: 2793588.4 | R21: 3133968.6 | S21: 3898004.1 | T21: 3365785 | U21: 3432996.5 | V21: 3993964.3 | W21: 3844077.6 | X21: 4373686.8 | Y21: 5816736.7 | Z21: 3839645.1 | AA21: 4916660.4 | AB21: 4393284.6 | AC21: 4314262.2 | AD21: 3641304.8 | AE21: 4699139 | AF21: 4825854.6 | AG21: 6264054.5 | AH21: 6727644.8 | AI21: 5585211 | AJ21: 4984922.1 | AK21: 11014440 | AL21: 5248538 | AM21: 4987409.1 | AN21: 5432181.6 | AO21: 4797256.4 | AP21: 5334396.3 | AQ21: 5695787.7 | AR21: 4669379.9 | AS21: 4955464.2 | AT21: 5244752.8 | AU21: 4265560 | AV21: 4662136.2 | AW21: 12717995 | AX21: 5202417.9 | AY21: 5427216.3 | AZ21: 4735178 | BA21: 5118233.8 | BB21: 4809167.3 | BC21: 5853537.6 | BD21: 4635795.3 | BE21: 6802153.9 | BF21: 5048354.5 | BG21: 5725849.1 | BH21: 5909068.6 | BI21: 8115484.2 | BJ21: 5485266.2 | BK21: 4778943.3 | BL21: 4870438 | BM21: 4552729.5 | BN21: 5441976.2 | BO21: 5059105 | BP21: 5168444.5 | BQ21: 5373311.2 | BR21: 4889440.2 | BS21: 4986038.1 | BT21: 4797334.6 | BU21: 6060881.5 | BV21: 4272544.1 | BW21: 4758276.3 | BX21: 4982133.8 | BY21: 3575360.4 | BZ21: 3635950.9 | CA21: 5078092.8 | CB21: 4697168 | CC21: 4960163.9
A23: SINIESTRALIDAD | B23: 6993652.8 | C23: 9048838.5 | D23: 7905647.9 | E23: 3453936.8 | F23: 7153170.6 | G23: 5651757.9 | H23: 7152958.3 | I23: 7402718.2 | J23: 11039182 | K23: 7211502.7 | L23: 10374894 | M23: 8971442.7 | N23: 6770606.9 | O23: 8896654.7 | P23: 9449302 | Q23: 7318152.8 | R23: 9912665.8 | S23: 9455061.2 | T23: 8830188.3 | U23: 8583551.6 | V23: 12319033 | W23: 9243793 | X23: 10204451 | Y23: 10591940 | Z23: 7719533.1 | AA23: 8950611.3 | AB23: 9373277.7 | AC23: 9695827.2 | AD23: 11074253 | AE23: 9600120.2 | AF23: 9439572.1 | AG23: 11445033 | AH23: 11982332 | AI23: 8202589.1 | AJ23: 13806432 | AK23: 12518923 | AL23: 7773786.5 | AM23: 11346257 | AN23: 11012409 | AO23: 9822839.6 | AP23: 11324614 | AQ23: 13265913 | AR23: 9011876.2 | AS23: 12374622 | AT23: 11345070 | AU23: 13428744 | AV23: 12656879 | AW23: 16674059 | AX23: 11210541 | AY23: 15544835 | AZ23: 14138597 | BA23: 9683701.8 | BB23: 15765057 | BC23: 13909162 | BD23: 16387598 | BE23: 13006609 | BF23: 17098802 | BG23: 13412081 | BH23: 23797913 | BI23: 3013632.9 | BJ23: 17242903 | BK23: 12562780 | BL23: 16730119 | BM23: 17664474 | BN23: 17137284 | BO23: 17418254 | BP23: 19000545 | BQ23: 14998641 | BR23: 13979568 | BS23: 15631865 | BT23: 13900910 | BU23: 14939004 | BV23: 15044779 | BW23: 13026913 | BX23: 12692203 | BY23: 14510128 | BZ23: 13006929 | CA23: 14787000 | CB23: 11380665 | CC23: 15864943
A24: Gastos por Obligaciones Contractuales | B24: 8807887 | C24: 13308891 | D24: 11157094 | E24: 3336605 | F24: 15816541 | G24: 10023695 | H24: 7229379.4 | I24: 10283222 | J24: 18626219 | K24: 10458917 | L24: 7108287.6 | M24: 11607340 | N24: -2363060.3 | O24: 6859612.1 | P24: 14626038 | Q24: 929620.82 | R24: 18686187 | S24: 19329578 | T24: 13222829 | U24: 9309938.3 | V24: 21724533 | W24: 25805005 | X24: 21819525 | Y24: 7345269.4 | Z24: 13452822 | AA24: 14749289 | AB24: 12607380 | AC24: 16197631 | AD24: 19325734 | AE24: 14509473 | AF24: 14400913 | AG24: 17705657 | AH24: 14774008 | AI24: 8181337.6 | AJ24: 16909083 | AK24: 30291025 | AL24: 11698822 | AM24: 15072245 | AN24: 6337585.4 | AO24: 17730309 | AP24: 17229648 | AQ24: 19099974 | AR24: 9926828.7 | AS24: 15796761 | AT24: 15226314 | AU24: 16875391 | AV24: 15460558 | AW24: 1.2549813e+08 | AX24: 14362330 | AY24: 17790518 | AZ24: 17791578 | BA24: 16659308 | BB24: -8407518.7 | BC24: 25468166 | BD24: 1.4572591e+08 | BE24: 22577832 | BF24: 20705039 | BG24: 35030634 | BH24: 32925522 | BI24: 25394509 | BJ24: 22034379 | BK24: 14666846 | BL24: 21620718 | BM24: 21406870 | BN24: 21652480 | BO24: 3943592.5 | BP24: 34552418 | BQ24: 10177573 | BR24: 22863189 | BS24: 28994761 | BT24: 12159722 | BU24: 12590910 | BV24: 13837550 | BW24: 21843014 | BX24: 18092761 | BY24: 19922549 | BZ24: 38130339 | CA24: 22021218 | CB24: 14759001 | CC24: 17157227
A25: Participacion de reaseguradoras en salvamentos y recuperaciones | B25: 0 | C25: 0 | D25: 0 | E25: 0 | F25: 0 | G25: 0 | H25: 0 | I25: 0 | J25: 0 | K25: 0 | L25: 0 | M25: 0 | N25: 0 | O25: 0 | P25: 0 | Q25: 0 | R25: 0 | S25: 0 | T25: 0 | U25: 0 | V25: 0 | W25: 0 | X25: 0 | Y25: 1101607.6 | Z25: 0 | AA25: 0 | AB25: 0 | AC25: 0 | AD25: 0 | AE25: 0 | AF25: 0 | AG25: 0 | AH25: 0 | AI25: 0 | AJ25: 0 | AK25: 312577.81 | AL25: 0 | AM25: 0 | AN25: 0 | AO25: 0 | AP25: 0 | AQ25: 0 | AR25: 0 | AS25: 0 | AT25: 0 | AU25: 0 | AV25: 0 | AW25: 0 | AX25: 0 | AY25: 0 | AZ25: 0 | BA25: 0 | BB25: 0 | BC25: 0 | BD25: 0 | BE25: 0 | BF25: 0 | BG25: 0 | BH25: 0 | BI25: 0 | BJ25: 0 | BK25: 0 | BL25: 18722.36 | BM25: 63801.24 | BN25: 0 | BO25: 0 | BP25: 0 | BQ25: 0 | BR25: 0 | BS25: 0 | BT25: 0 | BU25: 0 | BV25: 0 | BW25: 0 | BX25: 0 | BY25: 0 | BZ25: 0 | CA25: 0 | CB25: 0 | CC25: 0
A26: Menos:
A27: Recuperaciones por Reaseguro Cedido | B27: 1543260.8 | C27: 3900398 | D27: 2998170.8 | E27: -315893.76 | F27: 8636491.8 | G27: 4299856.7 | H27: -44154.69 | I27: 2625547.4 | J27: 7293362.8 | K27: 2794268.4 | L27: -3598072.4 | M27: 2359784.1 | N27: -9582587.2 | O27: -2172865.6 | P27: 5046003.1 | Q27: -6510894.9 | R27: 8267090.5 | S27: 9492920.3 | T27: 4293702.6 | U27: -61035.43 | V27: 9197678.3 | W27: 16365239 | X27: 11341754 | Y27: -3388893.5 | Z27: 5491848.5 | AA27: 5556463.3 | AB27: 2777084.5 | AC27: 6358082.1 | AD27: 8190817 | AE27: 3952137.7 | AF27: 4414286.3 | AG27: 5376414.6 | AH27: 2173934.6 | AI27: -349851.99 | AJ27: 2834716.4 | AK27: 16748058 | AL27: 2440858.6 | AM27: 2891476.4 | AN27: -5175973.5 | AO27: 7198825.1 | AP27: 5475219.4 | AQ27: 5399546.2 | AR27: 245090.5 | AS27: 3005050.3 | AT27: 2834203.4 | AU27: 3378460.4 | AV27: 2201242.5 | AW27: 1.0824728e+08 | AX27: 2960618.7 | AY27: 1755583.3 | AZ27: 3346091.3 | BA27: 6820825.3 | BB27: -25087599 | BC27: 11321450 | BD27: 1.2906256e+08 | BE27: 9111567.2 | BF27: 3225936.8 | BG27: 21110185 | BH27: 9064848.3 | BI27: 20250168 | BJ27: 4237501.4 | BK27: 1639162.1 | BL27: 4757020.3 | BM27: 3600261.3 | BN27: 4444209 | BO27: -15037499 | BP27: 15535458 | BQ27: -5859761.9 | BR27: 7988485.1 | BS27: 12478295 | BT27: -2150392 | BU27: -3613806.5 | BV27: -1531942 | BW27: 8184883.8 | BX27: 4600770.2 | BY27: 5332596.8 | BZ27: 23935766 | CA27: 6748592.9 | CB27: 3165074.5 | CC27: 1273334
A28: Salvamento y recuperaciones | B28: 270973.39 | C28: 359654.89 | D28: 253275.68 | E28: 198562.02 | F28: 26878.57 | G28: 72080.38 | H28: 120575.77 | I28: 254956.25 | J28: 293673.56 | K28: 453145.9 | L28: 331466.18 | M28: 276113.01 | N28: 448919.99 | O28: 135822.89 | P28: 130732.46 | Q28: 122362.93 | R28: 506430.59 | S28: 381596.19 | T28: 98937.89 | U28: 787422.14 | V28: 207822 | W28: 195972.83 | X28: 273319.07 | Y28: 1243830.4 | Z28: 241440.64 | AA28: 242214.76 | AB28: 457018.2 | AC28: 143721.58 | AD28: 60663.23 | AE28: 957215.17 | AF28: 547055.08 | AG28: 884209 | AH28: 617741 | AI28: 328600.44 | AJ28: 267934.74 | AK28: 1336621.2 | AL28: 1484177.2 | AM28: 834510.79 | AN28: 501150.08 | AO28: 708644.03 | AP28: 429814.3 | AQ28: 434515.11 | AR28: 669862.03 | AS28: 417089.44 | AT28: 1047040.7 | AU28: 68186.23 | AV28: 602435.92 | AW28: 576800 | AX28: 191170.23 | AY28: 490099.51 | AZ28: 306889.71 | BA28: 154780.94 | BB28: 915023.37 | BC28: 237553.45 | BD28: 275755.9 | BE28: 459655.1 | BF28: 380300 | BG28: 508367.63 | BH28: 62760.02 | BI28: 2130707.8 | BJ28: 553974.6 | BK28: 464904.45 | BL28: 152301.24 | BM28: 205936.48 | BN28: 70986.58 | BO28: 1562837.7 | BP28: 16413.95 | BQ28: 1038693.3 | BR28: 895135.51 | BS28: 884601.79 | BT28: 409203.58 | BU28: 1265712.8 | BV28: 324713.49 | BW28: 631216.87 | BX28: 799787.71 | BY28: 79824.5 | BZ28: 1187644.7 | CA28: 485624.79 | CB28: 213262.05 | CC28: 18950
A30: UTILIDAD BRUTA EN OPERACIONES DE SEGUROS | B30: 8646108.7 | C30: 7348949.6 | D30: 8039770.1 | E30: 10013358 | F30: 8387806.6 | G30: 11094108 | H30: 9795491.4 | I30: 9305323.6 | J30: 3839846.8 | K30: 7250719.5 | L30: 7470436.6 | M30: 8885883.3 | N30: 8765556.2 | O30: 9798237.4 | P30: 4228617.5 | Q30: 7690555.1 | R30: 6765389 | S30: 7206588.1 | T30: 8342749.1 | U30: 10270735 | V30: 5990764.4 | W30: 7401241.5 | X30: 7410809.1 | Y30: 7538835.4 | Z30: 7456296.2 | AA30: 10250758 | AB30: 12241063 | AC30: 10176259 | AD30: 8735568 | AE30: 14386558 | AF30: 12877928 | AG30: 12747665 | AH30: 13128450 | AI30: 13425191 | AJ30: 9865688.1 | AK30: 17891718 | AL30: 13214912 | AM30: 14838046 | AN30: 11733394 | AO30: 16715948 | AP30: 13709556 | AQ30: 13673345 | AR30: 9875013.7 | AS30: 11757858 | AT30: 12199740 | AU30: 10717330 | AV30: 9226446.2 | AW30: 23081574 | AX30: 9946044.7 | AY30: 11864265 | AZ30: 10740807 | BA30: 16887220 | BB30: 11774293 | BC30: 14817605 | BD30: 14191945 | BE30: 18153618 | BF30: 11452207 | BG30: 20672797 | BH30: 7437824 | BI30: 25904214 | BJ30: 13883620 | BK30: 13311969 | BL30: 11577476 | BM30: 13704696 | BN30: 15800820 | BO30: 16447155 | BP30: 8647430.6 | BQ30: 14293712 | BR30: =BR14-BR17 -> 17020262 | BS30: =BS14-BS17 -> 12780271 | BT30: 17290670 | BU30: 13818537 | BV30: 16001023 | BW30: 16897588 | BX30: 18140753 | BY30: 12937495 | BZ30: 15708626 | CA30: 15021502 | CB30: 14934521 | CC30: 11403611
A32: Menos:
