Workbook
Name A: #REF!
Name A: #REF!
Name alex: [2]AGENCIA!#REF!
Name alex: [2]AGENCIA!#REF!
Name asdf: #REF!
Name asdf: #REF!

Sheet Sep 26
A1: TARJETA BAM | B1: Pago | C1: Vigencia | D1: Tipo | E1: Poliza | F1: Certificado | G1: Nombre | H1: Fecha | I1: Fecha Cobro | J1: Zona | K1: Fuente | L1: Agencia | M1: Cod. Colaborador | N1: Nombre colaborador | O1: Prima | P1: Cod. Jefe | Q1: Nombre Jefe | R1: Producto | S1: Poliza Firmada | T1: Control
A2: SI | B2: CUOTAS | C2: 4 | D2: NUEVO | E2: VCB-20240008 | F2: 623 | G2: LESBIA ANGELICA FLORE PINEDA | H2: 46266 | I2: 46266 | J2: =+VLOOKUP(K2,Datos!$A:$C,3,FALSE) -> ORIENTE | K2: 179 | L2: =+VLOOKUP(K2,Datos!$A:$C,2,FALSE) -> ZACAPA CATEDRAL | M2: 315570 | N2: =+VLOOKUP(M2,Datos!$F:$G,2,FALSE) -> Zecena Ramos, Kemberly Del Rosario | O2: =IFERROR(IF(A2="SI",VLOOKUP(R2,Datos!$J$1:$K$50,2,FALSE)*C2,VLOOKUP(R2,Datos!$P$1:$T$50,2,FALSE)*C2),0) -> 5472 | P2: 309262 | Q2: =+VLOOKUP(P2,Datos!$F:$G,2,FALSE) -> Lisbeth Carolina Hernandez Urrutia | R2: VIDA+SEGURO PLAN 1 | S2: SI | T2: =+COUNTIFS($G$2:$G$623,G2) -> 1
A3: SI | B3: CONTADO | C3: 1 | D3: NUEVO | E3: VCB-20210003 | F3: 4160 | G3: ALMA LETICIA MONTERROSO SIPAQUE | H3: 46266 | I3: 46266 | J3: =+VLOOKUP(K3,Datos!$A:$C,3,FALSE) -> AMERICAS | K3: 226 | L3: =+VLOOKUP(K3,Datos!$A:$C,2,FALSE) -> SAN JOSE PINULA | M3: 315218 | N3: =+VLOOKUP(M3,Datos!$F:$G,2,FALSE) -> Herberth Alberto Barrios Perez | O3: =IFERROR(IF(A3="SI",VLOOKUP(R3,Datos!$J$1:$K$50,2,FALSE)*C3,VLOOKUP(R3,Datos!$P$1:$T$50,2,FALSE)*C3),0) -> 816 | P3: 301608 | Q3: =+VLOOKUP(P3,Datos!$F:$G,2,FALSE) -> Jaime Rene Guzman Muy | R3: VIDA+SEGURO | S3: SI | T3: =+COUNTIFS($G$2:$G$623,G3) -> 1
A4: SI | B4: CONTADO | C4: 1 | D4: NUEVO | E4: VCB-20210003 | F4: 4167 | G4: JOSE FRANCISCO SANTOS GOMEZ | H4: 46266 | I4: 46266 | J4: =+VLOOKUP(K4,Datos!$A:$C,3,FALSE) -> AMERICAS | K4: 226 | L4: =+VLOOKUP(K4,Datos!$A:$C,2,FALSE) -> SAN JOSE PINULA | M4: 315218 | N4: =+VLOOKUP(M4,Datos!$F:$G,2,FALSE) -> Herberth Alberto Barrios Perez | O4: =IFERROR(IF(A4="SI",VLOOKUP(R4,Datos!$J$1:$K$50,2,FALSE)*C4,VLOOKUP(R4,Datos!$P$1:$T$50,2,FALSE)*C4),0) -> 1368 | P4: 301608 | Q4: =+VLOOKUP(P4,Datos!$F:$G,2,FALSE) -> Jaime Rene Guzman Muy | R4: VIDA+SEGURO PLAN 1 | S4: SI | T4: =+COUNTIFS($G$2:$G$623,G4) -> 1
A5: SI | B5: CUOTAS | C5: 1 | D5: NUEVO | E5: VCB-20220010 | F5: 1088 | G5: ENMA ELIZABETH MUÑOZ | H5: 46266 | I5: 46266 | J5: =+VLOOKUP(K5,Datos!$A:$C,3,FALSE) -> PETAPA | K5: 88 | L5: =+VLOOKUP(K5,Datos!$A:$C,2,FALSE) -> ATANASIO TZUL | M5: 90086485 | N5: =+VLOOKUP(M5,Datos!$F:$G,2,FALSE) -> SHAROL STEFANY YOC GOMEZ | O5: =IFERROR(IF(A5="SI",VLOOKUP(R5,Datos!$J$1:$K$50,2,FALSE)*C5,VLOOKUP(R5,Datos!$P$1:$T$50,2,FALSE)*C5),0) -> 816 | P5: 306713 | Q5: =+VLOOKUP(P5,Datos!$F:$G,2,FALSE) -> Luis Fernando Santos Aguilar | R5: VIDA+SEGURO | S5: SI | T5: =+COUNTIFS($G$2:$G$623,G5) -> 1
A6: SI | B6: CUOTAS | C6: 1 | D6: NUEVO | E6: VCB-20210003 | F6: 4170 | G6: JOEL ARMANDO RODRIGUEZ LOPEZ | H6: 46266 | I6: 46266 | J6: =+VLOOKUP(K6,Datos!$A:$C,3,FALSE) -> ORIENTE | K6: 122 | L6: =+VLOOKUP(K6,Datos!$A:$C,2,FALSE) -> AGUA BLANCA | M6: 313981 | N6: =+VLOOKUP(M6,Datos!$F:$G,2,FALSE) -> Sindy Beatriz Perez Sanchez | O6: =IFERROR(IF(A6="SI",VLOOKUP(R6,Datos!$J$1:$K$50,2,FALSE)*C6,VLOOKUP(R6,Datos!$P$1:$T$50,2,FALSE)*C6),0) -> 816 | P6: 306259 | Q6: =+VLOOKUP(P6,Datos!$F:$G,2,FALSE) -> Brenda Raquel Ramirez Sanchez | R6: VIDA+SEGURO | S6: SI | T6: =+COUNTIFS($G$2:$G$623,G6) -> 1
A7: SI | B7: CUOTAS | C7: 1 | D7: NUEVO | E7: VCB-20210003 | F7: 41736 | G7: ALFONSO CAC CAAL | H7: 46266 | I7: 46266 | J7: =+VLOOKUP(K7,Datos!$A:$C,3,FALSE) -> NORTE | K7: 80 | L7: =+VLOOKUP(K7,Datos!$A:$C,2,FALSE) -> TACTIC | M7: 90051401 | N7: =+VLOOKUP(M7,Datos!$F:$G,2,FALSE) -> Gerson Celidon Melchor | O7: =IFERROR(IF(A7="SI",VLOOKUP(R7,Datos!$J$1:$K$50,2,FALSE)*C7,VLOOKUP(R7,Datos!$P$1:$T$50,2,FALSE)*C7),0) -> 816 | P7: 311405 | Q7: =+VLOOKUP(P7,Datos!$F:$G,2,FALSE) -> Marina Elena Giron Roldan | R7: VIDA+SEGURO | S7: SI | T7: =+COUNTIFS($G$2:$G$623,G7) -> 1
A8: SI | B8: CUOTAS | C8: 4 | D8: NUEVO | E8: VCB-20240007 | F8: 816 | G8: HUGO LEONEL CASTILLO DIAZ | H8: 46266 | I8: 46262 | J8: =+VLOOKUP(K8,Datos!$A:$C,3,FALSE) -> ORIENTE | K8: 228 | L8: =+VLOOKUP(K8,Datos!$A:$C,2,FALSE) -> PRADERA CHIQUIMULA | M8: 314831 | N8: =+VLOOKUP(M8,Datos!$F:$G,2,FALSE) -> Karla Paola Solorzano Monroy | O8: =IFERROR(IF(A8="SI",VLOOKUP(R8,Datos!$J$1:$K$50,2,FALSE)*C8,VLOOKUP(R8,Datos!$P$1:$T$50,2,FALSE)*C8),0) -> 5472 | P8: 90040440 | Q8: =+VLOOKUP(P8,Datos!$F:$G,2,FALSE) -> Ericka Carolina Diaz Hernandez | R8: VIDA+SEGURO PLAN 1 | S8: SI | T8: =+COUNTIFS($G$2:$G$623,G8) -> 1
A9: SI | B9: CUOTAS | C9: 4 | D9: NUEVO | E9: VCB-20240007 | F9: 842 | G9: MARIA VICTORIA RAMIREZ VILLALTA | H9: 46266 | I9: 46262 | J9: =+VLOOKUP(K9,Datos!$A:$C,3,FALSE) -> ORIENTE | K9: 228 | L9: =+VLOOKUP(K9,Datos!$A:$C,2,FALSE) -> PRADERA CHIQUIMULA | M9: 314831 | N9: =+VLOOKUP(M9,Datos!$F:$G,2,FALSE) -> Karla Paola Solorzano Monroy | O9: =IFERROR(IF(A9="SI",VLOOKUP(R9,Datos!$J$1:$K$50,2,FALSE)*C9,VLOOKUP(R9,Datos!$P$1:$T$50,2,FALSE)*C9),0) -> 5472 | P9: 90040440 | Q9: =+VLOOKUP(P9,Datos!$F:$G,2,FALSE) -> Ericka Carolina Diaz Hernandez | R9: VIDA+SEGURO PLAN 1 | S9: SI | T9: =+COUNTIFS($G$2:$G$623,G9) -> 1
A10: SI | B10: CUOTAS | C10: 1 | D10: NUEVO | E10: VCB-20210003 | F10: 4169 | G10: JUAN ALBERTO AGUILAR YANES | H10: 46266 | I10: 46266 | J10: =+VLOOKUP(K10,Datos!$A:$C,3,FALSE) -> AMERICAS | K10: 30 | L10: =+VLOOKUP(K10,Datos!$A:$C,2,FALSE) -> BARBERENA | M10: 307706 | N10: =+VLOOKUP(M10,Datos!$F:$G,2,FALSE) -> Monica Guadalupe Garcia Rivera | O10: =IFERROR(IF(A10="SI",VLOOKUP(R10,Datos!$J$1:$K$50,2,FALSE)*C10,VLOOKUP(R10,Datos!$P$1:$T$50,2,FALSE)*C10),0) -> 816 | P10: 300594 | Q10: =+VLOOKUP(P10,Datos!$F:$G,2,FALSE) -> Rosaura Grisleny Perez Rios | R10: VIDA+SEGURO | S10: SI | T10: =+COUNTIFS($G$2:$G$623,G10) -> 1
A11: SI | B11: CONTADO | C11: 2 | D11: NUEVO | E11: VCB-20220010 | F11: 1086 | G11: KEDYN EDUARDO RUCAL ENRIQUEZ | H11: 46266 | I11: 46266 | J11: =+VLOOKUP(K11,Datos!$A:$C,3,FALSE) -> AMERICAS | K11: 30 | L11: =+VLOOKUP(K11,Datos!$A:$C,2,FALSE) -> BARBERENA | M11: 90024235 | N11: =+VLOOKUP(M11,Datos!$F:$G,2,FALSE) -> Jason Alberto Bolaños Gutiérrez | O11: =IFERROR(IF(A11="SI",VLOOKUP(R11,Datos!$J$1:$K$50,2,FALSE)*C11,VLOOKUP(R11,Datos!$P$1:$T$50,2,FALSE)*C11),0) -> 1632 | P11: 300594 | Q11: =+VLOOKUP(P11,Datos!$F:$G,2,FALSE) -> Rosaura Grisleny Perez Rios | R11: VIDA+SEGURO | S11: SI | T11: =+COUNTIFS($G$2:$G$623,G11) -> 1
A12: SI | B12: CONTADO | C12: 1 | D12: NUEVO | E12: VCB-20210003 | F12: 4181 | G12: SANDY ROSEMARY BARAHONA DEL CID | H12: 46267 | I12: 46267 | J12: =+VLOOKUP(K12,Datos!$A:$C,3,FALSE) -> PETAPA | K12: 250 | L12: =+VLOOKUP(K12,Datos!$A:$C,2,FALSE) -> BOCA DEL MONTE | M12: 312542 | N12: =+VLOOKUP(M12,Datos!$F:$G,2,FALSE) -> Elba Eulalia Esquite Lemus | O12: =IFERROR(IF(A12="SI",VLOOKUP(R12,Datos!$J$1:$K$50,2,FALSE)*C12,VLOOKUP(R12,Datos!$P$1:$T$50,2,FALSE)*C12),0) -> 816 | P12: 310796 | Q12: =+VLOOKUP(P12,Datos!$F:$G,2,FALSE) -> Madelyn Estefany Vega Velasquez | R12: VIDA+SEGURO | S12: SI | T12: =+COUNTIFS($G$2:$G$623,G12) -> 1
A13: SI | B13: CONTADO | C13: 1 | D13: NUEVO | E13: VCB-20210003 | F13: 4184 | G13: ELIXON ROMAN UCELO | H13: 46267 | I13: 46267 | J13: =+VLOOKUP(K13,Datos!$A:$C,3,FALSE) -> AMERICAS | K13: 53 | L13: =+VLOOKUP(K13,Datos!$A:$C,2,FALSE) -> PUERTA PARADA | M13: 314472 | N13: =+VLOOKUP(M13,Datos!$F:$G,2,FALSE) -> Yuri Madali Cabrera Garcia | O13: =IFERROR(IF(A13="SI",VLOOKUP(R13,Datos!$J$1:$K$50,2,FALSE)*C13,VLOOKUP(R13,Datos!$P$1:$T$50,2,FALSE)*C13),0) -> 1368 | P13: 300919 | Q13: =+VLOOKUP(P13,Datos!$F:$G,2,FALSE) -> Juan Jose Rodriguez Catu | R13: VIDA+SEGURO PLAN 1 | S13: SI | T13: =+COUNTIFS($G$2:$G$623,G13) -> 1
... A101: SI | B101: CUOTAS | C101: 2 | D101: NUEVO | E101: VCB-20220010 | F101: 1146 | G101: MAYNOR OVIDIO CHO BOL | H101: 46272 | I101: 46270 | J101: =+VLOOKUP(K101,Datos!$A:$C,3,FALSE) -> NORTE | K101: 162 | L101: =+VLOOKUP(K101,Datos!$A:$C,2,FALSE) -> CHISEC | M101: 314417 | N101: =+VLOOKUP(M101,Datos!$F:$G,2,FALSE) -> Krisley Mary Dayana Mazariegos Vega | O101: =IFERROR(IF(A101="SI",VLOOKUP(R101,Datos!$J$1:$K$50,2,FALSE)*C101,VLOOKUP(R101,Datos!$P$1:$T$50,2,FALSE)*C101),0) -> 1632 | P101: 315051 | Q101: =+VLOOKUP(P101,Datos!$F:$G,2,FALSE) -> Carlos Alfredo Catun Rax | R101: VIDA+SEGURO | S101: SI | T101: =+COUNTIFS($G$2:$G$623,G101) -> 1
A102: SI | B102: CUOTAS | C102: 2 | D102: NUEVO | E102: ACPE-20220038 | F102: 156 | G102: DYLAN DANIEL DIVAS ORDOÑEZ | H102: 46272 | I102: 46267 | J102: ORIENTE | K102: 41 | L102: JUTIAPA | M102: 90048448 | N102: Erick Cecilio Salvatierra García | O102: 2016 | P102: 301658 | Q102: Ruth Nohemi Contreras Hernandez | R102: AP BIENESTAR | S102: SI | T102: 1
A103: SI | B103: CUOTAS | C103: 1 | D103: NUEVO | E103: VCB-20210015 | F103: 410 | G103: EDWIN AMILCAR CHEN MO | H103: 46272 | I103: 46272 | J103: =+VLOOKUP(K103,Datos!$A:$C,3,FALSE) -> NORTE | K103: 205 | L103: =+VLOOKUP(K103,Datos!$A:$C,2,FALSE) -> SAN CRISTOBAL VERAPAZ | M103: 90081179 | N103: =+VLOOKUP(M103,Datos!$F:$G,2,FALSE) -> OSCAR MIGUEL QUEJ TILOM | O103: =IFERROR(IF(A103="SI",VLOOKUP(R103,Datos!$J$1:$K$50,2,FALSE)*C103,VLOOKUP(R103,Datos!$P$1:$T$50,2,FALSE)*C103),0) -> 1092 | P103: 300978 | Q103: =+VLOOKUP(P103,Datos!$F:$G,2,FALSE) -> Wuangler Geovane Cal Sucup | R103: PREVENCION+SEGURA | S103: SI | T103: =+COUNTIFS($G$2:$G$623,G103) -> 1
A104: SI | B104: CUOTAS | C104: 4 | D104: NUEVO | E104: VCB-20240008 | F104: 677 | G104: CESAR RAMIRO JUC CHUB | H104: 46272 | I104: 46272 | J104: =+VLOOKUP(K104,Datos!$A:$C,3,FALSE) -> NORTE | K104: 194 | L104: =+VLOOKUP(K104,Datos!$A:$C,2,FALSE) -> PLAYA GRANDE | M104: 90023865 | N104: =+VLOOKUP(M104,Datos!$F:$G,2,FALSE) -> Benito Abad Jimenez Carrillo | O104: =IFERROR(IF(A104="SI",VLOOKUP(R104,Datos!$J$1:$K$50,2,FALSE)*C104,VLOOKUP(R104,Datos!$P$1:$T$50,2,FALSE)*C104),0) -> 3264 | P104: 313593 | Q104: =+VLOOKUP(P104,Datos!$F:$G,2,FALSE) -> Slayker Andony Santiago Natareno | R104: VIDA+SEGURO | S104: SI | T104: =+COUNTIFS($G$2:$G$623,G104) -> 1
A105: SI | B105: CUOTAS | C105: 4 | D105: NUEVO | E105: VCB-20240008 | F105: 662 | G105: CRISTIAN LISANDRO GARCIA AGUILAR | H105: 46272 | I105: 46270 | J105: =+VLOOKUP(K105,Datos!$A:$C,3,FALSE) -> ORIENTE | K105: 156 | L105: =+VLOOKUP(K105,Datos!$A:$C,2,FALSE) -> TECULUTAN | M105: 315488 | N105: =+VLOOKUP(M105,Datos!$F:$G,2,FALSE) -> Maria Alejandra Lanuza Pérez | O105: =IFERROR(IF(A105="SI",VLOOKUP(R105,Datos!$J$1:$K$50,2,FALSE)*C105,VLOOKUP(R105,Datos!$P$1:$T$50,2,FALSE)*C105),0) -> 3264 | P105: 310483 | Q105: =+VLOOKUP(P105,Datos!$F:$G,2,FALSE) -> Astrid Ivone Hernandez | R105: VIDA+SEGURO | S105: SI | T105: =+COUNTIFS($G$2:$G$623,G105) -> 1
A106: SI | B106: CUOTAS | C106: 1 | D106: NUEVO | E106: VCB-20210003 | F106: 4328 | G106: FRANCISCO COC ICHIC | H106: 46272 | I106: 46273 | J106: =+VLOOKUP(K106,Datos!$A:$C,3,FALSE) -> NORTE | K106: 195 | L106: =+VLOOKUP(K106,Datos!$A:$C,2,FALSE) -> TELEMAN | M106: 310871 | N106: =+VLOOKUP(M106,Datos!$F:$G,2,FALSE) -> Yuri Vanessa Bac Caal De Gomez | O106: =IFERROR(IF(A106="SI",VLOOKUP(R106,Datos!$J$1:$K$50,2,FALSE)*C106,VLOOKUP(R106,Datos!$P$1:$T$50,2,FALSE)*C106),0) -> 1368 | P106: 315351 | Q106: =+VLOOKUP(P106,Datos!$F:$G,2,FALSE) -> Maria Vicenta Lopez Mancilla De De Del Valle | R106: VIDA+SEGURO PLAN 1 | S106: SI | T106: =+COUNTIFS($G$2:$G$623,G106) -> 1
A107: SI | B107: CUOTAS | C107: 1 | D107: NUEVO | E107: VCB-20210003 | F107: 4339 | G107: ALFREDO YAXCAL CUCUL | H107: 46272 | I107: 46272 | J107: =+VLOOKUP(K107,Datos!$A:$C,3,FALSE) -> NORTE | K107: 195 | L107: =+VLOOKUP(K107,Datos!$A:$C,2,FALSE) -> TELEMAN | M107: 90082179 | N107: =+VLOOKUP(M107,Datos!$F:$G,2,FALSE) -> REYNA ADELAIDA CHAMAN CAAL | O107: =IFERROR(IF(A107="SI",VLOOKUP(R107,Datos!$J$1:$K$50,2,FALSE)*C107,VLOOKUP(R107,Datos!$P$1:$T$50,2,FALSE)*C107),0) -> 1368 | P107: 315351 | Q107: =+VLOOKUP(P107,Datos!$F:$G,2,FALSE) -> Maria Vicenta Lopez Mancilla De De Del Valle | R107: VIDA+SEGURO PLAN 1 | S107: SI | T107: =+COUNTIFS($G$2:$G$623,G107) -> 1
A108: SI | B108: CONTADO | C108: 1 | D108: NUEVO | E108: VCB-20210003 | F108: 4314 | G108: AGUSTINA CABNAL COY | H108: 46272 | I108: 46272 | J108: =+VLOOKUP(K108,Datos!$A:$C,3,FALSE) -> NORTE | K108: 38 | L108: =+VLOOKUP(K108,Datos!$A:$C,2,FALSE) -> CARCHA | M108: 90064229 | N108: =+VLOOKUP(M108,Datos!$F:$G,2,FALSE) -> KRISHNA MORALES | O108: =IFERROR(IF(A108="SI",VLOOKUP(R108,Datos!$J$1:$K$50,2,FALSE)*C108,VLOOKUP(R108,Datos!$P$1:$T$50,2,FALSE)*C108),0) -> 816 | P108: 315962 | Q108: =+VLOOKUP(P108,Datos!$F:$G,2,FALSE) -> Jennifer Celeste Delgado Garcia | R108: VIDA+SEGURO | S108: SI | T108: =+COUNTIFS($G$2:$G$623,G108) -> 2
A109: SI | B109: CUOTAS | C109: 2 | D109: NUEVO | E109: VCB-20220010 | F109: 1172 | G109: MARY ISELA INTERIANO GARCIA | H109: 46272 | I109: 46272 | J109: =+VLOOKUP(K109,Datos!$A:$C,3,FALSE) -> PETAPA | K109: 86 | L109: =+VLOOKUP(K109,Datos!$A:$C,2,FALSE) -> EL FRUTAL | M109: 310719 | N109: =+VLOOKUP(M109,Datos!$F:$G,2,FALSE) -> Gladyz Ninett Sanchez Perez | O109: =IFERROR(IF(A109="SI",VLOOKUP(R109,Datos!$J$1:$K$50,2,FALSE)*C109,VLOOKUP(R109,Datos!$P$1:$T$50,2,FALSE)*C109),0) -> 2736 | P109: 313727 | Q109: =+VLOOKUP(P109,Datos!$F:$G,2,FALSE) -> Erwin Antonio Lorenzo Zamora | R109: VIDA+SEGURO PLAN 1 | S109: SI | T109: =+COUNTIFS($G$2:$G$623,G109) -> 1
A110: SI | B110: CUOTAS | C110: 1 | D110: NUEVO | E110: VCB-20210003 | F110: 4329 | G110: JORGE LUIS HERNANDEZ ALVAREZ | H110: 46272 | I110: 46270 | J110: =+VLOOKUP(K110,Datos!$A:$C,3,FALSE) -> AMERICAS | K110: 231 | L110: =+VLOOKUP(K110,Datos!$A:$C,2,FALSE) -> SANTA AMELIA ZONA 16 | M110: 308152 | N110: =+VLOOKUP(M110,Datos!$F:$G,2,FALSE) -> Ericka Nathali Huitz Ortega | O110: =IFERROR(IF(A110="SI",VLOOKUP(R110,Datos!$J$1:$K$50,2,FALSE)*C110,VLOOKUP(R110,Datos!$P$1:$T$50,2,FALSE)*C110),0) -> 816 | P110: 311092 | Q110: =+VLOOKUP(P110,Datos!$F:$G,2,FALSE) -> Sandra Patricia Ochoa Sanchez | R110: VIDA+SEGURO | S110: SI | T110: =+COUNTIFS($G$2:$G$623,G110) -> 1
A111: SI | B111: CUOTAS | C111: 4 | D111: NUEVO | E111: VCB-20240008 | F111: 686 | G111: IRMA DAMARIS GOMEZ PEREZ | H111: 46273 | I111: 46273 | J111: =+VLOOKUP(K111,Datos!$A:$C,3,FALSE) -> ORIENTE | K111: 128 | L111: =+VLOOKUP(K111,Datos!$A:$C,2,FALSE) -> CHIQUIMULA 2 | M111: 313864 | N111: =+VLOOKUP(M111,Datos!$F:$G,2,FALSE) -> Milena Maria Mendez Cheguen | O111: =IFERROR(IF(A111="SI",VLOOKUP(R111,Datos!$J$1:$K$50,2,FALSE)*C111,VLOOKUP(R111,Datos!$P$1:$T$50,2,FALSE)*C111),0) -> 5472 | P111: 312176 | Q111: =+VLOOKUP(P111,Datos!$F:$G,2,FALSE) -> Nestor Edgardo Gutierrez Lazaro | R111: VIDA+SEGURO PLAN 1 | S111: SI | T111: =+COUNTIFS($G$2:$G$623,G111) -> 1
A112: SI | B112: CONTADO | C112: 1 | D112: NUEVO | E112: VCB-20210015 | F112: 415 | G112: KEVIN VLADIMIR PAIZ QUEL | H112: 46273 | I112: 46273 | J112: =+VLOOKUP(K112,Datos!$A:$C,3,FALSE) -> AMERICAS | K112: 231 | L112: =+VLOOKUP(K112,Datos!$A:$C,2,FALSE) -> SANTA AMELIA ZONA 16 | M112: 308152 | N112: =+VLOOKUP(M112,Datos!$F:$G,2,FALSE) -> Ericka Nathali Huitz Ortega | O112: =IFERROR(IF(A112="SI",VLOOKUP(R112,Datos!$J$1:$K$50,2,FALSE)*C112,VLOOKUP(R112,Datos!$P$1:$T$50,2,FALSE)*C112),0) -> 1092 | P112: 311092 | Q112: =+VLOOKUP(P112,Datos!$F:$G,2,FALSE) -> Sandra Patricia Ochoa Sanchez | R112: PREVENCION+SEGURA | S112: Pendiente | T112: =+COUNTIFS($G$2:$G$623,G112) -> 1
A113: SI | B113: CUOTAS | C113: 4 | D113: NUEVO | E113: VCB-20240008 | F113: 637 | G113: ANA GLADYS CORDON ASENCIO | H113: 46273 | I113: 46268 | J113: =+VLOOKUP(K113,Datos!$A:$C,3,FALSE) -> ORIENTE | K113: 156 | L113: =+VLOOKUP(K113,Datos!$A:$C,2,FALSE) -> TECULUTAN | M113: 315488 | N113: =+VLOOKUP(M113,Datos!$F:$G,2,FALSE) -> Maria Alejandra Lanuza Pérez | O113: =IFERROR(IF(A113="SI",VLOOKUP(R113,Datos!$J$1:$K$50,2,FALSE)*C113,VLOOKUP(R113,Datos!$P$1:$T$50,2,FALSE)*C113),0) -> 27312 | P113: 310483 | Q113: =+VLOOKUP(P113,Datos!$F:$G,2,FALSE) -> Astrid Ivone Hernandez | R113: VIDA+SEGURO PLAN 5 | S113: SI | T113: =+COUNTIFS($G$2:$G$623,G113) -> 1
A114: SI | B114: CONTADO | C114: 1 | D114: NUEVO | E114: VCB-20210003 | F114: 4345 | G114: ODILIA LISSETH AJCU BOROR | H114: 46273 | I114: 46273 | J114: =+VLOOKUP(K114,Datos!$A:$C,3,FALSE) -> PETAPA | K114: 112 | L114: =+VLOOKUP(K114,Datos!$A:$C,2,FALSE) -> PACIFIC CENTER | M114: 90063387 | N114: =+VLOOKUP(M114,Datos!$F:$G,2,FALSE) -> ANA MARTINEZ | O114: =IFERROR(IF(A114="SI",VLOOKUP(R114,Datos!$J$1:$K$50,2,FALSE)*C114,VLOOKUP(R114,Datos!$P$1:$T$50,2,FALSE)*C114),0) -> 816 | P114: 309744 | Q114: =+VLOOKUP(P114,Datos!$F:$G,2,FALSE) -> Odalis Ruby Garcia Siquina | R114: VIDA+SEGURO | S114: SI | T114: =+COUNTIFS($G$2:$G$623,G114) -> 1
... A343: SI | B343: CONTADO | C343: 4 | D343: NUEVO | E343: VCB-20240008 | F343: 873 | G343: ROLANDO POP CAAL | H343: 46285 | I343: 46285 | J343: =+VLOOKUP(K343,Datos!$A:$C,3,FALSE) -> NORTE | K343: 38 | L343: =+VLOOKUP(K343,Datos!$A:$C,2,FALSE) -> CARCHA | M343: 305736 | N343: =+VLOOKUP(M343,Datos!$F:$G,2,FALSE) -> Edvin Estuardo Ordoñez Gonzalez | O343: =IFERROR(IF(A343="SI",VLOOKUP(R343,Datos!$J$1:$K$50,2,FALSE)*C343,VLOOKUP(R343,Datos!$P$1:$T$50,2,FALSE)*C343),0) -> 10944 | P343: 313802 | Q343: =+VLOOKUP(P343,Datos!$F:$G,2,FALSE) -> Ligia Delfina Caal Coy | R343: VIDA+SEGURO PLAN 2 | S343: SI | T343: =+COUNTIFS($G$2:$G$623,G343) -> 1
A344: SI | D344: NUEVO | E344: PENDIENTE | F344: PENDIENTE | J344: =+VLOOKUP(K344,Datos!$A:$C,3,FALSE) -> #N/A | L344: =+VLOOKUP(K344,Datos!$A:$C,2,FALSE) -> #N/A | N344: =+VLOOKUP(M344,Datos!$F:$G,2,FALSE) -> #N/A | O344: =IFERROR(IF(A344="SI",VLOOKUP(R344,Datos!$J$1:$K$50,2,FALSE)*C344,VLOOKUP(R344,Datos!$P$1:$T$50,2,FALSE)*C344),0) -> 0 | Q344: =+VLOOKUP(P344,Datos!$F:$G,2,FALSE) -> #N/A | T344: =+COUNTIFS($G$2:$G$623,G344) -> 0
A345: SI | D345: NUEVO | E345: PENDIENTE | F345: PENDIENTE | J345: =+VLOOKUP(K345,Datos!$A:$C,3,FALSE) -> #N/A | L345: =+VLOOKUP(K345,Datos!$A:$C,2,FALSE) -> #N/A | N345: =+VLOOKUP(M345,Datos!$F:$G,2,FALSE) -> #N/A | O345: =IFERROR(IF(A345="SI",VLOOKUP(R345,Datos!$J$1:$K$50,2,FALSE)*C345,VLOOKUP(R345,Datos!$P$1:$T$50,2,FALSE)*C345),0) -> 0 | Q345: =+VLOOKUP(P345,Datos!$F:$G,2,FALSE) -> #N/A | T345: =+COUNTIFS($G$2:$G$623,G345) -> 0
A346: SI | D346: NUEVO | E346: PENDIENTE | F346: PENDIENTE | J346: =+VLOOKUP(K346,Datos!$A:$C,3,FALSE) -> #N/A | L346: =+VLOOKUP(K346,Datos!$A:$C,2,FALSE) -> #N/A | N346: =+VLOOKUP(M346,Datos!$F:$G,2,FALSE) -> #N/A | O346: =IFERROR(IF(A346="SI",VLOOKUP(R346,Datos!$J$1:$K$50,2,FALSE)*C346,VLOOKUP(R346,Datos!$P$1:$T$50,2,FALSE)*C346),0) -> 0 | Q346: =+VLOOKUP(P346,Datos!$F:$G,2,FALSE) -> #N/A | T346: =+COUNTIFS($G$2:$G$623,G346) -> 0
A347: SI | D347: NUEVO | E347: PENDIENTE | F347: PENDIENTE | J347: =+VLOOKUP(K347,Datos!$A:$C,3,FALSE) -> #N/A | L347: =+VLOOKUP(K347,Datos!$A:$C,2,FALSE) -> #N/A | N347: =+VLOOKUP(M347,Datos!$F:$G,2,FALSE) -> #N/A | O347: =IFERROR(IF(A347="SI",VLOOKUP(R347,Datos!$J$1:$K$50,2,FALSE)*C347,VLOOKUP(R347,Datos!$P$1:$T$50,2,FALSE)*C347),0) -> 0 | Q347: =+VLOOKUP(P347,Datos!$F:$G,2,FALSE) -> #N/A | T347: =+COUNTIFS($G$2:$G$623,G347) -> 0
A348: SI | D348: NUEVO | E348: PENDIENTE | F348: PENDIENTE | J348: =+VLOOKUP(K348,Datos!$A:$C,3,FALSE) -> #N/A | L348: =+VLOOKUP(K348,Datos!$A:$C,2,FALSE) -> #N/A | N348: =+VLOOKUP(M348,Datos!$F:$G,2,FALSE) -> #N/A | O348: =IFERROR(IF(A348="SI",VLOOKUP(R348,Datos!$J$1:$K$50,2,FALSE)*C348,VLOOKUP(R348,Datos!$P$1:$T$50,2,FALSE)*C348),0) -> 0 | Q348: =+VLOOKUP(P348,Datos!$F:$G,2,FALSE) -> #N/A | T348: =+COUNTIFS($G$2:$G$623,G348) -> 0
A349: SI | D349: NUEVO | E349: PENDIENTE | F349: PENDIENTE | J349: =+VLOOKUP(K349,Datos!$A:$C,3,FALSE) -> #N/A | L349: =+VLOOKUP(K349,Datos!$A:$C,2,FALSE) -> #N/A | N349: =+VLOOKUP(M349,Datos!$F:$G,2,FALSE) -> #N/A | O349: =IFERROR(IF(A349="SI",VLOOKUP(R349,Datos!$J$1:$K$50,2,FALSE)*C349,VLOOKUP(R349,Datos!$P$1:$T$50,2,FALSE)*C349),0) -> 0 | Q349: =+VLOOKUP(P349,Datos!$F:$G,2,FALSE) -> #N/A | T349: =+COUNTIFS($G$2:$G$623,G349) -> 0
A350: SI | D350: NUEVO | E350: PENDIENTE | F350: PENDIENTE | J350: =+VLOOKUP(K350,Datos!$A:$C,3,FALSE) -> #N/A | L350: =+VLOOKUP(K350,Datos!$A:$C,2,FALSE) -> #N/A | N350: =+VLOOKUP(M350,Datos!$F:$G,2,FALSE) -> #N/A | O350: =IFERROR(IF(A350="SI",VLOOKUP(R350,Datos!$J$1:$K$50,2,FALSE)*C350,VLOOKUP(R350,Datos!$P$1:$T$50,2,FALSE)*C350),0) -> 0 | Q350: =+VLOOKUP(P350,Datos!$F:$G,2,FALSE) -> #N/A | T350: =+COUNTIFS($G$2:$G$623,G350) -> 0
A351: SI | D351: NUEVO | E351: PENDIENTE | F351: PENDIENTE | J351: =+VLOOKUP(K351,Datos!$A:$C,3,FALSE) -> #N/A | L351: =+VLOOKUP(K351,Datos!$A:$C,2,FALSE) -> #N/A | N351: =+VLOOKUP(M351,Datos!$F:$G,2,FALSE) -> #N/A | O351: =IFERROR(IF(A351="SI",VLOOKUP(R351,Datos!$J$1:$K$50,2,FALSE)*C351,VLOOKUP(R351,Datos!$P$1:$T$50,2,FALSE)*C351),0) -> 0 | Q351: =+VLOOKUP(P351,Datos!$F:$G,2,FALSE) -> #N/A | T351: =+COUNTIFS($G$2:$G$623,G351) -> 0
A352: SI | D352: NUEVO | E352: PENDIENTE | F352: PENDIENTE | J352: =+VLOOKUP(K352,Datos!$A:$C,3,FALSE) -> #N/A | L352: =+VLOOKUP(K352,Datos!$A:$C,2,FALSE) -> #N/A | N352: =+VLOOKUP(M352,Datos!$F:$G,2,FALSE) -> #N/A | O352: =IFERROR(IF(A352="SI",VLOOKUP(R352,Datos!$J$1:$K$50,2,FALSE)*C352,VLOOKUP(R352,Datos!$P$1:$T$50,2,FALSE)*C352),0) -> 0 | Q352: =+VLOOKUP(P352,Datos!$F:$G,2,FALSE) -> #N/A | T352: =+COUNTIFS($G$2:$G$623,G352) -> 0
A353: SI | D353: NUEVO | E353: PENDIENTE | F353: PENDIENTE | J353: =+VLOOKUP(K353,Datos!$A:$C,3,FALSE) -> #N/A | L353: =+VLOOKUP(K353,Datos!$A:$C,2,FALSE) -> #N/A | N353: =+VLOOKUP(M353,Datos!$F:$G,2,FALSE) -> #N/A | O353: =IFERROR(IF(A353="SI",VLOOKUP(R353,Datos!$J$1:$K$50,2,FALSE)*C353,VLOOKUP(R353,Datos!$P$1:$T$50,2,FALSE)*C353),0) -> 0 | Q353: =+VLOOKUP(P353,Datos!$F:$G,2,FALSE) -> #N/A | T353: =+COUNTIFS($G$2:$G$623,G353) -> 0
A354: SI | D354: NUEVO | E354: PENDIENTE | F354: PENDIENTE | J354: =+VLOOKUP(K354,Datos!$A:$C,3,FALSE) -> #N/A | L354: =+VLOOKUP(K354,Datos!$A:$C,2,FALSE) -> #N/A | N354: =+VLOOKUP(M354,Datos!$F:$G,2,FALSE) -> #N/A | O354: =IFERROR(IF(A354="SI",VLOOKUP(R354,Datos!$J$1:$K$50,2,FALSE)*C354,VLOOKUP(R354,Datos!$P$1:$T$50,2,FALSE)*C354),0) -> 0 | Q354: =+VLOOKUP(P354,Datos!$F:$G,2,FALSE) -> #N/A | T354: =+COUNTIFS($G$2:$G$623,G354) -> 0
A355: SI | D355: NUEVO | E355: PENDIENTE | F355: PENDIENTE | J355: =+VLOOKUP(K355,Datos!$A:$C,3,FALSE) -> #N/A | L355: =+VLOOKUP(K355,Datos!$A:$C,2,FALSE) -> #N/A | N355: =+VLOOKUP(M355,Datos!$F:$G,2,FALSE) -> #N/A | O355: =IFERROR(IF(A355="SI",VLOOKUP(R355,Datos!$J$1:$K$50,2,FALSE)*C355,VLOOKUP(R355,Datos!$P$1:$T$50,2,FALSE)*C355),0) -> 0 | Q355: =+VLOOKUP(P355,Datos!$F:$G,2,FALSE) -> #N/A | T355: =+COUNTIFS($G$2:$G$623,G355) -> 0
...

Sheet Datos
A1: FTE. | B1: AGENCIA | C1: ZONA | F1: Codigo Empleado | G1: Nombre Empleado | H1: Codigo Empleado | I1: BAM | J1: Producto | K1: 1 año | L1: 2 años | M1: 3 años | N1: 4 años | O1: OTRO BANCO | P1: Producto | Q1: 1 año | R1: 2 años | S1: 3 años | T1: 4 años | V1: TIPO DE PAGO | X1: BAM | Z1: Poliza firmada
A2: 14 | B2: PRADERA | C2: AMERICAS | F2: 311961 | G2: Abner Eli Gonzalez Gonzalez | H2: 0 | J2: VIDA+SEGURO | K2: 816 | L2: 1632 | M2: 2448 | N2: 3264 | P2: VIDA+SEGURO | Q2: 888 | R2: 1776 | S2: 2664 | T2: 3552 | V2: CUOTAS | X2: SI | Z2: SI
A3: 53 | B3: PUERTA PARADA | C3: AMERICAS | F3: 305051 | G3: Amalia Cifuentes Gramajo | H3: 0 | J3: CONSULTA COMPLETO + BIENESTAR | K3: 2472 | L3: 4944 | M3: 7416 | N3: 9888 | P3: CONSULTA COMPLETO + BIENESTAR | Q3: 2067 | R3: 4134 | S3: 6201 | T3: 8268 | V3: CONTADO | X3: NO | Z3: Pendiente
A4: 54 | B4: LAS CONCHAS ZONA 14 | C4: AMERICAS | F4: 308201 | G4: Amparo Janet Cardona Linares | H4: 0 | J4: CONSULTA BASICO | K4: 1428 | L4: 2856 | M4: 4284 | N4: 5712 | P4: CONSULTA BASICO | Q4: 1548 | R4: 3096 | S4: 4644 | T4: 6192
A5: 58 | B5: EUROPLAZA | C5: AMERICAS | F5: 311188 | G5: Ana Ester Cuyan Aguilar De Dominguez | H5: 0 | J5: CONSULTA BASICO + BIENESTAR | K5: 1908 | L5: 3816 | M5: 5724 | N5: 7632 | P5: CONSULTA BASICO + BIENESTAR | Q5: 2676 | R5: 5352 | S5: 8028 | T5: 10704
A6: 71 | B6: VISTA HERMOSA | C6: AMERICAS | F6: 311460 | G6: Ana Vilma Bamaca Cardona | H6: 0 | J6: MULTIASISTENCIAS | K6: 1704 | L6: 3408 | M6: 5112 | N6: 6816 | P6: MULTIASISTENCIAS | Q6: 1848 | R6: 3696 | S6: 5544 | T6: 7392
A7: 90 | B7: CENTRO MEDICO | C7: AMERICAS | F7: 306579 | G7: Angel Emilio De Jesus Morales Ramirez | H7: 0 | J7: AP DENTAL FAMILIAR | K7: 1332 | L7: 2664 | M7: 3996 | N7: 5328 | P7: AP DENTAL FAMILIAR | Q7: 1440 | R7: 2880 | S7: 4320 | T7: 5760
A8: 92 | B8: CONDADO CONCEPCION | C8: AMERICAS | F8: 312284 | G8: Arnoldo Coque Hernandez | H8: 0 | J8: AP BIENESTAR | K8: 1008 | L8: 2016 | M8: 3024 | N8: 4032 | P8: AP BIENESTAR | Q8: 1092 | R8: 2184 | S8: 3276 | T8: 4368
A9: 224 | B9: MINUTO CARRETERA A EL SALVADOR | C9: AMERICAS | F9: 311234 | G9: Astrid Marlene Diaz | H9: 0 | J9: AUTO+SEGURO (AUTO) | K9: 2052 | L9: 4104 | M9: 6156 | N9: 8208 | P9: AUTO+SEGURO (AUTO) | Q9: 2160 | R9: 4320 | S9: 6480 | T9: 8640
A10: 226 | B10: SAN JOSE PINULA | C10: AMERICAS | F10: 308361 | G10: Brenda Maribel Orozco Mendoza | H10: 0 | J10: PREVENCION+SEGURA | K10: 1092 | L10: 2184 | M10: 3276 | N10: 4368 | P10: PREVENCION+SEGURA | Q10: 1200 | R10: 2400 | S10: 3600 | T10: 4800
A11: 231 | B11: SANTA AMELIA ZONA 16 | C11: AMERICAS | F11: 309678 | G11: Carla Noemi Irias Alvarez | H11: 0 | J11: AP DENTAL INDIVIDUAL | K11: 1308 | L11: 2616 | M11: 3924 | N11: 5232 | P11: AP DENTAL INDIVIDUAL | Q11: 1416 | R11: 2832 | S11: 4248 | T11: 5664
A12: 278 | B12: HINCAPIE | C12: AMERICAS | F12: 311232 | G12: Carlos Alberto Roque Galicia | H12: 0 | J12: CONSULTA COMPLETO | K12: 2004 | L12: 4008 | M12: 6012 | N12: 8016 | P12: CONSULTA COMPLETO | Q12: 2172 | R12: 4344 | S12: 6516 | T12: 8688
A13: 294 | B13: PLAZA ZONA 14 | C13: AMERICAS | F13: 312015 | G13: Carlos Alfredo Cuc Cuxe | H13: 0 | J13: AUTO+SEGURO (PICK UP) | K13: 2280 | L13: =K13*2 -> 4560 | M13: =K13*3 -> 6840 | N13: =K13*4 -> 9120 | P13: AUTO+SEGURO (PICK UP) | Q13: 1937 | R13: 3874 | S13: 5811 | T13: 7748
A14: 306 | B14: PLAZA VARIETA | C14: AMERICAS | F14: 311704 | G14: Celedonia Isabel Chan Batz De Iscaya | H14: 0 | J14: VIDA+SEGURO PLAN 1 | K14: 1368 | L14: 2736 | M14: 4104 | N14: 5472 | P14: VIDA+SEGURO PLAN 1 | Q14: 1488 | R14: 2976 | S14: 4464 | T14: 5952
A15: 338 | B15: SPAZIO | C15: AMERICAS | F15: 311894 | G15: Christyan Stuardo Ronquillo Saravia | H15: 0 | J15: VIDA+SEGURO PLAN 2 | K15: 2736 | L15: 5472 | M15: 8208 | N15: 10944 | P15: VIDA+SEGURO PLAN 2 | Q15: 2964 | R15: 5928 | S15: 8892 | T15: 11856
A16: 1000 | B16: PLAZA FINANCIERA | C16: AMERICAS | F16: 308901 | G16: David Estuardo Rosales Corado | H16: 0 | J16: VIDA+SEGURO PLAN 3 | K16: 4104 | L16: 8208 | M16: 12312 | N16: 16416 | P16: VIDA+SEGURO PLAN 3 | Q16: 4452 | R16: 8904 | S16: 13356 | T16: 17808
A17: 1 | B17: FUNDACION | C17: CENTRO HISTORICO | F17: 310382 | G17: David Gilberto Perez Mayorga | H17: 0 | J17: VIDA+SEGURO PLAN 4 | K17: 5460 | L17: 10920 | M17: 16380 | N17: 21840 | P17: VIDA+SEGURO PLAN 4 | Q17: 5916 | R17: 11832 | S17: 17748 | T17: 23664
A18: 2 | B18: ZONA 1 | C18: CENTRO HISTORICO | F18: 312069 | G18: De Leon Cach Roberto Carlos | H18: 0 | J18: VIDA+SEGURO PLAN 5 | K18: 6828 | L18: 13656 | M18: 20484 | N18: 27312 | P18: VIDA+SEGURO PLAN 5 | Q18: 7392 | R18: 14784 | S18: 22176 | T18: 29568
A19: 12 | B19: PLAZA FLORIDA | C19: CENTRO HISTORICO | F19: 311060 | G19: Dora Lissette Higueros Trejo | H19: 0 | J19: VIDA+SEGURO PLAN 6 | K19: 8196 | L19: 16392 | M19: 24588 | N19: 32784
A20: 13 | B20: METANORTE | C20: CENTRO HISTORICO | F20: 310710 | G20: Edgar Enrique Garcia Cortave | H20: 0 | J20: VIDA+SEGURO PLAN 7 | K20: 10056 | L20: 20112 | M20: 30168 | N20: 40224
A21: 19 | B21: MORAZAN ZONA 2 | C21: CENTRO HISTORICO | F21: 312045 | G21: Edgar Marco Tulio Sanchez Ochoa | H21: 0 | J21: MIGRANTE BAM | K21: 1380 | L21: 2760 | M21: 4140 | N21: 5520 | P21: MIGRANTE BAM | Q21: 1500 | R21: 3000 | S21: 4500 | T21: 6000
A22: 37 | B22: SAN JUAN SACATEPEQUEZ | C22: CENTRO HISTORICO | F22: 309496 | G22: Elcira Livduvina Perez Lopez De Merlos | H22: 0 | J22: MOTO+SEGURA | K22: 1500 | L22: 3000 | M22: 4500 | N22: 6000 | P22: MOTO+SEGURA | Q22: 1428 | R22: 2856 | S22: 4284 | T22: 5712
A23: 61 | B23: DEL CENTRO | C23: CENTRO HISTORICO | F23: 310331 | G23: Elda Luzbina Valdez Guerra De Fuentes | H23: 0
A24: 81 | B24: PEDRERA | C24: CENTRO HISTORICO | F24: 305796 | G24: Elias Perez Sequen | H24: 0
A25: 83 | B25: DISAGRO | C25: CENTRO HISTORICO | F25: 308464 | G25: Enmanuel Antonio Ochoa Hernandez | H25: 0
A26: 87 | B26: EL NARANJO | C26: CENTRO HISTORICO | F26: 312053 | G26: Erick Estuardo Gonzalez Culajay | H26: 0
A27: 98 | B27: CALLE MARTI | C27: CENTRO HISTORICO | F27: 311964 | G27: Estephanie Michelle Mendez Cano De Rivera | H27: 0
A28: 103 | B28: LOS ALAMOS | C28: CENTRO HISTORICO | F28: 309795 | G28: Evelin Johana Perez Fajardo De Estayul | H28: 0
A29: 113 | B29: PARQUE COLON | C29: CENTRO HISTORICO | F29: 310823 | G29: Francisca Yesenia Aceytuno Quevedo | H29: 0
A30: 166 | B30: 23 CALLE | C30: CENTRO HISTORICO | F30: 308490 | G30: Gabriela Poitan Ordoñez De Garcia | H30: 0
A31: 296 | B31: PORTALES | C31: CENTRO HISTORICO | F31: 311459 | G31: Gandy Baygesus Sanchez Estrada | H31: 0
A32: 302 | B32: CENTRANORTE | C32: CENTRO HISTORICO | F32: 303585 | G32: Gerber Estuardo Albizures Archila | H32: 0
A33: 21 | B33: SANTA LU | C33: COSTA SUR | F33: 311963 | G33: Giovanni Noel Valdez Rodriguez | H33: 0
A34: 24 | B34: ESCUINTLA | C34: COSTA SUR | F34: 308771 | G34: Gloria Estefanilla Espinoza Garcia | H34: 0
... A167: 346 | B167: PLAZA MADERO PROCERES | C167: AMERICAS | F167: 301139 | G167: Ana Cecilia De Los Angeles Monterroso Garcia | H167: 0
F168: 307790 | G168: Ana Cecilia Navichoc Chiquival | H168: 0
F169: 315044 | G169: Ana Celeste Garcia Garcia | H169: 0
F170: 90040315 | G170: Ana Daniela Lopez Cabrera | H170: 0
F171: 316153 | G171: Ana Del Rosario Yol Gonzalez | H171: 0
F172: 315858 | G172: Ana Francisca Citalan Velasquez | H172: 0
...
