Workbook
Name A: #REF!
Name A: #REF!
Name alex: [8]AGENCIA!#REF!
Name alex: [8]AGENCIA!#REF!
Name asdf: #REF!
Name asdf: #REF!

Sheet Mayo
A1: TARJETA BAM | B1: Pago | C1: Vigencia | D1: Tipo | E1: Poliza | F1: Certificado | G1: Nombre | H1: Fecha | I1: Fecha Cobro | J1: Zona | K1: Fuente | L1: Agencia | M1: Cod. Colaborador | N1: Nombre colaborador | O1: Prima | P1: Cod. Jefe | Q1: Nombre Jefe | R1: Producto | S1: Puesto | U1: Modificaciones | V1: Control | W1: Equipo | X1: Enviada | Y1: Meta campaña | Z1: Asesor
A2: SI | C2: 2 | D2: VIDA+SEGURO | E2: VCB-20220010 | F2: 1097 | G2: LEONIDAS BERNABE LOPEZ RAMOS | H2: 46266 | I2: 46266 | J2: =+VLOOKUP(K2,Datos!$A:$C,3,FALSE) -> SUROCCIDENTE | K2: 297 | L2: =+VLOOKUP(K2,Datos!$A:$C,2,FALSE) -> LA TRINIDAD COATEPEQUE | M2: 310220 | N2: =+VLOOKUP(M2,Datos!$F:$G,2,FALSE) -> Urias Samuel Velasquez Ardeano | O2: =IFERROR(IF(A2="SI",VLOOKUP(R2,Datos!$J$1:$K$50,2,FALSE)*C2,VLOOKUP(R2,Datos!$P$1:$T$13,2,FALSE)*C2),0) -> 1632 | P2: 311975 | Q2: =+VLOOKUP(P2,Datos!$F:$G,2,FALSE) -> Luis Eduardo Ramirez Arriaza | R2: VIDA+SEGURO | V2: =+COUNTIFS($G$2:$G$444,G2) -> 1 | W2: =+VLOOKUP(M2,Datos!$F:$H,3,FALSE) -> 0 | X2: 0 | Z2: =VLOOKUP(M2,'[1]INDIVIDUAL UN'!$C$6:$F$222,4,FALSE) -> #N/A
A3: SI | C3: 4 | D3: NUEVO | E3: VCB-20240008 | F3: 625 | G3: JAIME LEONEL DE LEON REYES | H3: 46266 | I3: 46266 | J3: =+VLOOKUP(K3,Datos!$A:$C,3,FALSE) -> SUROCCIDENTE | K3: 31 | L3: =+VLOOKUP(K3,Datos!$A:$C,2,FALSE) -> COATEPEQUE | M3: 316174 | N3: =+VLOOKUP(M3,Datos!$F:$G,2,FALSE) -> ENRIQUE ALFONSO LOPEZ RAMREZ | O3: =IFERROR(IF(A3="SI",VLOOKUP(R3,Datos!$J$1:$K$50,2,FALSE)*C3,VLOOKUP(R3,Datos!$P$1:$T$13,2,FALSE)*C3),0) -> 3264 | P3: 311258 | Q3: =+VLOOKUP(P3,Datos!$F:$G,2,FALSE) -> Victor Otoniel Sebastian Cardona | R3: VIDA+SEGURO | V3: =+COUNTIFS($G$2:$G$444,G3) -> 1 | W3: =+VLOOKUP(M3,Datos!$F:$H,3,FALSE) -> 0 | X3: 0 | Z3: =VLOOKUP(M3,'[1]INDIVIDUAL UN'!$C$6:$F$222,4,FALSE) -> #N/A
A4: SI | C4: 1 | D4: NUEVO | E4: VCB - 20210003 | F4: 4179 | G4: ERIKA MARINA ALONZO | H4: 46266 | I4: 46266 | J4: =+VLOOKUP(K4,Datos!$A:$C,3,FALSE) -> OCCIDENTE | K4: 28 | L4: =+VLOOKUP(K4,Datos!$A:$C,2,FALSE) -> SUCURSAL QUETZALTENANGO | M4: 90024418 | N4: =+VLOOKUP(M4,Datos!$F:$G,2,FALSE) -> EDNA GABRIELA RAMIREZ | O4: =IFERROR(IF(A4="SI",VLOOKUP(R4,Datos!$J$1:$K$50,2,FALSE)*C4,VLOOKUP(R4,Datos!$P$1:$T$13,2,FALSE)*C4),0) -> 816 | P4: 313644 | Q4: =+VLOOKUP(P4,Datos!$F:$G,2,FALSE) -> Estefani Elizabeth Tzul Macario | R4: VIDA+SEGURO | V4: =+COUNTIFS($G$2:$G$444,G4) -> 1 | W4: =+VLOOKUP(M4,Datos!$F:$H,3,FALSE) -> 0 | X4: 0 | Z4: =VLOOKUP(M4,'[1]INDIVIDUAL UN'!$C$6:$F$222,4,FALSE) -> #N/A
A5: SI | C5: 1 | D5: NUEVO | E5: APSS-20200009 | F5: 2938 | G5: JOSUE EZEQUIEL CAAL | H5: 46266 | I5: 46266 | J5: =+VLOOKUP(K5,Datos!$A:$C,3,FALSE) -> OCCIDENTE | K5: 126 | L5: =+VLOOKUP(K5,Datos!$A:$C,2,FALSE) -> CHICHICASTENANGO | M5: 314956 | N5: =+VLOOKUP(M5,Datos!$F:$G,2,FALSE) -> Sebastian Geovanny Calel Ixtuc | O5: =IFERROR(IF(A5="SI",VLOOKUP(R5,Datos!$J$1:$K$50,2,FALSE)*C5,VLOOKUP(R5,Datos!$P$1:$T$13,2,FALSE)*C5),0) -> 1428 | P5: 306497 | Q5: =+VLOOKUP(P5,Datos!$F:$G,2,FALSE) -> Erika Ixtan Canil | R5: CONSULTA BASICO | V5: =+COUNTIFS($G$2:$G$444,G5) -> 1 | W5: =+VLOOKUP(M5,Datos!$F:$H,3,FALSE) -> 0 | X5: 0 | Z5: =VLOOKUP(M5,'[1]INDIVIDUAL UN'!$C$6:$F$222,4,FALSE) -> #N/A
A6: SI | C6: 1 | D6: NUEVO | E6: VCB-20210003 | F6: 4168 | G6: CARLOS ALFREDO TECUN DOMINGUEZ | H6: 46266 | I6: 46266 | J6: =+VLOOKUP(K6,Datos!$A:$C,3,FALSE) -> OCCIDENTE | K6: 126 | L6: =+VLOOKUP(K6,Datos!$A:$C,2,FALSE) -> CHICHICASTENANGO | M6: 310610 | N6: =+VLOOKUP(M6,Datos!$F:$G,2,FALSE) -> Ricky Edson Lux Cassia | O6: =IFERROR(IF(A6="SI",VLOOKUP(R6,Datos!$J$1:$K$50,2,FALSE)*C6,VLOOKUP(R6,Datos!$P$1:$T$13,2,FALSE)*C6),0) -> 816 | P6: 303674 | Q6: =+VLOOKUP(P6,Datos!$F:$G,2,FALSE) -> Imelda Elizabeth Castro Rodas | R6: VIDA+SEGURO | V6: =+COUNTIFS($G$2:$G$444,G6) -> 1 | W6: =+VLOOKUP(M6,Datos!$F:$H,3,FALSE) -> 0 | X6: 0 | Z6: =VLOOKUP(M6,'[1]INDIVIDUAL UN'!$C$6:$F$222,4,FALSE) -> #N/A
A7: SI | C7: 1 | D7: NUEVO | E7: VCB-20210003 | F7: 4178 | G7: MARIA TERESA BOCEL TECUN | H7: 46266 | I7: 46266 | J7: =+VLOOKUP(K7,Datos!$A:$C,3,FALSE) -> OCCIDENTE | K7: 126 | L7: =+VLOOKUP(K7,Datos!$A:$C,2,FALSE) -> CHICHICASTENANGO | M7: 309989 | N7: =+VLOOKUP(M7,Datos!$F:$G,2,FALSE) -> Olga Maricela Guarcas Tol | O7: =IFERROR(IF(A7="SI",VLOOKUP(R7,Datos!$J$1:$K$50,2,FALSE)*C7,VLOOKUP(R7,Datos!$P$1:$T$13,2,FALSE)*C7),0) -> 816 | P7: 303674 | Q7: =+VLOOKUP(P7,Datos!$F:$G,2,FALSE) -> Imelda Elizabeth Castro Rodas | R7: VIDA+SEGURO | V7: =+COUNTIFS($G$2:$G$444,G7) -> 1 | W7: =+VLOOKUP(M7,Datos!$F:$H,3,FALSE) -> 0 | X7: 0 | Z7: =VLOOKUP(M7,'[1]INDIVIDUAL UN'!$C$6:$F$222,4,FALSE) -> #N/A
A8: SI | C8: 2 | D8: NUEVO | E8: VCB-20220010 | F8: 1093 | G8: MARIA ESPERANZA CANEL DIAZ | H8: 46266 | I8: 46266 | J8: =+VLOOKUP(K8,Datos!$A:$C,3,FALSE) -> SUROCCIDENTE | K8: 297 | L8: =+VLOOKUP(K8,Datos!$A:$C,2,FALSE) -> LA TRINIDAD COATEPEQUE | M8: 306248 | N8: =+VLOOKUP(M8,Datos!$F:$G,2,FALSE) -> Gladys Susana Marin De Leon | O8: =IFERROR(IF(A8="SI",VLOOKUP(R8,Datos!$J$1:$K$50,2,FALSE)*C8,VLOOKUP(R8,Datos!$P$1:$T$13,2,FALSE)*C8),0) -> 1632 | P8: 311975 | Q8: =+VLOOKUP(P8,Datos!$F:$G,2,FALSE) -> Luis Eduardo Ramirez Arriaza | R8: VIDA+SEGURO | V8: =+COUNTIFS($G$2:$G$444,G8) -> 1 | W8: =+VLOOKUP(M8,Datos!$F:$H,3,FALSE) -> 0 | X8: 0 | Z8: =VLOOKUP(M8,'[1]INDIVIDUAL UN'!$C$6:$F$222,4,FALSE) -> #N/A
A9: SI | C9: 3 | D9: NUEVO | E9: VCB-20220034 | F9: 600 | G9: JULIO ROBERTO CAJAS HERNANDEZ | H9: 46267 | I9: 46267 | J9: =+VLOOKUP(K9,Datos!$A:$C,3,FALSE) -> OCCIDENTE | K9: 56 | L9: =+VLOOKUP(K9,Datos!$A:$C,2,FALSE) -> LOS ALTOS | M9: 90040102 | N9: =+VLOOKUP(M9,Datos!$F:$G,2,FALSE) -> KAREN JASMIN PEREZ CORONADO | O9: =IFERROR(IF(A9="SI",VLOOKUP(R9,Datos!$J$1:$K$50,2,FALSE)*C9,VLOOKUP(R9,Datos!$P$1:$T$13,2,FALSE)*C9),0) -> 2448 | P9: 308266 | Q9: =+VLOOKUP(P9,Datos!$F:$G,2,FALSE) -> Julio Cesar De Leon Huinac | R9: VIDA+SEGURO | V9: =+COUNTIFS($G$2:$G$444,G9) -> 1 | W9: =+VLOOKUP(M9,Datos!$F:$H,3,FALSE) -> 0 | X9: 0 | Z9: =VLOOKUP(M9,'[1]INDIVIDUAL UN'!$C$6:$F$222,4,FALSE) -> #N/A
A10: SI | C10: 1 | D10: NUEVO | E10: ACPE-20210019 | F10: 2898 | G10: ISIAIAS OTONIEL LOPEZ SOTO | H10: 46267 | I10: 46266 | J10: =+VLOOKUP(K10,Datos!$A:$C,3,FALSE) -> SUROCCIDENTE | K10: 178 | L10: =+VLOOKUP(K10,Datos!$A:$C,2,FALSE) -> LA TRINIDAD MALACATAN | M10: 90019118 | N10: =+VLOOKUP(M10,Datos!$F:$G,2,FALSE) -> Angela Josefina Ramírez Chang | O10: =IFERROR(IF(A10="SI",VLOOKUP(R10,Datos!$J$1:$K$50,2,FALSE)*C10,VLOOKUP(R10,Datos!$P$1:$T$13,2,FALSE)*C10),0) -> 1308 | P10: 304805 | Q10: =+VLOOKUP(P10,Datos!$F:$G,2,FALSE) -> Sheily Raquel Angel Arreaga | R10: AP DENTAL INDIVIDUAL | V10: =+COUNTIFS($G$2:$G$444,G10) -> 1 | W10: =+VLOOKUP(M10,Datos!$F:$H,3,FALSE) -> 0 | X10: 0 | Z10: =VLOOKUP(M10,'[1]INDIVIDUAL UN'!$C$6:$F$222,4,FALSE) -> #N/A
A11: SI | C11: 2 | D11: NUEVO | E11: VCB-20220010 | F11: 1100 | G11: ENMA MISHELLE LOPEZ LOPEZ | H11: 46267 | I11: 46267 | J11: =+VLOOKUP(K11,Datos!$A:$C,3,FALSE) -> SUROCCIDENTE | K11: 178 | L11: =+VLOOKUP(K11,Datos!$A:$C,2,FALSE) -> LA TRINIDAD MALACATAN | M11: 90019118 | N11: =+VLOOKUP(M11,Datos!$F:$G,2,FALSE) -> Angela Josefina Ramírez Chang | O11: =IFERROR(IF(A11="SI",VLOOKUP(R11,Datos!$J$1:$K$50,2,FALSE)*C11,VLOOKUP(R11,Datos!$P$1:$T$13,2,FALSE)*C11),0) -> 1632 | P11: 304805 | Q11: =+VLOOKUP(P11,Datos!$F:$G,2,FALSE) -> Sheily Raquel Angel Arreaga | R11: VIDA+SEGURO | V11: =+COUNTIFS($G$2:$G$444,G11) -> 1 | W11: =+VLOOKUP(M11,Datos!$F:$H,3,FALSE) -> 0 | X11: 0 | Z11: =VLOOKUP(M11,'[1]INDIVIDUAL UN'!$C$6:$F$222,4,FALSE) -> #N/A
A12: SI | C12: 2 | D12: NUEVO | E12: VCB-20220010 | F12: 1114 | G12: JUAN JOSE RAMOS GOMEZ | H12: 46267 | I12: 46267 | J12: =+VLOOKUP(K12,Datos!$A:$C,3,FALSE) -> SUROCCIDENTE | K12: 178 | L12: =+VLOOKUP(K12,Datos!$A:$C,2,FALSE) -> LA TRINIDAD MALACATAN | M12: 316215 | N12: =+VLOOKUP(M12,Datos!$F:$G,2,FALSE) -> ANAYELI MARIBEL JIMENEZ GOMEZ | O12: =IFERROR(IF(A12="SI",VLOOKUP(R12,Datos!$J$1:$K$50,2,FALSE)*C12,VLOOKUP(R12,Datos!$P$1:$T$13,2,FALSE)*C12),0) -> 2736 | P12: 316487 | Q12: =+VLOOKUP(P12,Datos!$F:$G,2,FALSE) -> Wilmer Ovando Mejia Godínez | R12: VIDA+SEGURO PLAN 1 | V12: =+COUNTIFS($G$2:$G$444,G12) -> 1 | W12: =+VLOOKUP(M12,Datos!$F:$H,3,FALSE) -> 0 | X12: 0 | Z12: =VLOOKUP(M12,'[1]INDIVIDUAL UN'!$C$6:$F$222,4,FALSE) -> #N/A
A13: SI | C13: 1 | D13: NUEVO | E13: VCB-20210003 | F13: 4192 | G13: OSBALDO DAVID SAMAYOA RODRIGUEZ | H13: 46267 | I13: 46267 | J13: =+VLOOKUP(K13,Datos!$A:$C,3,FALSE) -> OCCIDENTE | K13: 55 | L13: =+VLOOKUP(K13,Datos!$A:$C,2,FALSE) -> ZENTROPLAZA | M13: 313671 | N13: =+VLOOKUP(M13,Datos!$F:$G,2,FALSE) -> Virginia Yesenia Merida Lopez De Lopez | O13: =IFERROR(IF(A13="SI",VLOOKUP(R13,Datos!$J$1:$K$50,2,FALSE)*C13,VLOOKUP(R13,Datos!$P$1:$T$13,2,FALSE)*C13),0) -> 1368 | P13: 311950 | Q13: =+VLOOKUP(P13,Datos!$F:$G,2,FALSE) -> Alan Javier Castillo Ordoñez | R13: VIDA+SEGURO PLAN 1 | V13: =+COUNTIFS($G$2:$G$444,G13) -> 1 | W13: =+VLOOKUP(M13,Datos!$F:$H,3,FALSE) -> 0 | X13: 0 | Z13: =VLOOKUP(M13,'[1]INDIVIDUAL UN'!$C$6:$F$222,4,FALSE) -> #N/A
... A22: SI | C22: 1 | D22: NUEVO | E22: VCB-20210003 | F22: 4203 | G22: MATILDE TOMAS PEDRO | H22: 46267 | I22: 46267 | J22: =+VLOOKUP(K22,Datos!$A:$C,3,FALSE) -> OCCIDENTE | K22: 246 | L22: =+VLOOKUP(K22,Datos!$A:$C,2,FALSE) -> SANTA CRUZ BARILLAS | M22: 313666 | N22: =+VLOOKUP(M22,Datos!$F:$G,2,FALSE) -> Avner Josue Merida Molina | O22: =IFERROR(IF(A22="SI",VLOOKUP(R22,Datos!$J$1:$K$50,2,FALSE)*C22,VLOOKUP(R22,Datos!$P$1:$T$13,2,FALSE)*C22),0) -> 1368 | P22: 304166 | Q22: =+VLOOKUP(P22,Datos!$F:$G,2,FALSE) -> Maviela Bibianeth Castillo Avila | R22: VIDA+SEGURO PLAN 1 | V22: =+COUNTIFS($G$2:$G$444,G22) -> 1 | W22: =+VLOOKUP(M22,Datos!$F:$H,3,FALSE) -> 0 | X22: 0 | Z22: =VLOOKUP(M22,'[1]INDIVIDUAL UN'!$C$6:$F$222,4,FALSE) -> #N/A
A23: SI | C23: 1 | D23: NUEVO | E23: VCB-20210003 | F23: 4185 | G23: CECILIA MARISOL SALES | H23: 46267 | I23: 46267 | J23: =+VLOOKUP(K23,Datos!$A:$C,3,FALSE) -> SUROCCIDENTE | K23: 31 | L23: =+VLOOKUP(K23,Datos!$A:$C,2,FALSE) -> COATEPEQUE | M23: 90065999 | N23: =+VLOOKUP(M23,Datos!$F:$G,2,FALSE) -> SEPHORA ABIGAIL SANCHEZ HERDOCIA | O23: =IFERROR(IF(A23="SI",VLOOKUP(R23,Datos!$J$1:$K$50,2,FALSE)*C23,VLOOKUP(R23,Datos!$P$1:$T$13,2,FALSE)*C23),0) -> 1368 | P23: 311258 | Q23: =+VLOOKUP(P23,Datos!$F:$G,2,FALSE) -> Victor Otoniel Sebastian Cardona | R23: VIDA+SEGURO PLAN 1 | V23: =+COUNTIFS($G$2:$G$444,G23) -> 1 | W23: =+VLOOKUP(M23,Datos!$F:$H,3,FALSE) -> 0 | X23: 0 | Z23: =VLOOKUP('[2]DICIEMBREE 2024'!M51,'[1]INDIVIDUAL UN'!$C$6:$F$222,4,FALSE) -> #N/A
A24: SI | C24: 1 | D24: NUEVO | E24: VCB-20210003 | F24: 4194 | G24: HENRRI AVILA SANTIZO | H24: 46267 | I24: 46267 | J24: =+VLOOKUP(K24,Datos!$A:$C,3,FALSE) -> SUROCCIDENTE | K24: 297 | L24: =+VLOOKUP(K24,Datos!$A:$C,2,FALSE) -> LA TRINIDAD COATEPEQUE | M24: 312831 | N24: =+VLOOKUP(M24,Datos!$F:$G,2,FALSE) -> Cindy Yojana Mendoza Cajas | O24: =IFERROR(IF(A24="SI",VLOOKUP(R24,Datos!$J$1:$K$50,2,FALSE)*C24,VLOOKUP(R24,Datos!$P$1:$T$13,2,FALSE)*C24),0) -> 816 | P24: 311975 | Q24: =+VLOOKUP(P24,Datos!$F:$G,2,FALSE) -> Luis Eduardo Ramirez Arriaza | R24: VIDA+SEGURO | V24: =+COUNTIFS($G$2:$G$444,G24) -> 1 | W24: =+VLOOKUP(M24,Datos!$F:$H,3,FALSE) -> 0 | X24: 0 | Z24: =VLOOKUP(M24,'[1]INDIVIDUAL UN'!$C$6:$F$222,4,FALSE) -> #N/A
A25: SI | C25: 1 | D25: NUEVO | E25: VCB 20220009 | F25: 4193 | G25: BAYRON NATTANAEL LOPEZ BARAN | H25: 46267 | I25: 46267 | J25: =+VLOOKUP(K25,Datos!$A:$C,3,FALSE) -> OCCIDENTE | K25: 28 | L25: =+VLOOKUP(K25,Datos!$A:$C,2,FALSE) -> SUCURSAL QUETZALTENANGO | M25: 304024 | N25: =+VLOOKUP(M25,Datos!$F:$G,2,FALSE) -> Vicky Roxana Lopez Hernandez | O25: =IFERROR(IF(A25="SI",VLOOKUP(R25,Datos!$J$1:$K$50,2,FALSE)*C25,VLOOKUP(R25,Datos!$P$1:$T$13,2,FALSE)*C25),0) -> 816 | P25: 313644 | Q25: =+VLOOKUP(P25,Datos!$F:$G,2,FALSE) -> Estefani Elizabeth Tzul Macario | R25: VIDA+SEGURO | V25: =+COUNTIFS($G$2:$G$444,G25) -> 1 | W25: =+VLOOKUP(M25,Datos!$F:$H,3,FALSE) -> 0 | X25: 0 | Z25: =VLOOKUP(M25,'[1]INDIVIDUAL UN'!$C$6:$F$222,4,FALSE) -> #N/A
A26: SI | C26: 1 | D26: NUEVO | E26: VCB 20210003 | F26: 4182 | G26: SAMUEL SOLIS MORALES | H26: 46267 | I26: 46267 | J26: =+VLOOKUP(K26,Datos!$A:$C,3,FALSE) -> OCCIDENTE | K26: 56 | L26: =+VLOOKUP(K26,Datos!$A:$C,2,FALSE) -> LOS ALTOS | M26: 315133 | N26: =+VLOOKUP(M26,Datos!$F:$G,2,FALSE) -> Bryan Daniel Milián De Leon | O26: =IFERROR(IF(A26="SI",VLOOKUP(R26,Datos!$J$1:$K$50,2,FALSE)*C26,VLOOKUP(R26,Datos!$P$1:$T$13,2,FALSE)*C26),0) -> 816 | P26: 308266 | Q26: =+VLOOKUP(P26,Datos!$F:$G,2,FALSE) -> Julio Cesar De Leon Huinac | R26: VIDA+SEGURO | V26: =+COUNTIFS($G$2:$G$444,G26) -> 1 | W26: =+VLOOKUP(M26,Datos!$F:$H,3,FALSE) -> 0 | X26: 0 | Z26: =VLOOKUP(M26,'[1]INDIVIDUAL UN'!$C$6:$F$222,4,FALSE) -> #N/A
A27: SI | C27: 2 | D27: NUEVO | E27: VCB-20220010 | F27: 1126 | G27: YOSELIN YESSENIA ALVAREZ PEREZ | H27: 46268 | I27: 46268 | J27: =+VLOOKUP(K27,Datos!$A:$C,3,FALSE) -> SUROCCIDENTE | K27: 89 | L27: =+VLOOKUP(K27,Datos!$A:$C,2,FALSE) -> LA TRINIDAD RETALHULEU | M27: 90064210 | N27: =+VLOOKUP(M27,Datos!$F:$G,2,FALSE) -> GEREMY ARMANDO HERNANDEZ CAMACHO | O27: =IFERROR(IF(A27="SI",VLOOKUP(R27,Datos!$J$1:$K$50,2,FALSE)*C27,VLOOKUP(R27,Datos!$P$1:$T$13,2,FALSE)*C27),0) -> 1632 | P27: 302841 | Q27: =+VLOOKUP(P27,Datos!$F:$G,2,FALSE) -> Jessica Maria Jose Santizo Guzman | R27: VIDA+SEGURO | V27: =+COUNTIFS($G$2:$G$444,G27) -> 1 | W27: =+VLOOKUP(M27,Datos!$F:$H,3,FALSE) -> 0 | X27: 0 | Z27: =VLOOKUP(M27,'[1]INDIVIDUAL UN'!$C$6:$F$222,4,FALSE) -> #N/A
A28: SI | C28: 3 | D28: NUEVO | E28: VCB-20220034 | F28: 602 | G28: ROSA ESPERANZA SIPAC CHIRIX | H28: 46268 | I28: 46268 | J28: =+VLOOKUP(K28,Datos!$A:$C,3,FALSE) -> OCCIDENTE | K28: 155 | L28: =+VLOOKUP(K28,Datos!$A:$C,2,FALSE) -> TECPAN | M28: 315629 | N28: =+VLOOKUP(M28,Datos!$F:$G,2,FALSE) -> Rucuch Choguaj, Miguel | O28: =IFERROR(IF(A28="SI",VLOOKUP(R28,Datos!$J$1:$K$50,2,FALSE)*C28,VLOOKUP(R28,Datos!$P$1:$T$13,2,FALSE)*C28),0) -> 2448 | P28: 305955 | Q28: =+VLOOKUP(P28,Datos!$F:$G,2,FALSE) -> Jorge Alfredo Gutierrez Rodriguez | R28: VIDA+SEGURO | V28: =+COUNTIFS($G$2:$G$444,G28) -> 1 | W28: =+VLOOKUP(M28,Datos!$F:$H,3,FALSE) -> 0 | X28: 0 | Z28: =VLOOKUP(M28,'[1]INDIVIDUAL UN'!$C$6:$F$222,4,FALSE) -> #N/A
A29: SI | C29: 1 | D29: NUEVO | E29: VCB-20210003 | F29: 4216 | G29: HENRY FERNANDO LOPEZ PASCUAL | H29: 46268 | I29: 03/29/2026 | J29: =+VLOOKUP(K29,Datos!$A:$C,3,FALSE) -> SUROCCIDENTE | K29: 31 | L29: =+VLOOKUP(K29,Datos!$A:$C,2,FALSE) -> COATEPEQUE | M29: 310671 | N29: =+VLOOKUP(M29,Datos!$F:$G,2,FALSE) -> Sucely Paola Godinez Gomez De Perez | O29: =IFERROR(IF(A29="SI",VLOOKUP(R29,Datos!$J$1:$K$50,2,FALSE)*C29,VLOOKUP(R29,Datos!$P$1:$T$13,2,FALSE)*C29),0) -> 1368 | P29: 306654 | Q29: =+VLOOKUP(P29,Datos!$F:$G,2,FALSE) -> Gerson Arcadio Hernandez Barrios | R29: VIDA+SEGURO PLAN 1 | V29: =+COUNTIFS($G$2:$G$444,G29) -> 1 | W29: =+VLOOKUP(M29,Datos!$F:$H,3,FALSE) -> 0 | X29: 0 | Z29: =VLOOKUP(M29,'[1]INDIVIDUAL UN'!$C$6:$F$222,4,FALSE) -> #N/A
A30: SI | C30: 1 | D30: NUEVO | E30: VCB-20210015 | F30: 407 | G30: BONIFILIO GUDIEL HUINIL CHAY | H30: 46268 | I30: 46268 | J30: =+VLOOKUP(K30,Datos!$A:$C,3,FALSE) -> SUROCCIDENTE | K30: 31 | L30: =+VLOOKUP(K30,Datos!$A:$C,2,FALSE) -> COATEPEQUE | M30: 315679 | N30: =+VLOOKUP(M30,Datos!$F:$G,2,FALSE) -> ANGELA XIOMARA PONCIANO GONZALEZ | O30: =IFERROR(IF(A30="SI",VLOOKUP(R30,Datos!$J$1:$K$50,2,FALSE)*C30,VLOOKUP(R30,Datos!$P$1:$T$13,2,FALSE)*C30),0) -> 1092 | P30: 311258 | Q30: =+VLOOKUP(P30,Datos!$F:$G,2,FALSE) -> Victor Otoniel Sebastian Cardona | R30: PREVENCION+SEGURA | V30: =+COUNTIFS($G$2:$G$444,G30) -> 1 | W30: =+VLOOKUP(M30,Datos!$F:$H,3,FALSE) -> 0 | X30: 0 | Z30: =VLOOKUP(M30,'[1]INDIVIDUAL UN'!$C$6:$F$222,4,FALSE) -> #N/A
A31: SI | C31: 1 | D31: NUEVO | E31: VCB-20210003 | F31: 4243 | G31: MARVIN ESTUARDO RIOS AGUSTIN | H31: 46268 | I31: 46268 | J31: =+VLOOKUP(K31,Datos!$A:$C,3,FALSE) -> OCCIDENTE | K31: 55 | L31: =+VLOOKUP(K31,Datos!$A:$C,2,FALSE) -> ZENTROPLAZA | M31: 315686 | N31: =+VLOOKUP(M31,Datos!$F:$G,2,FALSE) -> REINA NOHEMI PASCUAL | O31: =IFERROR(IF(A31="SI",VLOOKUP(R31,Datos!$J$1:$K$50,2,FALSE)*C31,VLOOKUP(R31,Datos!$P$1:$T$13,2,FALSE)*C31),0) -> 816 | P31: 311950 | Q31: =+VLOOKUP(P31,Datos!$F:$G,2,FALSE) -> Alan Javier Castillo Ordoñez | R31: VIDA+SEGURO | V31: =+COUNTIFS($G$2:$G$444,G31) -> 1 | W31: =+VLOOKUP(M31,Datos!$F:$H,3,FALSE) -> 0 | X31: 0 | Z31: =VLOOKUP(M31,'[1]INDIVIDUAL UN'!$C$6:$F$222,4,FALSE) -> #N/A
A32: SI | C32: 2 | D32: NUEVO | E32: VCB- 20220022 | F32: 133 | G32: JERONIMO ROSALES LOPEZ | H32: 46268 | I32: 46268 | J32: =+VLOOKUP(K32,Datos!$A:$C,3,FALSE) -> SUROCCIDENTE | K32: 297 | L32: =+VLOOKUP(K32,Datos!$A:$C,2,FALSE) -> LA TRINIDAD COATEPEQUE | M32: 306248 | N32: =+VLOOKUP(M32,Datos!$F:$G,2,FALSE) -> Gladys Susana Marin De Leon | O32: =IFERROR(IF(A32="SI",VLOOKUP(R32,Datos!$J$1:$K$50,2,FALSE)*C32,VLOOKUP(R32,Datos!$P$1:$T$13,2,FALSE)*C32),0) -> 2184 | P32: 311975 | Q32: =+VLOOKUP(P32,Datos!$F:$G,2,FALSE) -> Luis Eduardo Ramirez Arriaza | R32: PREVENCION+SEGURA | V32: =+COUNTIFS($G$2:$G$444,G32) -> 1 | W32: =+VLOOKUP(M32,Datos!$F:$H,3,FALSE) -> 0 | X32: 0 | Z32: =VLOOKUP(M32,'[1]INDIVIDUAL UN'!$C$6:$F$222,4,FALSE) -> #N/A
A33: SI | C33: 1 | D33: NUEVO | E33: VCB-20210003 | F33: 4229 | G33: TOMAS DOMINGO ZACARIAS DOMINGO | H33: 46268 | I33: 46268 | J33: =+VLOOKUP(K33,Datos!$A:$C,3,FALSE) -> OCCIDENTE | K33: 33 | L33: =+VLOOKUP(K33,Datos!$A:$C,2,FALSE) -> HUEHUETENANGO | M33: 314636 | N33: =+VLOOKUP(M33,Datos!$F:$G,2,FALSE) -> Walkiria Anais Herrera Castillo | O33: =IFERROR(IF(A33="SI",VLOOKUP(R33,Datos!$J$1:$K$50,2,FALSE)*C33,VLOOKUP(R33,Datos!$P$1:$T$13,2,FALSE)*C33),0) -> 1368 | P33: 313225 | Q33: =+VLOOKUP(P33,Datos!$F:$G,2,FALSE) -> Karen Deniss Lucas Chavez | R33: VIDA+SEGURO PLAN 1 | V33: =+COUNTIFS($G$2:$G$444,G33) -> 1 | W33: =+VLOOKUP(M33,Datos!$F:$H,3,FALSE) -> 0 | X33: 0 | Z33: =VLOOKUP(M33,'[1]INDIVIDUAL UN'!$C$6:$F$222,4,FALSE) -> #N/A
A34: SI | C34: 2 | D34: NUEVO | E34: VCB-20220010 | F34: 1115 | G34: LIDIA ESPERANZA REYES CIFUENTES | H34: 46268 | I34: 46267 | J34: =+VLOOKUP(K34,Datos!$A:$C,3,FALSE) -> SUROCCIDENTE | K34: 297 | L34: =+VLOOKUP(K34,Datos!$A:$C,2,FALSE) -> LA TRINIDAD COATEPEQUE | M34: 310220 | N34: =+VLOOKUP(M34,Datos!$F:$G,2,FALSE) -> Urias Samuel Velasquez Ardeano | O34: =IFERROR(IF(A34="SI",VLOOKUP(R34,Datos!$J$1:$K$50,2,FALSE)*C34,VLOOKUP(R34,Datos!$P$1:$T$13,2,FALSE)*C34),0) -> 1632 | P34: 311975 | Q34: =+VLOOKUP(P34,Datos!$F:$G,2,FALSE) -> Luis Eduardo Ramirez Arriaza | R34: VIDA+SEGURO | V34: =+COUNTIFS($G$2:$G$444,G34) -> 1 | W34: =+VLOOKUP(M34,Datos!$F:$H,3,FALSE) -> 0 | X34: 0 | Z34: =VLOOKUP(M34,'[1]INDIVIDUAL UN'!$C$6:$F$222,4,FALSE) -> #N/A
A35: SI | C35: 1 | D35: NUEVO | E35: VCB-20210003 | F35: 4233 | G35: RONI MARCOTULIO MIRANDA ORTEGA | H35: 46268 | I35: 46268 | J35: =+VLOOKUP(K35,Datos!$A:$C,3,FALSE) -> SUROCCIDENTE | K35: 297 | L35: =+VLOOKUP(K35,Datos!$A:$C,2,FALSE) -> LA TRINIDAD COATEPEQUE | M35: 310220 | N35: =+VLOOKUP(M35,Datos!$F:$G,2,FALSE) -> Urias Samuel Velasquez Ardeano | O35: =IFERROR(IF(A35="SI",VLOOKUP(R35,Datos!$J$1:$K$50,2,FALSE)*C35,VLOOKUP(R35,Datos!$P$1:$T$13,2,FALSE)*C35),0) -> 816 | P35: 311975 | Q35: =+VLOOKUP(P35,Datos!$F:$G,2,FALSE) -> Luis Eduardo Ramirez Arriaza | R35: VIDA+SEGURO | V35: =+COUNTIFS($G$2:$G$444,G35) -> 1 | W35: =+VLOOKUP(M35,Datos!$F:$H,3,FALSE) -> 0 | X35: 0 | Z35: =VLOOKUP(M35,'[1]INDIVIDUAL UN'!$C$6:$F$222,4,FALSE) -> #N/A
A36: SI | C36: 1 | D36: NUEVO | E36: VCB-20210003 | F36: 4221 | G36: JOSE LUIS CHOCHOM LOPEZ | H36: 46268 | I36: 46268 | J36: =+VLOOKUP(K36,Datos!$A:$C,3,FALSE) -> SUROCCIDENTE | K36: 143 | L36: =+VLOOKUP(K36,Datos!$A:$C,2,FALSE) -> RETALHULEU LA SIRENA | M36: 90087842 | N36: =+VLOOKUP(M36,Datos!$F:$G,2,FALSE) -> ANGEL DAVID BAMAC ORELLANA | O36: =IFERROR(IF(A36="SI",VLOOKUP(R36,Datos!$J$1:$K$50,2,FALSE)*C36,VLOOKUP(R36,Datos!$P$1:$T$13,2,FALSE)*C36),0) -> 816 | P36: 311380 | Q36: =+VLOOKUP(P36,Datos!$F:$G,2,FALSE) -> Andrea Lisbeth Ruiz Rodas | R36: VIDA+SEGURO | V36: =+COUNTIFS($G$2:$G$444,G36) -> 1 | W36: =+VLOOKUP(M36,Datos!$F:$H,3,FALSE) -> 0 | X36: 0 | Z36: =VLOOKUP(M36,'[1]INDIVIDUAL UN'!$C$6:$F$222,4,FALSE) -> #N/A
A37: SI | C37: 3 | D37: NUEVO | E37: VCB-20220034 | F37: 601 | G37: GIOVANA MARIANA MAZARIEGOS SERRANO | H37: 46268 | I37: 46268 | J37: =+VLOOKUP(K37,Datos!$A:$C,3,FALSE) -> OCCIDENTE | K37: 65 | L37: =+VLOOKUP(K37,Datos!$A:$C,2,FALSE) -> PANAJACHEL | M37: 312996 | N37: =+VLOOKUP(M37,Datos!$F:$G,2,FALSE) -> Marlen Aida Pelaez Ramirez | O37: =IFERROR(IF(A37="SI",VLOOKUP(R37,Datos!$J$1:$K$50,2,FALSE)*C37,VLOOKUP(R37,Datos!$P$1:$T$13,2,FALSE)*C37),0) -> 4104 | P37: 305532 | Q37: =+VLOOKUP(P37,Datos!$F:$G,2,FALSE) -> Nicolas Ajiquichi Ibate | R37: VIDA+SEGURO PLAN 1 | V37: =+COUNTIFS($G$2:$G$444,G37) -> 1 | W37: =+VLOOKUP(M37,Datos!$F:$H,3,FALSE) -> 0 | X37: 0 | Z37: =VLOOKUP(M37,'[1]INDIVIDUAL UN'!$C$6:$F$222,4,FALSE) -> #N/A
A38: SI | C38: 1 | D38: NUEVO | E38: VCB-20210003 | F38: 4217 | G38: ALMA PATRICIA GIRON REYES | H38: 46268 | I38: 46268 | J38: =+VLOOKUP(K38,Datos!$A:$C,3,FALSE) -> SUROCCIDENTE | K38: 297 | L38: =+VLOOKUP(K38,Datos!$A:$C,2,FALSE) -> LA TRINIDAD COATEPEQUE | M38: 312831 | N38: =+VLOOKUP(M38,Datos!$F:$G,2,FALSE) -> Cindy Yojana Mendoza Cajas | O38: =IFERROR(IF(A38="SI",VLOOKUP(R38,Datos!$J$1:$K$50,2,FALSE)*C38,VLOOKUP(R38,Datos!$P$1:$T$13,2,FALSE)*C38),0) -> 816 | P38: 311975 | Q38: =+VLOOKUP(P38,Datos!$F:$G,2,FALSE) -> Luis Eduardo Ramirez Arriaza | R38: VIDA+SEGURO | V38: =+COUNTIFS($G$2:$G$444,G38) -> 1 | W38: =+VLOOKUP(M38,Datos!$F:$H,3,FALSE) -> 0 | X38: 0 | Z38: =VLOOKUP(M38,'[1]INDIVIDUAL UN'!$C$6:$F$222,4,FALSE) -> #N/A
A39: SI | C39: 3 | D39: NUEVO | E39: VCB-20220034 | F39: 603 | G39: KAREN MELISA PEREZ CAN | H39: 46269 | I39: 46269 | J39: =+VLOOKUP(K39,Datos!$A:$C,3,FALSE) -> OCCIDENTE | K39: 155 | L39: =+VLOOKUP(K39,Datos!$A:$C,2,FALSE) -> TECPAN | M39: 315629 | N39: =+VLOOKUP(M39,Datos!$F:$G,2,FALSE) -> Rucuch Choguaj, Miguel | O39: =IFERROR(IF(A39="SI",VLOOKUP(R39,Datos!$J$1:$K$50,2,FALSE)*C39,VLOOKUP(R39,Datos!$P$1:$T$13,2,FALSE)*C39),0) -> 2448 | P39: 305955 | Q39: =+VLOOKUP(P39,Datos!$F:$G,2,FALSE) -> Jorge Alfredo Gutierrez Rodriguez | R39: VIDA+SEGURO | V39: =+COUNTIFS($G$2:$G$444,G39) -> 1 | W39: =+VLOOKUP(M39,Datos!$F:$H,3,FALSE) -> 0 | X39: 0 | Z39: =VLOOKUP(M39,'[1]INDIVIDUAL UN'!$C$6:$F$222,4,FALSE) -> #N/A
A40: SI | C40: 2 | D40: NUEVO | E40: VCB-20220010 | F40: 1133 | G40: DAVID ESTEBAN MENDOZA DOMINGUEZ | H40: 46269 | I40: 46269 | J40: =+VLOOKUP(K40,Datos!$A:$C,3,FALSE) -> OCCIDENTE | K40: 29 | L40: =+VLOOKUP(K40,Datos!$A:$C,2,FALSE) -> SAN PEDRO SACATEPEQUEZ S.M. | M40: 90027919 | N40: =+VLOOKUP(M40,Datos!$F:$G,2,FALSE) -> OFNY JOSELITO FUENTES | O40: =IFERROR(IF(A40="SI",VLOOKUP(R40,Datos!$J$1:$K$50,2,FALSE)*C40,VLOOKUP(R40,Datos!$P$1:$T$13,2,FALSE)*C40),0) -> 1632 | P40: 310641 | Q40: =+VLOOKUP(P40,Datos!$F:$G,2,FALSE) -> Jorge Antonio Ramirez Sicay | R40: VIDA+SEGURO | V40: =+COUNTIFS($G$2:$G$444,G40) -> 1 | W40: =+VLOOKUP(M40,Datos!$F:$H,3,FALSE) -> 0 | X40: 0 | Z40: =VLOOKUP(M40,'[1]INDIVIDUAL UN'!$C$6:$F$222,4,FALSE) -> #N/A
A41: SI | C41: 1 | D41: NUEVO | E41: APSS-20200009 | F41: 2944 | G41: FILIBERTO LOPEZ BUC | H41: 46269 | I41: 46269 | J41: =+VLOOKUP(K41,Datos!$A:$C,3,FALSE) -> OCCIDENTE | K41: 65 | L41: =+VLOOKUP(K41,Datos!$A:$C,2,FALSE) -> PANAJACHEL | M41: 312996 | N41: =+VLOOKUP(M41,Datos!$F:$G,2,FALSE) -> Marlen Aida Pelaez Ramirez | O41: =IFERROR(IF(A41="SI",VLOOKUP(R41,Datos!$J$1:$K$50,2,FALSE)*C41,VLOOKUP(R41,Datos!$P$1:$T$13,2,FALSE)*C41),0) -> 1908 | P41: 305532 | Q41: =+VLOOKUP(P41,Datos!$F:$G,2,FALSE) -> Nicolas Ajiquichi Ibate | R41: CONSULTA BASICO + BIENESTAR | V41: =+COUNTIFS($G$2:$G$444,G41) -> 1 | W41: =+VLOOKUP(M41,Datos!$F:$H,3,FALSE) -> 0 | X41: 0 | Z41: =VLOOKUP(M41,'[1]INDIVIDUAL UN'!$C$6:$F$222,4,FALSE) -> #N/A
... A44: SI | C44: 1 | D44: NUEVO | E44: APSS20200009 | F44: 2945 | G44: EFRAIN MANUEL JIMENEZ MENDEZ | H44: 46269 | I44: 46269 | J44: =+VLOOKUP(K44,Datos!$A:$C,3,FALSE) -> OCCIDENTE | K44: 33 | L44: =+VLOOKUP(K44,Datos!$A:$C,2,FALSE) -> HUEHUETENANGO | M44: 90084483 | N44: =+VLOOKUP(M44,Datos!$F:$G,2,FALSE) -> ASTRID MILETCHA RAYMUNDO HIDALGO | O44: =IFERROR(IF(A44="SI",VLOOKUP(R44,Datos!$J$1:$K$50,2,FALSE)*C44,VLOOKUP(R44,Datos!$P$1:$T$13,2,FALSE)*C44),0) -> 2004 | P44: 301644 | Q44: =+VLOOKUP(P44,Datos!$F:$G,2,FALSE) -> Imelda Eugenia Recinos Martinez | R44: CONSULTA COMPLETO | V44: =+COUNTIFS($G$2:$G$444,G44) -> 1 | W44: =+VLOOKUP(M44,Datos!$F:$H,3,FALSE) -> 0 | X44: 0 | Z44: =VLOOKUP(M44,'[1]INDIVIDUAL UN'!$C$6:$F$222,4,FALSE) -> #N/A
A45: SI | C45: 4 | D45: NUEVO | E45: VCB-20240008 | F45: 647 | G45: JUANA SANTIAGO PANJOJ SALVADOR | H45: 46269 | I45: 46269 | J45: =+VLOOKUP(K45,Datos!$A:$C,3,FALSE) -> OCCIDENTE | K45: 126 | L45: =+VLOOKUP(K45,Datos!$A:$C,2,FALSE) -> CHICHICASTENANGO | M45: 90040633 | N45: =+VLOOKUP(M45,Datos!$F:$G,2,FALSE) -> MANUELA LUCRECIA SALVADOR SICAL | O45: =IFERROR(IF(A45="SI",VLOOKUP(R45,Datos!$J$1:$K$50,2,FALSE)*C45,VLOOKUP(R45,Datos!$P$1:$T$13,2,FALSE)*C45),0) -> 3264 | P45: 306497 | Q45: =+VLOOKUP(P45,Datos!$F:$G,2,FALSE) -> Erika Ixtan Canil | R45: VIDA+SEGURO | V45: =+COUNTIFS($G$2:$G$444,G45) -> 2 | W45: =+VLOOKUP(M45,Datos!$F:$H,3,FALSE) -> 0 | X45: 0 | Y45: 2 polia | Z45: =VLOOKUP(M45,'[1]INDIVIDUAL UN'!$C$6:$F$222,4,FALSE) -> #N/A
A46: SI | C46: 3 | D46: NUEVO | E46: VCB-20220046 | F46: 106 | G46: JUANA SANTIAGO PANJOJ SALVADOR | H46: 46269 | I46: 46269 | J46: =+VLOOKUP(K46,Datos!$A:$C,3,FALSE) -> OCCIDENTE | K46: 126 | L46: =+VLOOKUP(K46,Datos!$A:$C,2,FALSE) -> CHICHICASTENANGO | M46: 90040633 | N46: =+VLOOKUP(M46,Datos!$F:$G,2,FALSE) -> MANUELA LUCRECIA SALVADOR SICAL | O46: =IFERROR(IF(A46="SI",VLOOKUP(R46,Datos!$J$1:$K$50,2,FALSE)*C46,VLOOKUP(R46,Datos!$P$1:$T$13,2,FALSE)*C46),0) -> 3276 | P46: 306497 | Q46: =+VLOOKUP(P46,Datos!$F:$G,2,FALSE) -> Erika Ixtan Canil | R46: PREVENCION+SEGURA | V46: =+COUNTIFS($G$2:$G$444,G46) -> 2 | W46: =+VLOOKUP(M46,Datos!$F:$H,3,FALSE) -> 0 | X46: 0 | Y46: 2 poliza | Z46: =VLOOKUP(M46,'[1]INDIVIDUAL UN'!$C$6:$F$222,4,FALSE) -> #N/A
A47: SI | C47: 4 | D47: NUEVO | E47: VCB-20240008 | F47: 655 | G47: EDIL WOSBELI GOMEZ GOMEZ | H47: 46269 | I47: 46269 | J47: =+VLOOKUP(K47,Datos!$A:$C,3,FALSE) -> SUROCCIDENTE | K47: 31 | L47: =+VLOOKUP(K47,Datos!$A:$C,2,FALSE) -> COATEPEQUE | M47: 315882 | N47: =+VLOOKUP(M47,Datos!$F:$G,2,FALSE) -> RUTH ANAI GOMEZ RAMIREZ | O47: =IFERROR(IF(A47="SI",VLOOKUP(R47,Datos!$J$1:$K$50,2,FALSE)*C47,VLOOKUP(R47,Datos!$P$1:$T$13,2,FALSE)*C47),0) -> 5472 | P47: 306656 | Q47: =+VLOOKUP(P47,Datos!$F:$G,2,FALSE) -> Wilmer Benjamin Vasquez Puac | R47: VIDA+SEGURO PLAN 1 | V47: =+COUNTIFS($G$2:$G$444,G47) -> 1 | W47: =+VLOOKUP(M47,Datos!$F:$H,3,FALSE) -> 0 | X47: 0 | Z47: =VLOOKUP(M47,'[1]INDIVIDUAL UN'!$C$6:$F$222,4,FALSE) -> #N/A
A48: SI | C48: 1 | D48: NUEVO | E48: VCB-20210003 | F48: 4261 | G48: DOMINGO MATEO SEBASTIAN | H48: 46269 | I48: 46269 | J48: =+VLOOKUP(K48,Datos!$A:$C,3,FALSE) -> OCCIDENTE | K48: 246 | L48: =+VLOOKUP(K48,Datos!$A:$C,2,FALSE) -> SANTA CRUZ BARILLAS | M48: 312087 | N48: =+VLOOKUP(M48,Datos!$F:$G,2,FALSE) -> Yoni Yosuen Rodriguez Sosa | O48: =IFERROR(IF(A48="SI",VLOOKUP(R48,Datos!$J$1:$K$50,2,FALSE)*C48,VLOOKUP(R48,Datos!$P$1:$T$13,2,FALSE)*C48),0) -> 816 | P48: 304166 | Q48: =+VLOOKUP(P48,Datos!$F:$G,2,FALSE) -> Maviela Bibianeth Castillo Avila | R48: VIDA+SEGURO | V48: =+COUNTIFS($G$2:$G$444,G48) -> 1 | W48: =+VLOOKUP(M48,Datos!$F:$H,3,FALSE) -> 0 | X48: 0 | Z48: =VLOOKUP(M48,'[1]INDIVIDUAL UN'!$C$6:$F$222,4,FALSE) -> #N/A
A49: SI | C49: 1 | D49: NUEVO | E49: VCB-20210003 | F49: 4265 | G49: RONY FIDEL AGUILAR AJTUN | H49: 46269 | I49: 46269 | J49: =+VLOOKUP(K49,Datos!$A:$C,3,FALSE) -> OCCIDENTE | K49: 243 | L49: =+VLOOKUP(K49,Datos!$A:$C,2,FALSE) -> PRADERA XELA | M49: 316039 | N49: =+VLOOKUP(M49,Datos!$F:$G,2,FALSE) -> Edgar Francisco Garcia | O49: =IFERROR(IF(A49="SI",VLOOKUP(R49,Datos!$J$1:$K$50,2,FALSE)*C49,VLOOKUP(R49,Datos!$P$1:$T$13,2,FALSE)*C49),0) -> 816 | P49: 315174 | Q49: =+VLOOKUP(P49,Datos!$F:$G,2,FALSE) -> Edwin Adolfo Soberanis Mazariegos | R49: VIDA+SEGURO | V49: =+COUNTIFS($G$2:$G$444,G49) -> 1 | W49: =+VLOOKUP(M49,Datos!$F:$H,3,FALSE) -> 0 | X49: 0 | Z49: =VLOOKUP(M49,'[1]INDIVIDUAL UN'!$C$6:$F$222,4,FALSE) -> #N/A
A50: SI | C50: 1 | D50: NUEVO | E50: ACPE-20210007 | F50: 2580 | G50: ERVIN HOMERO LOPEZ REYES | H50: 46269 | I50: 46269 | J50: =+VLOOKUP(K50,Datos!$A:$C,3,FALSE) -> SUROCCIDENTE | K50: 31 | L50: =+VLOOKUP(K50,Datos!$A:$C,2,FALSE) -> COATEPEQUE | M50: 315882 | N50: =+VLOOKUP(M50,Datos!$F:$G,2,FALSE) -> RUTH ANAI GOMEZ RAMIREZ | O50: =IFERROR(IF(A50="SI",VLOOKUP(R50,Datos!$J$1:$K$50,2,FALSE)*C50,VLOOKUP(R50,Datos!$P$1:$T$13,2,FALSE)*C50),0) -> 1008 | P50: 306656 | Q50: =+VLOOKUP(P50,Datos!$F:$G,2,FALSE) -> Wilmer Benjamin Vasquez Puac | R50: AP BIENESTAR | V50: =+COUNTIFS($G$2:$G$444,G50) -> 1 | W50: =+VLOOKUP(M50,Datos!$F:$H,3,FALSE) -> 0 | X50: 0 | Z50: =VLOOKUP(M50,'[1]INDIVIDUAL UN'!$C$6:$F$222,4,FALSE) -> #N/A
...

Sheet Datos
A1: FTE. | B1: AGENCIA | C1: ZONA | F1: Codigo Empleado | G1: Nombre Empleado | H1: Codigo Empleado | I1: BAM | J1: Producto | K1: 1 año | L1: 2 años | M1: 3 años | N1: 4 años | O1: OTRO BANCO | P1: Producto | Q1: 1 año | R1: 2 años | S1: 3 años | T1: 4 años
A2: 14 | B2: PRADERA | C2: AMERICAS | F2: 314692 | G2: Abi Susana Santos Alvarado | H2: 0 | J2: VIDA+SEGURO | K2: 816 | L2: =+K2*2 -> 1632 | M2: =+K2*3 -> 2448 | N2: =+K2*4 -> 3264 | P2: VIDA+SEGURO | Q2: 888 | R2: =+Q2*2 -> 1776 | S2: =+Q2*3 -> 2664 | T2: =+Q2*4 -> 3552
A3: 53 | B3: PUERTA PARADA | C3: AMERICAS | F3: 313537 | G3: Abigail Nohemi Letona Lopez | H3: 0 | J3: CONSULTA COMPLETO + BIENESTAR | K3: 2472 | L3: =+K3*2 -> 4944 | M3: =+K3*3 -> 7416 | N3: =+K3*4 -> 9888 | P3: CONSULTA COMPLETO + BIENESTAR | Q3: 2676 | R3: =+Q3*2 -> 5352 | S3: =+Q3*3 -> 8028 | T3: =+Q3*4 -> 10704
A4: 54 | B4: LAS CONCHAS ZONA 14 | C4: AMERICAS | F4: 314163 | G4: Abner Amilcar Miguel Pedro | H4: 0 | J4: CONSULTA BASICO | K4: 1428 | L4: =+K4*2 -> 2856 | M4: =+K4*3 -> 4284 | N4: =+K4*4 -> 5712 | P4: CONSULTA BASICO | Q4: 1548 | R4: =+Q4*2 -> 3096 | S4: =+Q4*3 -> 4644 | T4: =+Q4*4 -> 6192
A5: 58 | B5: EUROPLAZA | C5: AMERICAS | F5: 300544 | G5: Abner Enmanuel Perez Rodriguez | H5: 0 | J5: CONSULTA BASICO + BIENESTAR | K5: 1908 | L5: =+K5*2 -> 3816 | M5: =+K5*3 -> 5724 | N5: =+K5*4 -> 7632 | P5: CONSULTA BASICO + BIENESTAR | Q5: 2064 | R5: =+Q5*2 -> 4128 | S5: =+Q5*3 -> 6192 | T5: =+Q5*4 -> 8256
A6: 71 | B6: VISTA HERMOSA | C6: AMERICAS | F6: 315208 | G6: Abner Juan Alexander Menchu Tiu | H6: 0 | J6: MULTIASISTENCIAS | K6: 1704 | L6: =+K6*2 -> 3408 | M6: =+K6*3 -> 5112 | N6: =+K6*4 -> 6816 | P6: MULTIASISTENCIAS | Q6: 1848 | R6: =+Q6*2 -> 3696 | S6: =+Q6*3 -> 5544 | T6: =+Q6*4 -> 7392
A7: 90 | B7: CENTRO MEDICO | C7: AMERICAS | F7: 315069 | G7: Abner Rocael Sosa Escobar | H7: 0 | J7: AP DENTAL FAMILIAR | K7: 1332 | L7: =+K7*2 -> 2664 | M7: =+K7*3 -> 3996 | N7: =+K7*4 -> 5328 | P7: AP DENTAL FAMILIAR | Q7: 1440 | R7: =+Q7*2 -> 2880 | S7: =+Q7*3 -> 4320 | T7: =+Q7*4 -> 5760
A8: 92 | B8: CONDADO CONCEPCION | C8: AMERICAS | F8: 310864 | G8: Adelaida Garcia Hernandez | H8: 0 | J8: AP BIENESTAR | K8: 1008 | L8: =+K8*2 -> 2016 | M8: =+K8*3 -> 3024 | N8: =+K8*4 -> 4032 | P8: AP BIENESTAR | Q8: 1092 | R8: =+Q8*2 -> 2184 | S8: =+Q8*3 -> 3276 | T8: =+Q8*4 -> 4368
A9: 224 | B9: MINUTO CARRETERA A EL SALVADOR | C9: AMERICAS | F9: 314604 | G9: Adieny Moren Ramirez Gamboa | H9: 0 | J9: AUTO+SEGURO (AUTO) | K9: 1308 | L9: =+K9*2 -> 2616 | M9: =+K9*3 -> 3924 | N9: =+K9*4 -> 5232 | P9: AUTO+SEGURO (AUTO) | Q9: 1417 | R9: =+Q9*2 -> 2834 | S9: =+Q9*3 -> 4251 | T9: =+Q9*4 -> 5668
A10: 226 | B10: SAN JOSE PINULA | C10: AMERICAS | F10: 311687 | G10: Aida Gabriela De Leon Carrascoza | H10: 0 | J10: PREVENCION+SEGURA | K10: 1092 | L10: =+K10*2 -> 2184 | M10: =+K10*3 -> 3276 | N10: =+K10*4 -> 4368 | P10: PREVENCION+SEGURA | Q10: 1200 | R10: =+Q10*2 -> 2400 | S10: =+Q10*3 -> 3600 | T10: =+Q10*4 -> 4800
A11: 231 | B11: SANTA AMELIA ZONA 16 | C11: AMERICAS | F11: 315221 | G11: Alan David Perez Muyus | H11: 0 | J11: AP DENTAL INDIVIDUAL | K11: 1308 | L11: =+K11*2 -> 2616 | M11: =+K11*3 -> 3924 | N11: =+K11*4 -> 5232 | P11: AP DENTAL INDIVIDUAL | Q11: 1416 | R11: =+Q11*2 -> 2832 | S11: =+Q11*3 -> 4248 | T11: =+Q11*4 -> 5664
A12: 278 | B12: HINCAPIE | C12: AMERICAS | F12: 311950 | G12: Alan Javier Castillo Ordoñez | H12: 0 | J12: CONSULTA COMPLETO | K12: 2004 | L12: =+K12*2 -> 4008 | M12: =+K12*3 -> 6012 | N12: =+K12*4 -> 8016 | P12: CONSULTA COMPLETO | Q12: 2172 | R12: =+Q12*2 -> 4344 | S12: =+Q12*3 -> 6516 | T12: =+Q12*4 -> 8688
A13: 294 | B13: PLAZA ZONA 14 | C13: AMERICAS | F13: 313765 | G13: Alan Ricardo Flores Diaz | H13: 0 | J13: AUTO+SEGURO (PICK UP) | K13: 1788 | L13: =+K13*2 -> 3576 | M13: =+K13*3 -> 5364 | N13: =+K13*4 -> 7152 | P13: AUTO+SEGURO (PICK UP) | Q13: 1937 | R13: =+Q13*2 -> 3874 | S13: =+Q13*3 -> 5811 | T13: =+Q13*4 -> 7748
... A19: 12 | B19: PLAZA FLORIDA | C19: CENTRO HISTORICO | F19: 315220 | G19: Alejandro Jose Mont Diaz | H19: 0 | J19: MIGRANTE BAM | K19: 1380 | L19: =+K19*2 -> 2760 | M19: =+K19*3 -> 4140 | N19: =+K19*4 -> 5520 | P19: MIGRANTE BAM | Q19: 1500 | R19: =+Q19*2 -> 3000 | S19: =+Q19*3 -> 4500 | T19: =+Q19*4 -> 6000
A20: 13 | B20: METANORTE | C20: CENTRO HISTORICO | F20: 311810 | G20: Alexander Macario Gonzalez Monterroso | H20: 0 | J20: MOTO+SEGURA | K20: 1500 | L20: 3000 | M20: 4500 | N20: 6000 | P20: MOTO+SEGURA | Q20: 1620 | R20: 3240 | S20: 4860 | T20: 6480
A21: 19 | B21: MORAZAN ZONA 2 | C21: CENTRO HISTORICO | F21: 300907 | G21: Alexangel Quan Urrutia | H21: 0
A22: 37 | B22: SAN JUAN SACATEPEQUEZ | C22: ROOSEVELT | F22: 312962 | G22: Alexia Paola Marroquin Lopez | H22: 0
A23: 61 | B23: DEL CENTRO | C23: CENTRO HISTORICO | F23: 314671 | G23: Alexsandra Daniela Cano Garcia | H23: 0
A24: 81 | B24: PEDRERA | C24: CENTRO HISTORICO | F24: 311103 | G24: Alfredo Chiyal Bocel | H24: 0
A25: 83 | B25: DISAGRO | C25: CENTRO HISTORICO | F25: 311576 | G25: Alfredo Gomez Lancerio | H25: 0
A26: 87 | B26: EL NARANJO | C26: CENTRO HISTORICO | F26: 313014 | G26: Alfredo Monsanto Santos | H26: 0
A27: 98 | B27: CALLE MARTI | C27: CENTRO HISTORICO | F27: 315223 | G27: Alicia Magaly Juarez Quiacain | H27: 0
A28: 103 | B28: LOS ALAMOS | C28: CENTRO HISTORICO | F28: 314035 | G28: Alisson Andrea Jacobo Castro | H28: 0
A29: 113 | B29: PARQUE COLON | C29: CENTRO HISTORICO | F29: 315214 | G29: Allan David Galdamez De Leon | H29: 0
A30: 166 | B30: 23 CALLE | C30: CENTRO HISTORICO | F30: 306902 | G30: Allan Kalleb Garcia Cahuex | H30: 0
A31: 296 | B31: PORTALES | C31: CENTRO HISTORICO | F31: 315434 | G31: Alma Carolina Herrera Pirir | H31: 0
A32: 302 | B32: CENTRANORTE | C32: CENTRO HISTORICO | F32: 315280 | G32: Alma Rosa Valle Blandon | H32: 0
... A170: 355 | B170: PARADOR DEL MAR | C170: COSTA SUR | F170: 315158 | G170: Carlos Emilio Cumez Chenol | H170: 0
F171: 312533 | G171: Carlos Enrique Coz Toc | H171: 0
F172: 314773 | G172: Carlos Enrique Ramirez Lopez | H172: 0
F173: 313303 | G173: Carlos Enrique Vasquez Esteban | H173: 0
F174: 314841 | G174: Carlos Estuardo Campos Asig | H174: 0
F175: 308075 | G175: Carlos Humberto De Paz Paiz | H175: 0
F176: 314441 | G176: Carlos Josue Perez Garcia | H176: 0
F177: 202153 | G177: Carlos Leonel Corado Sosa | H177: 0
F178: 313324 | G178: Carlos Miguel Carrillo Perez | H178: 0
F179: 310535 | G179: Carlos Oliverio Ortiz Villalobos | H179: 0
F180: 315501 | G180: Carlos Onofre Sierra Vasquez | H180: 0
F181: 313844 | G181: Carlos Raul Pedroza Lopez | H181: 0
F182: 315111 | G182: Carlos Roberto Arana Garcia | H182: 0
...
